Workbook

Sheet 4월 (3)
B1: 구 분 | G1: 경 비 내 역
B2: 매장명 | C2: 1월매출 | D2: 4월 매출 | E2: 오프라인 | F2: 온라인 | G2: 고객배송 택배비 | H2: 건수 | I2: 매장 수평 택배비 | J2: 건수 | K2: 매장경비 | L2: 건수 | M2: 계 | N2: 매출대비 전체비율 | O2: 확인 | P2: 비고란 | Q2: 근로계약서
A3: 53 | B3: 롯데아울렛광교점 | C3: =VLOOKUP(B3,#REF!,2,0) -> #REF! | D3: 39065500 | E3: =VLOOKUP(B3,#REF!,5,0) -> #REF! | F3: =VLOOKUP(B3,#REF!,9,0) -> #REF! | G3: 429000 | H3: 88 | I3: 31000 | J3: 8 | K3: 0 | L3: 0 | M3: =G3+I3+K3 -> 460000 | N3: =M3/D3 -> 0.011775096 | O3: 본사지급
A4: 51 | B4: 롯데아울렛광명점 | C4: =VLOOKUP(B4,#REF!,2,0) -> #REF! | D4: 41360480 | E4: =VLOOKUP(B4,#REF!,5,0) -> #REF! | F4: =VLOOKUP(B4,#REF!,9,0) -> #REF! | G4: 394500 | H4: 95 | I4: 88000 | J4: 23 | K4: 8000 | L4: 2 | M4: =G4+I4+K4 -> 490500 | N4: =M4/D4 -> 0.011859147 | O4: 본사지급 | Q4: OK
A5: 54 | B5: 롯데아울렛동부산점 | D5: 45443550 | G5: 282000 | H5: 73 | I5: 128000 | J5: 35 | K5: 86400 | L5: 2 | M5: =G5+I5+K5 -> 496400 | N5: =M5/D5 -> 0.010923442 | O5: 본사지급 | P5: 문구류, 약속장 (지출증빙 완료)
A6: 39 | B6: 신세계충청점 | C6: =VLOOKUP(B6,#REF!,2,0) -> #REF! | D6: 20260450 | E6: =VLOOKUP(B6,#REF!,5,0) -> #REF! | F6: =VLOOKUP(B6,#REF!,9,0) -> #REF! | G6: 241000 | H6: 58 | I6: 24000 | J6: 6 | K6: 8000 | L6: 2 | M6: =G6+I6+K6 -> 273000 | N6: =M6/D6 -> 0.013474528 | O6: 본사지급
A7: 45 | B7: AK프라자분당점 | C7: =VLOOKUP(B7,#REF!,2,0) -> #REF! | D7: 44617050 | E7: =VLOOKUP(B7,#REF!,5,0) -> #REF! | F7: =VLOOKUP(B7,#REF!,9,0) -> #REF! | G7: 171000 | H7: 41 | I7: 35000 | J7: 9 | K7: 0 | L7: 0 | M7: =G7+I7+K7 -> 206000 | N7: =M7/D7 -> 0.004617069 | O7: 본사지급 | Q7: OK
A8: 7 | B8: 롯데창원점 | C8: =VLOOKUP(B8,#REF!,2,0) -> #REF! | D8: 57623150 | E8: =VLOOKUP(B8,#REF!,5,0) -> #REF! | F8: =VLOOKUP(B8,#REF!,9,0) -> #REF! | G8: 169000 | H8: 49 | I8: 72500 | J8: 18 | K8: 0 | L8: 0 | M8: =G8+I8+K8 -> 241500 | N8: =M8/D8 -> 0.0041910239 | O8: 본사지급 | Q8: OK
A9: 52 | B9: 롯데아울렛고양점 | C9: =VLOOKUP(B9,#REF!,2,0) -> #REF! | D9: 18920070 | E9: =VLOOKUP(B9,#REF!,5,0) -> #REF! | F9: =VLOOKUP(B9,#REF!,9,0) -> #REF! | G9: 155000 | H9: 44 | I9: 48000 | J9: 13 | K9: 3000 | L9: 1 | M9: =G9+I9+K9 -> 206000 | N9: =M9/D9 -> 0.010887909 | O9: 본사지급
A10: 58 | B10: 모다아울렛인천점 | C10: =VLOOKUP(B10,#REF!,2,0) -> #REF! | D10: 31103840 | E10: =VLOOKUP(B10,#REF!,5,0) -> #REF! | F10: =VLOOKUP(B10,#REF!,9,0) -> #REF! | G10: 150500 | H10: 47 | I10: 40500 | J10: 10 | K10: 23000 | L10: 3 | M10: =G10+I10+K10 -> 214000 | N10: =M10/D10 -> 0.0068801794 | O10: 본사지급 | P10: 대도지물 : 17,000원
A11: 43 | B11: 갤러리아천안점 | C11: =VLOOKUP(B11,#REF!,2,0) -> #REF! | D11: 56376440 | E11: =VLOOKUP(B11,#REF!,5,0) -> #REF! | F11: =VLOOKUP(B11,#REF!,9,0) -> #REF! | G11: 146500 | H11: 31 | I11: 68000 | J11: 18 | K11: 0 | L11: 0 | M11: =G11+I11+K11 -> 214500 | N11: =M11/D11 -> 0.0038047809 | O11: 본사지급
A12: 15 | B12: 롯데안산점 | C12: =VLOOKUP(B12,#REF!,2,0) -> #REF! | D12: 36606960 | E12: =VLOOKUP(B12,#REF!,5,0) -> #REF! | F12: =VLOOKUP(B12,#REF!,9,0) -> #REF! | G12: 141000 | H12: 26 | I12: 98000 | J12: 25 | K12: 3000 | L12: 1 | M12: =G12+I12+K12 -> 242000 | N12: =M12/D12 -> 0.0066107647 | O12: 본사지급 | Q12: OK
A13: 26 | B13: 현대울산점 | C13: =VLOOKUP(B13,#REF!,2,0) -> #REF! | D13: 41040440 | E13: =VLOOKUP(B13,#REF!,5,0) -> #REF! | F13: =VLOOKUP(B13,#REF!,9,0) -> #REF! | G13: 139000 | H13: 35 | I13: 17000 | J13: 5 | M13: =G13+I13+K13 -> 156000 | N13: =M13/D13 -> 0.0038011288 | O13: 본사지급
A14: 27 | B14: 현대중동점 | C14: =VLOOKUP(B14,#REF!,2,0) -> #REF! | D14: 58217450 | E14: =VLOOKUP(B14,#REF!,5,0) -> #REF! | F14: =VLOOKUP(B14,#REF!,9,0) -> #REF! | G14: 137000 | H14: 25 | I14: 128300 | J14: 33 | M14: =G14+I14+K14 -> 265300 | N14: =M14/D14 -> 0.0045570529 | O14: 본사지급 | Q14: OK
A15: 55 | B15: 롯데아울렛군산점 | C15: =VLOOKUP(B15,#REF!,2,0) -> #REF! | D15: 34954550 | E15: =VLOOKUP(B15,#REF!,5,0) -> #REF! | F15: =VLOOKUP(B15,#REF!,9,0) -> #REF! | G15: 135000 | H15: 40 | I15: 67500 | J15: 18 | K15: 0 | L15: 0 | M15: =G15+I15+K15 -> 202500 | N15: =M15/D15 -> 0.0057932372 | O15: 본사지급 | Q15: OK
A16: 13 | B16: 롯데부산본점 | C16: =VLOOKUP(B16,#REF!,2,0) -> #REF! | D16: 47637440 | E16: =VLOOKUP(B16,#REF!,5,0) -> #REF! | F16: =VLOOKUP(B16,#REF!,9,0) -> #REF! | G16: 128000 | H16: 37 | I16: 138000 | J16: 39 | K16: 11000 | L16: 3 | M16: =G16+I16+K16 -> 277000 | N16: =M16/D16 -> 0.0058147541 | O16: 본사지급 | P16: A4 용지 5,000원 (지출증빙 완료)
A17: 23 | B17: 롯데인천터미널점 | C17: =VLOOKUP(B17,#REF!,2,0) -> #REF! | D17: 88534350 | E17: =VLOOKUP(B17,#REF!,5,0) -> #REF! | F17: =VLOOKUP(B17,#REF!,9,0) -> #REF! | G17: 120000 | H17: 26 | I17: 150500 | J17: 38 | K17: 65200 | L17: 3 | M17: =G17+I17+K17 -> 335700 | N17: =M17/D17 -> 0.0037917486 | O17: 본사지급 | P17: 대도지물,문구류 지출증빙 완료
A18: 48 | B18: 마리오아울렛금천점 | C18: =VLOOKUP(B18,#REF!,2,0) -> #REF! | D18: 20284510 | E18: =VLOOKUP(B18,#REF!,5,0) -> #REF! | F18: =VLOOKUP(B18,#REF!,9,0) -> #REF! | G18: 117000 | H18: 33 | I18: 16500 | J18: 5 | K18: 9000 | L18: 3 | M18: =G18+I18+K18 -> 142500 | N18: =M18/D18 -> 0.0070250649 | O18: 본사지급
A19: 6 | B19: 롯데동래점 | C19: =VLOOKUP(B19,#REF!,2,0) -> #REF! | D19: 35020690 | E19: =VLOOKUP(B19,#REF!,5,0) -> #REF! | F19: =VLOOKUP(B19,#REF!,9,0) -> #REF! | G19: 116000 | H19: 36 | I19: 77000 | J19: 20 | K19: 73000 | L19: 5 | M19: =G19+I19+K19 -> 266000 | N19: =M19/D19 -> 0.00759551 | O19: 본사지급 | P19: 약속대장 : 60,000원 (지출증빙 완료) | Q19: OK
A20: 33 | B20: 현대판교점 | C20: =VLOOKUP(B20,#REF!,2,0) -> #REF! | D20: 49178250 | E20: =VLOOKUP(B20,#REF!,5,0) -> #REF! | F20: =VLOOKUP(B20,#REF!,9,0) -> #REF! | G20: 110000 | H20: 18 | I20: 23000 | J20: 6 | M20: =G20+I20+K20 -> 133000 | N20: =M20/D20 -> 0.0027044476 | O20: 기본수수료
A21: 57 | B21: 모다아울렛행담도점 | C21: =VLOOKUP(B21,#REF!,2,0) -> #REF! | D21: 9513150 | E21: =VLOOKUP(B21,#REF!,5,0) -> #REF! | F21: =VLOOKUP(B21,#REF!,9,0) -> #REF! | G21: 101000 | H21: 20 | I21: 0 | J21: 0 | K21: 0 | L21: 0 | M21: =G21+I21+K21 -> 101000 | N21: =M21/D21 -> 0.010616883 | O21: 본사지급
A22: 60 | B22: 신세계스타필드고양점 | C22: =VLOOKUP(B22,#REF!,2,0) -> #REF! | D22: 26191750 | E22: =VLOOKUP(B22,#REF!,5,0) -> #REF! | F22: =VLOOKUP(B22,#REF!,9,0) -> #REF! | G22: 100000 | H22: 27 | I22: 16000 | J22: 4 | K22: 15000 | L22: 1 | M22: =G22+I22+K22 -> 131000 | N22: =M22/D22 -> 0.0050015749 | O22: 본사지급 | P22: 다이소, 커피,종이컵,청소포,문구류(지출증빙 완료) | Q22: OK
A23: 22 | B23: 롯데분당점 | C23: =VLOOKUP(B23,#REF!,2,0) -> #REF! | D23: 26605930 | E23: =VLOOKUP(B23,#REF!,5,0) -> #REF! | F23: =VLOOKUP(B23,#REF!,9,0) -> #REF! | G23: 87000 | H23: 12 | I23: 78000 | J23: 20 | K23: 0 | L23: 0 | M23: =G23+I23+K23 -> 165000 | N23: =M23/D23 -> 0.006201625 | O23: 본사지급 | Q23: OK
A24: 24 | B24: 현대무역점 | C24: =VLOOKUP(B24,#REF!,2,0) -> #REF! | D24: 48148460 | E24: =VLOOKUP(B24,#REF!,5,0) -> #REF! | F24: =VLOOKUP(B24,#REF!,9,0) -> #REF! | G24: 81000 | H24: 20 | I24: 122500 | J24: 32 | K24: 12000 | L24: 1 | M24: =G24+I24+K24 -> 215500 | N24: =M24/D24 -> 0.0044757402 | O24: 본사지급 | P24: 시니어명찰 | Q24: OK
A25: 20 | B25: 롯데대구점 | C25: =VLOOKUP(B25,#REF!,2,0) -> #REF! | D25: 31335150 | E25: =VLOOKUP(B25,#REF!,5,0) -> #REF! | F25: =VLOOKUP(B25,#REF!,9,0) -> #REF! | G25: 80000 | H25: 17 | I25: 75000 | J25: 19 | K25: 0 | L25: 0 | M25: =G25+I25+K25 -> 155000 | N25: =M25/D25 -> 0.0049465217 | O25: 본사지급 | Q25: OK
A26: 18 | B26: 롯데광복점 | C26: =VLOOKUP(B26,#REF!,2,0) -> #REF! | D26: 43138440 | E26: =VLOOKUP(B26,#REF!,5,0) -> #REF! | F26: =VLOOKUP(B26,#REF!,9,0) -> #REF! | G26: 67500 | H26: 16 | I26: 86000 | J26: 24 | K26: 0 | L26: 0 | M26: =G26+I26+K26 -> 153500 | N26: =M26/D26 -> 0.0035583113 | O26: 본사지급 | Q26: OK
A27: 35 | B27: 신세계마산점 | C27: =VLOOKUP(B27,#REF!,2,0) -> #REF! | D27: 43707000 | E27: =VLOOKUP(B27,#REF!,5,0) -> #REF! | F27: =VLOOKUP(B27,#REF!,9,0) -> #REF! | G27: 64000 | H27: 4 | I27: 71500 | J27: 19 | K27: 0 | L27: 0 | M27: =G27+I27+K27 -> 135500 | N27: =M27/D27 -> 0.0031001899 | O27: 본사지급 | Q27: OK
A28: 19 | B28: 롯데수원점 | C28: =VLOOKUP(B28,#REF!,2,0) -> #REF! | D28: 35351700 | E28: =VLOOKUP(B28,#REF!,5,0) -> #REF! | F28: =VLOOKUP(B28,#REF!,9,0) -> #REF! | G28: 57000 | H28: 17 | I28: 61500 | J28: 15 | K28: 0 | L28: 0 | M28: =G28+I28+K28 -> 118500 | N28: =M28/D28 -> 0.0033520312 | O28: 본사지급
A29: 4 | B29: 롯데강남점 | C29: =VLOOKUP(B29,#REF!,2,0) -> #REF! | D29: 36288800 | E29: =VLOOKUP(B29,#REF!,5,0) -> #REF! | F29: =VLOOKUP(B29,#REF!,9,0) -> #REF! | G29: 55000 | H29: 12 | I29: 55000 | J29: 16 | K29: 7000 | L29: 2 | M29: =G29+I29+K29 -> 117000 | N29: =M29/D29 -> 0.0032241353 | O29: 본사지급 | Q29: OK
A30: 8 | B30: 롯데상인점 | C30: =VLOOKUP(B30,#REF!,2,0) -> #REF! | D30: 33771350 | E30: =VLOOKUP(B30,#REF!,5,0) -> #REF! | F30: =VLOOKUP(B30,#REF!,9,0) -> #REF! | G30: 46000 | H30: 11 | I30: 75500 | J30: 20 | K30: 0 | L30: 0 | M30: =G30+I30+K30 -> 121500 | N30: =M30/D30 -> 0.0035977241 | O30: 본사지급
A31: 17 | B31: 롯데본점 | C31: =VLOOKUP(B31,#REF!,2,0) -> #REF! | D31: 82861350 | E31: =VLOOKUP(B31,#REF!,5,0) -> #REF! | F31: =VLOOKUP(B31,#REF!,9,0) -> #REF! | G31: 46000 | H31: 8 | I31: 115000 | J31: =17+16 -> 33 | K31: 3000 | L31: 1 | M31: =G31+I31+K31 -> 164000 | N31: =M31/D31 -> 0.0019792098 | O31: 본사지급 | Q31: OK
A32: 12 | B32: 롯데센텀점 | C32: =VLOOKUP(B32,#REF!,2,0) -> #REF! | D32: 21499680 | E32: =VLOOKUP(B32,#REF!,5,0) -> #REF! | F32: =VLOOKUP(B32,#REF!,9,0) -> #REF! | G32: 44000 | H32: 10 | I32: 40000 | J32: 11 | K32: 57500 | L32: 2 | M32: =G32+I32+K32 -> 141500 | N32: =M32/D32 -> 0.0065814933 | O32: 본사지급 | P32: 대명지류(끈,포장지) - 증빙처리 완료 | Q32: OK
A33: 9 | B33: 롯데미아점 | C33: =VLOOKUP(B33,#REF!,2,0) -> #REF! | D33: 27445450 | E33: =VLOOKUP(B33,#REF!,5,0) -> #REF! | F33: =VLOOKUP(B33,#REF!,9,0) -> #REF! | G33: 40000 | H33: 8 | I33: 24800 | J33: 7 | K33: 3000 | L33: 1 | M33: =G33+I33+K33 -> 67800 | N33: =M33/D33 -> 0.0024703548 | O33: 본사지급 | Q33: OK
A34: 32 | B34: 현대동구점 | C34: =VLOOKUP(B34,#REF!,2,0) -> #REF! | D34: 20591650 | E34: =VLOOKUP(B34,#REF!,5,0) -> #REF! | F34: =VLOOKUP(B34,#REF!,9,0) -> #REF! | G34: 27000 | H34: 9 | I34: 13000 | J34: 3 | M34: =G34+I34+K34 -> 40000 | N34: =M34/D34 -> 0.001942535 | O34: 본사지급
A35: 2 | B35: 롯데관악점 | C35: =VLOOKUP(B35,#REF!,2,0) -> #REF! | D35: 33141940 | E35: =VLOOKUP(B35,#REF!,5,0) -> #REF! | F35: =VLOOKUP(B35,#REF!,9,0) -> #REF! | G35: 20000 | H35: 4 | I35: 38500 | J35: 10 | K35: 3000 | L35: 1 | M35: =G35+I35+K35 -> 61500 | N35: =M35/D35 -> 0.0018556548 | O35: 본사지급 | Q35: OK
A36: 40 | B36: 신세계김해점 | C36: =VLOOKUP(B36,#REF!,2,0) -> #REF! | D36: 50619300 | E36: =VLOOKUP(B36,#REF!,5,0) -> #REF! | F36: =VLOOKUP(B36,#REF!,9,0) -> #REF! | G36: 17000 | H36: 4 | I36: 73500 | J36: 19 | K36: 2500 | L36: 1 | M36: =G36+I36+K36 -> 93000 | N36: =M36/D36 -> 0.0018372439 | O36: 본사지급 | Q36: OK
A37: 41 | B37: 신세계스타필드하남점 | C37: =VLOOKUP(B37,#REF!,2,0) -> #REF! | D37: 39209040 | E37: =VLOOKUP(B37,#REF!,5,0) -> #REF! | F37: =VLOOKUP(B37,#REF!,9,0) -> #REF! | G37: 15000 | H37: 1 | I37: 103000 | J37: 27 | K37: 3000 | L37: 1 | M37: =G37+I37+K37 -> 121000 | N37: =M37/D37 -> 0.003086023 | O37: 본사지급
A38: 10 | B38: 롯데구리점 | C38: =VLOOKUP(B38,#REF!,2,0) -> #REF! | D38: 19634560 | E38: =VLOOKUP(B38,#REF!,5,0) -> #REF! | F38: =VLOOKUP(B38,#REF!,9,0) -> #REF! | G38: 14500 | H38: 4 | I38: 29500 | J38: 8 | K38: 6000 | L38: 2 | M38: =G38+I38+K38 -> 50000 | N38: =M38/D38 -> 0.0025465302 | O38: 본사지급
A39: 38 | B39: 신세계영등포점 | C39: =VLOOKUP(B39,#REF!,2,0) -> #REF! | D39: 53008870 | E39: =VLOOKUP(B39,#REF!,5,0) -> #REF! | F39: =VLOOKUP(B39,#REF!,9,0) -> #REF! | G39: 14000 | H39: 3 | I39: 37500 | J39: 11 | K39: 9500 | L39: 3 | M39: =G39+I39+K39 -> 61000 | N39: =M39/D39 -> 0.0011507508 | O39: 본사지급 | P39: 종이쇼핑백 : 2,000원 (지출증빙 완료)
A40: 46 | B40: AK프라자원주점 | C40: =VLOOKUP(B40,#REF!,2,0) -> #REF! | D40: 29970950 | E40: =VLOOKUP(B40,#REF!,5,0) -> #REF! | F40: =VLOOKUP(B40,#REF!,9,0) -> #REF! | G40: 0 | H40: 0 | I40: 46500 | J40: 12 | K40: 0 | L40: 0 | M40: =G40+I40+K40 -> 46500 | N40: =M40/D40 -> 0.0015515024 | O40: 본사지급
...

Sheet Sheet1
B5: * 2023년 매장 경비내역
C6: 매출 | D6: 매출대비 전체비율 | E6: 배송 택배비 | F6: 건수 | G6: 수평 택배비 | H6: 건수 | I6: 매장경비 | J6: 건수 | K6: 계 | L6: 전월대비
B7: 1월 | C7: 2544931756 | D7: =K7/C7 -> 0.0047838454 | E7: 8241680 | F7: 1544 | G7: 2654640 | H7: 648 | I7: 1278240 | J7: 62 | K7: =E7+G7+I7 -> 12174560 | L7: =K7/K36 -> 0.83695005 | M7: =K7/C7 -> 0.0047838454
B8: 2월 | C8: 2676358390 | D8: =K8/C8 -> 0.0045185727 | E8: 7208230 | F8: 1587 | G8: 4194040 | H8: 1015 | I8: 691050 | J8: 43 | K8: =E8+G8+I8 -> 12093320 | L8: =K8/K7 -> 0.99332707 | M8: =K8/C8 -> 0.0045185727
B9: 3월 | C9: 2921414132 | D9: =K9/C9 -> 0.0055150517 | E9: 9489100 | F9: 1974 | G9: 5473870 | H9: 1300 | I9: 1148780 | J9: 52 | K9: =E9+G9+I9 -> 16111750 | L9: =K9/K8 -> 1.3322851 | M9: =K9/C9 -> 0.0055150517
B10: 4월 | C10: 3561041622 | D10: =K10/C10 -> 0.0047502646 | E10: 10298140 | F10: 2448 | G10: 5941260 | H10: 1405 | I10: 676490 | J10: 54 | K10: =E10+G10+I10 -> 16915890 | L10: =K10/K9 -> 1.0499102 | M10: =K10/C10 -> 0.0047502646
B11: 5월 | C11: 3722708136 | D11: =K11/C11 -> 0.0050873878 | E11: 11872640 | F11: 2400 | G11: 6250670 | H11: 1530 | I11: 815550 | J11: 47 | K11: =E11+G11+I11 -> 18938860 | L11: =K11/K10 -> 1.1195899 | M11: =K11/C11 -> 0.0050873878
B12: 6월 | C12: 4037824686 | D12: =K12/C12 -> 0.004489291 | E12: 9394510 | F12: 2007 | G12: 7777950 | H12: 1962 | I12: 954510 | J12: 47 | K12: 18126970 | L12: =K12/K11 -> 0.957131 | M12: =K12/C12 -> 0.004489291
B13: 7월 | C13: 3339138178 | D13: =K13/C13 -> 0.0057169362 | E13: 10140310 | F13: 2091 | G13: 8267030 | H13: 2029 | I13: 682300 | J13: 43 | K13: 19089640 | L13: =K13/K12 -> 1.0531071 | M13: =K13/C13 -> 0.0057169362
B14: 8월 | C14: 2449387854 | D14: =K14/C14 -> 0.0054726449 | E14: 7424140 | F14: 1359 | G14: 5111470 | H14: 1237 | I14: 869020 | J14: 60 | K14: =E14+G14+I14 -> 13404630 | L14: =K14/K13 -> 0.70219396 | M14: =K14/C14 -> 0.0054726449
B15: 9월 | C15: 2846491210 | D15: =K15/C15 -> 0.0039178586 | E15: 6428560 | F15: 1223 | G15: 4100120 | H15: 986 | I15: 623470 | J15: 32 | K15: =E15+G15+I15 -> 11152150 | L15: =K15/K14 -> 0.83196254
B16: 10월 | K16: =E16+G16+I16 -> 0 | L16: =K16/K15 -> 0
B17: 11월 | K17: =E17+G17+I17 -> 0 | L17: =K17/K16 -> #DIV/0!
B18: 12월 | K18: =E18+G18+I18 -> 0 | L18: =K18/K17 -> #DIV/0!
B19: 계 | C19: =SUM(C7:C18) -> 28099295964 | D19: =K19/C19 -> 0.0049114316 | E19: =SUM(E7:E18) -> 80497310 | F19: =SUM(F7:F18) -> 16633 | G19: =SUM(G7:G18) -> 49771050 | H19: =SUM(H7:H18) -> 12112 | I19: =SUM(I7:I18) -> 7739410 | J19: =SUM(J7:J18) -> 440 | K19: =SUM(K7:K18) -> 138007770
B22: * 2022년 매장 경비내역
C23: 매출 | D23: 매출대비 전체비율 | E23: 배송 택배비 | F23: 건수 | G23: 수평 택배비 | H23: 건수 | I23: 매장경비 | J23: 건수 | K23: 계 | L23: 전월대비
B24: 1월 | C24: 2953885856 | D24: =K24/C24 -> 0.0068047078 | E24: 10589790 | F24: 2270 | G24: 8339100 | H24: 2054 | I24: 1171440 | J24: 68 | K24: =I24+G24+E24 -> 20100330 | L24: 1
B25: 2월 | C25: 2785202870 | D25: =K25/C25 -> 0.0059016563 | E25: 9445890 | F25: 1735 | G25: 6396280 | H25: 1588 | I25: 595140 | J25: 52 | K25: =I25+G25+E25 -> 16437310 | L25: =K25/K24 -> 0.81776319
B26: 3월 | C26: 2934002332 | D26: =K26/C26 -> 0.0059417369 | E26: 9818140 | F26: 1912 | G26: 6949160 | H26: 1714 | I26: 665770 | J26: 48 | K26: =I26+G26+E26 -> 17433070 | L26: =K26/K25 -> 1.0605793
B27: 4월 | C27: 4040333992 | D27: =K27/C27 -> 0.0043786108 | E27: 11202250 | F27: 2201 | G27: 5692930 | H27: 1405 | I27: 795870 | J27: 52 | K27: =I27+G27+E27 -> 17691050 | L27: =K27/K26 -> 1.0147983
B28: 5월 | C28: 3901318362 | D28: =K28/C28 -> 0.0051977455 | E28: 12798240 | F28: 2642 | G28: 6475810 | H28: 1616 | I28: 1004010 | J28: 62 | K28: =I28+G28+E28 -> 20278060 | L28: =K28/K27 -> 1.1462327
B29: 6월 | C29: 4511894922 | D29: =K29/C29 -> 0.00502105 | E29: 13979690 | F29: 2907 | G29: 7751860 | H29: 1931 | I29: 922900 | J29: 72 | K29: =I29+G29+E29 -> 22654450 | L29: =K29/K28 -> 1.1171902
B30: 7월 | C30: 3318942648 | D30: =K30/C30 -> 0.0057682588 | E30: 10494730 | F30: 2324 | G30: 7945100 | H30: 1935 | I30: 704690 | J30: 58 | K30: =I30+G30+E30 -> 19144520 | L30: =K30/K29 -> 0.84506664
B31: 8월 | C31: 2581088176 | D31: =K31/C31 -> 0.0040108626 | E31: 6745850 | F31: 1471 | G31: 3341410 | H31: 841 | I31: 265130 | J31: 40 | K31: =I31+G31+E31 -> 10352390 | L31: =K31/K30 -> 0.54074952
B32: 9월 | C32: 3030980964 | D32: =K32/C32 -> 0.0036888585 | E32: 7393670 | F32: 1374 | G32: 2911150 | H32: 725 | I32: 876040 | J32: 53 | K32: =I32+G32+E32 -> 11180860 | L32: =K32/K31 -> 1.0800269
B33: 계 | C33: =SUM(C24:C32) -> 30057650122 | D33: =K33/C33 -> 0.0051658077 | E33: =SUM(E24:E32) -> 92468250 | F33: =SUM(F24:F32) -> 18836 | G33: =SUM(G24:G32) -> 55802800 | H33: =SUM(H24:H32) -> 13809 | I33: =SUM(I24:I32) -> 7000990 | J33: =SUM(J24:J32) -> 505 | K33: =SUM(K24:K32) -> 155272040
B34: 10월 | C34: 4229153430 | D34: =K34/C34 -> 0.0041734405 | E34: 11767220 | F34: 2426 | G34: 4518630 | H34: 1105 | I34: 1364270 | J34: 66 | K34: =I34+G34+E34 -> 17650120 | L34: =K34/K32 -> 1.5786013
B35: 11월 | C35: 2960965230 | D35: =K35/C35 -> 0.0047984251 | E35: 10073650 | F35: 1984 | G35: 3670270 | H35: 883 | I35: 464050 | J35: 51 | K35: =I35+G35+E35 -> 14207970 | L35: =K35/K34 -> 0.80497866
B36: 12월 | C36: 3073103549 | D36: =K36/C36 -> 0.0047334363 | E36: 10519780 | F36: 1988 | G36: 3152130 | H36: 781 | I36: 874430 | J36: 58 | K36: =I36+G36+E36 -> 14546340 | L36: =K36/K35 -> 1.0238155
B37: 계 | C37: =SUM(C24:C36) -> 70378522453 | D37: =K37/C37 -> 0.0050718386 | E37: =SUM(E24:E36) -> 217297150 | F37: =SUM(F24:F36) -> 44070 | G37: =SUM(G24:G36) -> 122946630 | H37: =SUM(H24:H36) -> 30387 | I37: =SUM(I24:I36) -> 16704730 | J37: =SUM(J24:J36) -> 1185 | K37: =SUM(K24:K36) -> 356948510

Sheet Sheet4
A1: 매장명 | B1: 수량 | C1: 운임비(v-) | F1: 매장명
A2: 롯데아울렛기흥점 | B2: 13 | C2: 60250 | F2: 코지네스트일산점 | G2: 김경훈 팀장
A3: 롯데아울렛김해점 | B3: 8 | C3: 33300 | F3: 롯데잠실점 | G3: 김경훈 팀장
A4: 롯데아울렛이천점 | B4: 42 | C4: 191100 | F4: 롯데창원점 | G4: 김경훈 팀장
A5: 현대아울렛남양주점 | B5: 98 | C5: 460100 | F5: 신세계마산점 | G5: 김경훈 팀장
A6: 현대아울렛대전점 | B6: 28 | C6: 122500 | F6: 신세계강남점 | G6: 김경훈 팀장
B7: =SUM(B2:B6) -> 189 | C7: =SUM(C2:D6) -> 867250 | F7: 신세계천안아산점 | G7: 김경훈 팀장
F8: 신세계김해점 | G8: 김경훈 팀장
F9: 갤러리아천안점 | G9: 김경훈 팀장
F10: 롯데아울렛김해점 | G10: 김경훈 팀장
F11: 롯데아울렛광명점 | G11: 김경훈 팀장
F12: (온)롯데잠실 | G12: 김경훈 팀장
F13: (온)롯데창원 | G13: 김경훈 팀장
F14: (온)신세계마산 | G14: 김경훈 팀장
F15: (온)신세계강남 | G15: 김경훈 팀장
F16: (온)신세계김해 | G16: 김경훈 팀장
F17: (온)갤러리아천안 | G17: 김경훈 팀장
F18: (온)롯데아울렛김해 | G18: 김경훈 팀장
F19: (온)롯데아울렛광명 | G19: 김경훈 팀장
... F107: 현대아울렛남양주점 | G107: 유정훈 대리

Sheet 26년 5월경비
F1: 4 | G1: 5 | H1: 6 | I1: 7 | J1: 8 | K1: 9 | L1: 10 | N1: 11 | O1: 12 | P1: 2 | Q1: 3 | R1: 4 | S1: 5 | T1: 6 | U1: 7 | V1: 8 | W1: 9 | X1: 11 | Y1: 22 | Z1: 23 | AA1: 24 | AB1: 25 | AC1: 26 | AD1: 27 | AE1: 28 | AF1: 29 | AG1: 30 | AH1: 31 | AI1: 32 | AJ1: 33 | AK1: 34 | AL1: 35 | AM1: 36 | AN1: 37 | AO1: 38
D2: 구 분 | E2: 26년 경 비 내 역 | P2: 25년 경 비 내 역 | Z2: 전년 대비 경 비 내 역
A3: 담당자 | B3: NO. | C3: 직택배 시행기간 | D3: 매장명 | E3: 26년 5월 매출 | F3: 고객배송 택배비 | G3: 건수 | H3: 매장 수평 택배비 | I3: 건수 | J3: 매장경비 | K3: 건수 | L3: 계 | M3: 매출대비 전체비율 | P3: 25년 5월 매출 | Q3: 고객배송 택배비 | R3: 건수 | S3: 매장 수평 택배비 | T3: 건수 | U3: 매장경비 | V3: 건수 | W3: 계 | X3: 매출대비 전체비율 | Z3: 전년 대비 매출 | AA3: 고객배송 택배비 | AB3: 건수 | AC3: 매장 수평 택배비 | AD3: 건수 | AE3: 매장경비 | AF3: 건수 | AG3: 계 | AH3: 확인 | AI3: 비고란 | AJ3: 근로계약서 | AL3: 고객배송 기본택배비 | AM3: 고객배송 택배업체 | AN3: 비고 | AO3: 수평,고객배송 과다체크
A4: 김경훈 팀장 | B4: 1 | C4: 45432 | D4: 신세계김해점 | E4: =VLOOKUP(D4,매출!C:J,8,0) -> 64638670 | F4: =IFERROR(VLOOKUP($D4,매장경비정리!$C:$K,F$1,FALSE),0) -> 190500 | G4: =IFERROR(VLOOKUP($D4,매장경비정리!$C:$K,G$1,FALSE),0) -> 58 | H4: =IFERROR(VLOOKUP($D4,매장경비정리!$C:$K,H$1,FALSE),0) -> 56000 | I4: =IFERROR(VLOOKUP($D4,매장경비정리!$C:$K,I$1,FALSE),0) -> 14 | J4: =IFERROR(VLOOKUP($D4,매장경비정리!$C:$K,J$1,FALSE),0) -> 76150 | K4: =IFERROR(VLOOKUP($D4,매장경비정리!$C:$K,K$1,FALSE),0) -> 2 | L4: =SUM(F4,H4,J4) -> 322650 | M4: =L4/E4 -> 0.004991594 | P4: =VLOOKUP($D4,'[1]25년 5월경비'!$D:$M,P$1,FALSE) -> 45572690 | Q4: =VLOOKUP($D4,'[1]25년 5월경비'!$D:$M,Q$1,FALSE) -> 19800 | R4: =VLOOKUP($D4,'[1]25년 5월경비'!$D:$M,R$1,FALSE) -> 4 | S4: =VLOOKUP($D4,'[1]25년 5월경비'!$D:$M,S$1,FALSE) -> 101000 | T4: =VLOOKUP($D4,'[1]25년 5월경비'!$D:$M,T$1,FALSE) -> 24 | U4: =VLOOKUP($D4,'[1]25년 5월경비'!$D:$M,U$1,FALSE) -> 3500 | V4: =VLOOKUP($D4,'[1]25년 5월경비'!$D:$M,V$1,FALSE) -> 1 | W4: =VLOOKUP($D4,'[1]25년 5월경비'!$D:$M,W$1,FALSE) -> 124300 | X4: =W4/P4 -> 0.0027275107 | Z4: =E4-P4 -> 19065980 | AA4: =F4-Q4 -> 170700 | AB4: =G4-R4 -> 54 | AC4: =H4-S4 -> -45000 | AD4: =I4-T4 -> -10 | AE4: =J4-U4 -> 72650 | AF4: =K4-V4 -> 1 | AG4: =L4-W4 -> 198350
B5: 2 | C5: 45357 | D5: 롯데아울렛김해점 | E5: =VLOOKUP(D5,매출!C:J,8,0) -> 119883530 | F5: =IFERROR(VLOOKUP($D5,매장경비정리!$C:$K,F$1,FALSE),0) -> 0 | G5: =IFERROR(VLOOKUP($D5,매장경비정리!$C:$K,G$1,FALSE),0) -> 0 | H5: =IFERROR(VLOOKUP($D5,매장경비정리!$C:$K,H$1,FALSE),0) -> 0 | I5: =IFERROR(VLOOKUP($D5,매장경비정리!$C:$K,I$1,FALSE),0) -> 0 | J5: =IFERROR(VLOOKUP($D5,매장경비정리!$C:$K,J$1,FALSE),0) -> 0 | K5: =IFERROR(VLOOKUP($D5,매장경비정리!$C:$K,K$1,FALSE),0) -> 0 | L5: =SUM(F5,H5,J5) -> 0 | M5: =L5/E5 -> 0 | P5: =VLOOKUP($D5,'[1]25년 5월경비'!$D:$M,P$1,FALSE) -> 76085360 | Q5: =VLOOKUP($D5,'[1]25년 5월경비'!$D:$M,Q$1,FALSE) -> 0 | R5: =VLOOKUP($D5,'[1]25년 5월경비'!$D:$M,R$1,FALSE) -> 0 | S5: =VLOOKUP($D5,'[1]25년 5월경비'!$D:$M,S$1,FALSE) -> 0 | T5: =VLOOKUP($D5,'[1]25년 5월경비'!$D:$M,T$1,FALSE) -> 0 | U5: =VLOOKUP($D5,'[1]25년 5월경비'!$D:$M,U$1,FALSE) -> 0 | V5: =VLOOKUP($D5,'[1]25년 5월경비'!$D:$M,V$1,FALSE) -> 0 | W5: =VLOOKUP($D5,'[1]25년 5월경비'!$D:$M,W$1,FALSE) -> 0 | X5: =W5/P5 -> 0 | Z5: =E5-P5 -> 43798170 | AA5: =F5-Q5 -> 0 | AB5: =G5-R5 -> 0 | AC5: =H5-S5 -> 0 | AD5: =I5-T5 -> 0 | AE5: =J5-U5 -> 0 | AF5: =K5-V5 -> 0 | AG5: =L5-W5 -> 0
B6: 3 | C6: 45357 | D6: 갤러리아진주점 | E6: =VLOOKUP(D6,매출!C:J,8,0) -> 24307440 | F6: =IFERROR(VLOOKUP($D6,매장경비정리!$C:$K,F$1,FALSE),0) -> 0 | G6: =IFERROR(VLOOKUP($D6,매장경비정리!$C:$K,G$1,FALSE),0) -> 0 | H6: =IFERROR(VLOOKUP($D6,매장경비정리!$C:$K,H$1,FALSE),0) -> 12500 | I6: =IFERROR(VLOOKUP($D6,매장경비정리!$C:$K,I$1,FALSE),0) -> 3 | J6: =IFERROR(VLOOKUP($D6,매장경비정리!$C:$K,J$1,FALSE),0) -> 0 | K6: =IFERROR(VLOOKUP($D6,매장경비정리!$C:$K,K$1,FALSE),0) -> 0 | L6: =SUM(F6,H6,J6) -> 12500 | M6: =L6/E6 -> 0.00051424584 | P6: =VLOOKUP($D6,'[1]25년 5월경비'!$D:$M,P$1,FALSE) -> 24241030 | Q6: =VLOOKUP($D6,'[1]25년 5월경비'!$D:$M,Q$1,FALSE) -> 0 | R6: =VLOOKUP($D6,'[1]25년 5월경비'!$D:$M,R$1,FALSE) -> 0 | S6: =VLOOKUP($D6,'[1]25년 5월경비'!$D:$M,S$1,FALSE) -> 83900 | T6: =VLOOKUP($D6,'[1]25년 5월경비'!$D:$M,T$1,FALSE) -> 19 | U6: =VLOOKUP($D6,'[1]25년 5월경비'!$D:$M,U$1,FALSE) -> 0 | V6: =VLOOKUP($D6,'[1]25년 5월경비'!$D:$M,V$1,FALSE) -> 0 | W6: =VLOOKUP($D6,'[1]25년 5월경비'!$D:$M,W$1,FALSE) -> 83900 | X6: =W6/P6 -> 0.0034610741 | Z6: =E6-P6 -> 66410 | AA6: =F6-Q6 -> 0 | AB6: =G6-R6 -> 0 | AC6: =H6-S6 -> -71400 | AD6: =I6-T6 -> -16 | AE6: =J6-U6 -> 0 | AF6: =K6-V6 -> 0 | AG6: =L6-W6 -> -71400
E7: =SUM(E4:E6) -> 208829640 | F7: =SUM(F4:F6) -> 190500 | G7: =SUM(G4:G6) -> 58 | H7: =SUM(H4:H6) -> 68500 | I7: =SUM(I4:I6) -> 17 | J7: =SUM(J4:J6) -> 76150 | K7: =SUM(K4:K6) -> 2 | L7: =SUM(L4:L6) -> 335150 | M7: =L7/E7 -> 0.0016048967 | P7: =SUM(P4:P6) -> 145899080 | Q7: =SUM(Q4:Q6) -> 19800 | R7: =SUM(R4:R6) -> 4 | S7: =SUM(S4:S6) -> 184900 | T7: =SUM(T4:T6) -> 43 | U7: =SUM(U4:U6) -> 3500 | V7: =SUM(V4:V6) -> 1 | W7: =SUM(W4:W6) -> 208200 | X7: =W7/P7 -> 0.0014270138 | Z7: =SUM(Z4:Z6) -> 62930560 | AA7: =SUM(AA4:AA6) -> 170700 | AB7: =SUM(AB4:AB6) -> 54 | AC7: =SUM(AC4:AC6) -> -116400 | AD7: =SUM(AD4:AD6) -> -26 | AE7: =SUM(AE4:AE6) -> 72650 | AF7: =SUM(AF4:AF6) -> 1 | AG7: =SUM(AG4:AG6) -> 126950
A9: 담당자 | B9: NO. | C9: 직택배 시행기간 | D9: 매장명 | E9: 26년 5월 매출 | F9: 고객배송 택배비 | G9: 건수 | H9: 매장 수평 택배비 | I9: 건수 | J9: 매장경비 | K9: 건수 | L9: 계 | M9: 매출대비 전체비율 | P9: 25년 5월 매출 | Q9: 고객배송 택배비 | R9: 건수 | S9: 매장 수평 택배비 | T9: 건수 | U9: 매장경비 | V9: 건수 | W9: 계 | X9: 매출대비 전체비율 | Z9: 전년 대비 매출 | AA9: 고객배송 택배비 | AB9: 건수 | AC9: 매장 수평 택배비 | AD9: 건수 | AE9: 매장경비 | AF9: 건수 | AG9: 계 | AH9: 확인 | AI9: 비고란 | AJ9: 근로계약서 | AL9: 고객배송 기본택배비 | AM9: 고객배송 택배업체 | AN9: 비고 | AO9: 수평,고객배송 과다체크
A10: 원태윤 차장 | B10: 1 | C10: 45425 | D10: 롯데수원점 | E10: =VLOOKUP(D10,매출!C:J,8,0) -> 38562070 | F10: =IFERROR(VLOOKUP($D10,매장경비정리!$C:$K,F$1,FALSE),0) -> 78000 | G10: =IFERROR(VLOOKUP($D10,매장경비정리!$C:$K,G$1,FALSE),0) -> 20 | H10: =IFERROR(VLOOKUP($D10,매장경비정리!$C:$K,H$1,FALSE),0) -> 57000 | I10: =IFERROR(VLOOKUP($D10,매장경비정리!$C:$K,I$1,FALSE),0) -> 14 | J10: =IFERROR(VLOOKUP($D10,매장경비정리!$C:$K,J$1,FALSE),0) -> 0 | K10: =IFERROR(VLOOKUP($D10,매장경비정리!$C:$K,K$1,FALSE),0) -> 0 | L10: =SUM(F10,H10,J10) -> 135000 | M10: =L10/E10 -> 0.0035008494 | P10: =VLOOKUP($D10,'[1]25년 5월경비'!$D:$M,P$1,FALSE) -> 44165350 | Q10: =VLOOKUP($D10,'[1]25년 5월경비'!$D:$M,Q$1,FALSE) -> 80000 | R10: =VLOOKUP($D10,'[1]25년 5월경비'!$D:$M,R$1,FALSE) -> 20 | S10: =VLOOKUP($D10,'[1]25년 5월경비'!$D:$M,S$1,FALSE) -> 152100 | T10: =VLOOKUP($D10,'[1]25년 5월경비'!$D:$M,T$1,FALSE) -> 38 | U10: =VLOOKUP($D10,'[1]25년 5월경비'!$D:$M,U$1,FALSE) -> 0 | V10: =VLOOKUP($D10,'[1]25년 5월경비'!$D:$M,V$1,FALSE) -> 0 | W10: =VLOOKUP($D10,'[1]25년 5월경비'!$D:$M,W$1,FALSE) -> 232100 | X10: =W10/P10 -> 0.005255251 | Z10: =E10-P10 -> -5603280 | AA10: =F10-Q10 -> -2000 | AB10: =G10-R10 -> 0 | AC10: =H10-S10 -> -95100 | AD10: =I10-T10 -> -24 | AE10: =J10-U10 -> 0 | AF10: =K10-V10 -> 0 | AG10: =L10-W10 -> -97100
B11: 2 | C11: 45425 | D11: 롯데안산점 | E11: =VLOOKUP(D11,매출!C:J,8,0) -> 45105140 | F11: =IFERROR(VLOOKUP($D11,매장경비정리!$C:$K,F$1,FALSE),0) -> 62000 | G11: =IFERROR(VLOOKUP($D11,매장경비정리!$C:$K,G$1,FALSE),0) -> 15 | H11: =IFERROR(VLOOKUP($D11,매장경비정리!$C:$K,H$1,FALSE),0) -> 90950 | I11: =IFERROR(VLOOKUP($D11,매장경비정리!$C:$K,I$1,FALSE),0) -> 22 | J11: =IFERROR(VLOOKUP($D11,매장경비정리!$C:$K,J$1,FALSE),0) -> 0 | K11: =IFERROR(VLOOKUP($D11,매장경비정리!$C:$K,K$1,FALSE),0) -> 0 | L11: =SUM(F11,H11,J11) -> 152950 | M11: =L11/E11 -> 0.0033909661 | P11: =VLOOKUP($D11,'[1]25년 5월경비'!$D:$M,P$1,FALSE) -> 34977600 | Q11: =VLOOKUP($D11,'[1]25년 5월경비'!$D:$M,Q$1,FALSE) -> 48000 | R11: =VLOOKUP($D11,'[1]25년 5월경비'!$D:$M,R$1,FALSE) -> 8 | S11: =VLOOKUP($D11,'[1]25년 5월경비'!$D:$M,S$1,FALSE) -> 63270 | T11: =VLOOKUP($D11,'[1]25년 5월경비'!$D:$M,T$1,FALSE) -> 16 | U11: =VLOOKUP($D11,'[1]25년 5월경비'!$D:$M,U$1,FALSE) -> 54500 | V11: =VLOOKUP($D11,'[1]25년 5월경비'!$D:$M,V$1,FALSE) -> 2 | W11: =VLOOKUP($D11,'[1]25년 5월경비'!$D:$M,W$1,FALSE) -> 165770 | X11: =W11/P11 -> 0.0047393189 | Z11: =E11-P11 -> 10127540 | AA11: =F11-Q11 -> 14000 | AB11: =G11-R11 -> 7 | AC11: =H11-S11 -> 27680 | AD11: =I11-T11 -> 6 | AE11: =J11-U11 -> -54500 | AF11: =K11-V11 -> -2 | AG11: =L11-W11 -> -12820
B12: 3 | C12: 45418 | D12: 신세계대전점 | E12: =VLOOKUP(D12,매출!C:J,8,0) -> 57171610 | F12: =IFERROR(VLOOKUP($D12,매장경비정리!$C:$K,F$1,FALSE),0) -> 140000 | G12: =IFERROR(VLOOKUP($D12,매장경비정리!$C:$K,G$1,FALSE),0) -> 13 | H12: =IFERROR(VLOOKUP($D12,매장경비정리!$C:$K,H$1,FALSE),0) -> 66400 | I12: =IFERROR(VLOOKUP($D12,매장경비정리!$C:$K,I$1,FALSE),0) -> 13 | J12: =IFERROR(VLOOKUP($D12,매장경비정리!$C:$K,J$1,FALSE),0) -> 0 | K12: =IFERROR(VLOOKUP($D12,매장경비정리!$C:$K,K$1,FALSE),0) -> 0 | L12: =SUM(F12,H12,J12) -> 206400 | M12: =L12/E12 -> 0.0036101834 | P12: =VLOOKUP($D12,'[1]25년 5월경비'!$D:$M,P$1,FALSE) -> 52541860 | Q12: =VLOOKUP($D12,'[1]25년 5월경비'!$D:$M,Q$1,FALSE) -> 152000 | R12: =VLOOKUP($D12,'[1]25년 5월경비'!$D:$M,R$1,FALSE) -> 14 | S12: =VLOOKUP($D12,'[1]25년 5월경비'!$D:$M,S$1,FALSE) -> 70900 | T12: =VLOOKUP($D12,'[1]25년 5월경비'!$D:$M,T$1,FALSE) -> 17 | U12: =VLOOKUP($D12,'[1]25년 5월경비'!$D:$M,U$1,FALSE) -> 0 | V12: =VLOOKUP($D12,'[1]25년 5월경비'!$D:$M,V$1,FALSE) -> 0 | W12: =VLOOKUP($D12,'[1]25년 5월경비'!$D:$M,W$1,FALSE) -> 222900 | X12: =W12/P12 -> 0.0042423317 | Z12: =E12-P12 -> 4629750 | AA12: =F12-Q12 -> -12000 | AB12: =G12-R12 -> -1 | AC12: =H12-S12 -> -4500 | AD12: =I12-T12 -> -4 | AE12: =J12-U12 -> 0 | AF12: =K12-V12 -> 0 | AG12: =L12-W12 -> -16500
B13: 4 | C13: 45357 | D13: 신세계천안아산점 | E13: =VLOOKUP(D13,매출!C:J,8,0) -> 38455850 | F13: =IFERROR(VLOOKUP($D13,매장경비정리!$C:$K,F$1,FALSE),0) -> 94000 | G13: =IFERROR(VLOOKUP($D13,매장경비정리!$C:$K,G$1,FALSE),0) -> 23 | H13: =IFERROR(VLOOKUP($D13,매장경비정리!$C:$K,H$1,FALSE),0) -> 43200 | I13: =IFERROR(VLOOKUP($D13,매장경비정리!$C:$K,I$1,FALSE),0) -> 11 | J13: =IFERROR(VLOOKUP($D13,매장경비정리!$C:$K,J$1,FALSE),0) -> 0 | K13: =IFERROR(VLOOKUP($D13,매장경비정리!$C:$K,K$1,FALSE),0) -> 0 | L13: =SUM(F13,H13,J13) -> 137200 | M13: =L13/E13 -> 0.0035677277 | P13: =VLOOKUP($D13,'[1]25년 5월경비'!$D:$M,P$1,FALSE) -> 25106730 | Q13: =VLOOKUP($D13,'[1]25년 5월경비'!$D:$M,Q$1,FALSE) -> 129000 | R13: =VLOOKUP($D13,'[1]25년 5월경비'!$D:$M,R$1,FALSE) -> 28 | S13: =VLOOKUP($D13,'[1]25년 5월경비'!$D:$M,S$1,FALSE) -> 41500 | T13: =VLOOKUP($D13,'[1]25년 5월경비'!$D:$M,T$1,FALSE) -> 10 | U13: =VLOOKUP($D13,'[1]25년 5월경비'!$D:$M,U$1,FALSE) -> 4000 | V13: =VLOOKUP($D13,'[1]25년 5월경비'!$D:$M,V$1,FALSE) -> 1 | W13: =VLOOKUP($D13,'[1]25년 5월경비'!$D:$M,W$1,FALSE) -> 174500 | X13: =W13/P13 -> 0.0069503277 | Z13: =E13-P13 -> 13349120 | AA13: =F13-Q13 -> -35000 | AB13: =G13-R13 -> -5 | AC13: =H13-S13 -> 1700 | AD13: =I13-T13 -> 1 | AE13: =J13-U13 -> -4000 | AF13: =K13-V13 -> -1 | AG13: =L13-W13 -> -37300
B14: 5 | C14: 45338 | D14: 갤러리아천안점 | E14: =VLOOKUP(D14,매출!C:J,8,0) -> 46885330 | F14: =IFERROR(VLOOKUP($D14,매장경비정리!$C:$K,F$1,FALSE),0) -> 200000 | G14: =IFERROR(VLOOKUP($D14,매장경비정리!$C:$K,G$1,FALSE),0) -> 40 | H14: =IFERROR(VLOOKUP($D14,매장경비정리!$C:$K,H$1,FALSE),0) -> 25500 | I14: =IFERROR(VLOOKUP($D14,매장경비정리!$C:$K,I$1,FALSE),0) -> 6 | J14: =IFERROR(VLOOKUP($D14,매장경비정리!$C:$K,J$1,FALSE),0) -> 0 | K14: =IFERROR(VLOOKUP($D14,매장경비정리!$C:$K,K$1,FALSE),0) -> 0 | L14: =SUM(F14,H14,J14) -> 225500 | M14: =L14/E14 -> 0.0048096068 | P14: =VLOOKUP($D14,'[1]25년 5월경비'!$D:$M,P$1,FALSE) -> 55817820 | Q14: =VLOOKUP($D14,'[1]25년 5월경비'!$D:$M,Q$1,FALSE) -> 98000 | R14: =VLOOKUP($D14,'[1]25년 5월경비'!$D:$M,R$1,FALSE) -> 19 | S14: =VLOOKUP($D14,'[1]25년 5월경비'!$D:$M,S$1,FALSE) -> 101650 | T14: =VLOOKUP($D14,'[1]25년 5월경비'!$D:$M,T$1,FALSE) -> 25 | U14: =VLOOKUP($D14,'[1]25년 5월경비'!$D:$M,U$1,FALSE) -> 0 | V14: =VLOOKUP($D14,'[1]25년 5월경비'!$D:$M,V$1,FALSE) -> 0 | W14: =VLOOKUP($D14,'[1]25년 5월경비'!$D:$M,W$1,FALSE) -> 199650 | X14: =W14/P14 -> 0.0035768147 | Z14: =E14-P14 -> -8932490 | AA14: =F14-Q14 -> 102000 | AB14: =G14-R14 -> 21 | AC14: =H14-S14 -> -76150 | AD14: =I14-T14 -> -19 | AE14: =J14-U14 -> 0 | AF14: =K14-V14 -> 0 | AG14: =L14-W14 -> 25850
B15: 6 | D15: AK프라자수원점 | E15: =VLOOKUP(D15,매출!C:J,8,0) -> 58176500 | F15: =IFERROR(VLOOKUP($D15,매장경비정리!$C:$K,F$1,FALSE),0) -> 374900 | G15: =IFERROR(VLOOKUP($D15,매장경비정리!$C:$K,G$1,FALSE),0) -> 92 | H15: =IFERROR(VLOOKUP($D15,매장경비정리!$C:$K,H$1,FALSE),0) -> 54100 | I15: =IFERROR(VLOOKUP($D15,매장경비정리!$C:$K,I$1,FALSE),0) -> 14 | J15: =IFERROR(VLOOKUP($D15,매장경비정리!$C:$K,J$1,FALSE),0) -> 0 | K15: =IFERROR(VLOOKUP($D15,매장경비정리!$C:$K,K$1,FALSE),0) -> 0 | L15: =SUM(F15,H15,J15) -> 429000 | M15: =L15/E15 -> 0.0073741115 | P15: 0 | Q15: 0 | R15: 0 | S15: 0 | T15: 0 | U15: 0 | V15: 0 | W15: 0 | X15: =IFERROR(W15/P15,"") | Z15: =E15-P15 -> 58176500 | AA15: =F15-Q15 -> 374900 | AB15: =G15-R15 -> 92 | AC15: =H15-S15 -> 54100 | AD15: =I15-T15 -> 14 | AE15: =J15-U15 -> 0 | AF15: =K15-V15 -> 0 | AG15: =L15-W15 -> 429000
B16: 7 | C16: 45425 | D16: 롯데아울렛광명점 | E16: =VLOOKUP(D16,매출!C:J,8,0) -> 44347650 | F16: =IFERROR(VLOOKUP($D16,매장경비정리!$C:$K,F$1,FALSE),0) -> 121500 | G16: =IFERROR(VLOOKUP($D16,매장경비정리!$C:$K,G$1,FALSE),0) -> 29 | H16: =IFERROR(VLOOKUP($D16,매장경비정리!$C:$K,H$1,FALSE),0) -> 37500 | I16: =IFERROR(VLOOKUP($D16,매장경비정리!$C:$K,I$1,FALSE),0) -> 9 | J16: =IFERROR(VLOOKUP($D16,매장경비정리!$C:$K,J$1,FALSE),0) -> 3500 | K16: =IFERROR(VLOOKUP($D16,매장경비정리!$C:$K,K$1,FALSE),0) -> 1 | L16: =SUM(F16,H16,J16) -> 162500 | M16: =L16/E16 -> 0.0036642302 | P16: =VLOOKUP($D16,'[1]25년 5월경비'!$D:$M,P$1,FALSE) -> 41370060 | Q16: =VLOOKUP($D16,'[1]25년 5월경비'!$D:$M,Q$1,FALSE) -> 140000 | R16: =VLOOKUP($D16,'[1]25년 5월경비'!$D:$M,R$1,FALSE) -> 31 | S16: =VLOOKUP($D16,'[1]25년 5월경비'!$D:$M,S$1,FALSE) -> 42300 | T16: =VLOOKUP($D16,'[1]25년 5월경비'!$D:$M,T$1,FALSE) -> 11 | U16: =VLOOKUP($D16,'[1]25년 5월경비'!$D:$M,U$1,FALSE) -> 62000 | V16: =VLOOKUP($D16,'[1]25년 5월경비'!$D:$M,V$1,FALSE) -> 3 | W16: =VLOOKUP($D16,'[1]25년 5월경비'!$D:$M,W$1,FALSE) -> 244300 | X16: =W16/P16 -> 0.0059052368 | Z16: =E16-P16 -> 2977590 | AA16: =F16-Q16 -> -18500 | AB16: =G16-R16 -> -2 | AC16: =H16-S16 -> -4800 | AD16: =I16-T16 -> -2 | AE16: =J16-U16 -> -58500 | AF16: =K16-V16 -> -2 | AG16: =L16-W16 -> -81800
B17: 8 | C17: 45323 | D17: 롯데아울렛군산점 | E17: =VLOOKUP(D17,매출!C:J,8,0) -> 38322990 | F17: =IFERROR(VLOOKUP($D17,매장경비정리!$C:$K,F$1,FALSE),0) -> 71400 | G17: =IFERROR(VLOOKUP($D17,매장경비정리!$C:$K,G$1,FALSE),0) -> 19 | H17: =IFERROR(VLOOKUP($D17,매장경비정리!$C:$K,H$1,FALSE),0) -> 32600 | I17: =IFERROR(VLOOKUP($D17,매장경비정리!$C:$K,I$1,FALSE),0) -> 7 | J17: =IFERROR(VLOOKUP($D17,매장경비정리!$C:$K,J$1,FALSE),0) -> 0 | K17: =IFERROR(VLOOKUP($D17,매장경비정리!$C:$K,K$1,FALSE),0) -> 0 | L17: =SUM(F17,H17,J17) -> 104000 | M17: =L17/E17 -> 0.0027137757 | P17: =VLOOKUP($D17,'[1]25년 5월경비'!$D:$M,P$1,FALSE) -> 29381510 | Q17: =VLOOKUP($D17,'[1]25년 5월경비'!$D:$M,Q$1,FALSE) -> 132600 | R17: =VLOOKUP($D17,'[1]25년 5월경비'!$D:$M,R$1,FALSE) -> 37 | S17: =VLOOKUP($D17,'[1]25년 5월경비'!$D:$M,S$1,FALSE) -> 86400 | T17: =VLOOKUP($D17,'[1]25년 5월경비'!$D:$M,T$1,FALSE) -> 21 | U17: =VLOOKUP($D17,'[1]25년 5월경비'!$D:$M,U$1,FALSE) -> 0 | V17: =VLOOKUP($D17,'[1]25년 5월경비'!$D:$M,V$1,FALSE) -> 0 | W17: =VLOOKUP($D17,'[1]25년 5월경비'!$D:$M,W$1,FALSE) -> 219000 | X17: =W17/P17 -> 0.0074536673 | Z17: =E17-P17 -> 8941480 | AA17: =F17-Q17 -> -61200 | AB17: =G17-R17 -> -18 | AC17: =H17-S17 -> -53800 | AD17: =I17-T17 -> -14 | AE17: =J17-U17 -> 0 | AF17: =K17-V17 -> 0 | AG17: =L17-W17 -> -115000
B18: 9 | C18: 45357 | D18: 현대아울렛대전점 | E18: =VLOOKUP(D18,매출!C:J,8,0) -> 112038310 | F18: =IFERROR(VLOOKUP($D18,매장경비정리!$C:$K,F$1,FALSE),0) -> 0 | G18: =IFERROR(VLOOKUP($D18,매장경비정리!$C:$K,G$1,FALSE),0) -> 0 | H18: =IFERROR(VLOOKUP($D18,매장경비정리!$C:$K,H$1,FALSE),0) -> 0 | I18: =IFERROR(VLOOKUP($D18,매장경비정리!$C:$K,I$1,FALSE),0) -> 0 | J18: =IFERROR(VLOOKUP($D18,매장경비정리!$C:$K,J$1,FALSE),0) -> 0 | K18: =IFERROR(VLOOKUP($D18,매장경비정리!$C:$K,K$1,FALSE),0) -> 0 | L18: =SUM(F18,H18,J18) -> 0 | M18: =L18/E18 -> 0 | P18: =VLOOKUP($D18,'[1]25년 5월경비'!$D:$M,P$1,FALSE) -> 96500780 | Q18: =VLOOKUP($D18,'[1]25년 5월경비'!$D:$M,Q$1,FALSE) -> 0 | R18: =VLOOKUP($D18,'[1]25년 5월경비'!$D:$M,R$1,FALSE) -> 0 | S18: =VLOOKUP($D18,'[1]25년 5월경비'!$D:$M,S$1,FALSE) -> 0 | T18: =VLOOKUP($D18,'[1]25년 5월경비'!$D:$M,T$1,FALSE) -> 0 | U18: =VLOOKUP($D18,'[1]25년 5월경비'!$D:$M,U$1,FALSE) -> 0 | V18: =VLOOKUP($D18,'[1]25년 5월경비'!$D:$M,V$1,FALSE) -> 0 | W18: =VLOOKUP($D18,'[1]25년 5월경비'!$D:$M,W$1,FALSE) -> 0 | Z18: =E18-P18 -> 15537530 | AA18: =F18-Q18 -> 0 | AB18: =G18-R18 -> 0 | AC18: =H18-S18 -> 0 | AD18: =I18-T18 -> 0 | AE18: =J18-U18 -> 0 | AF18: =K18-V18 -> 0 | AG18: =L18-W18 -> 0
B19: 10 | C19: 45404 | D19: LF스퀘어양주점 | E19: =VLOOKUP(D19,매출!C:J,8,0) -> 55264530 | F19: =IFERROR(VLOOKUP($D19,매장경비정리!$C:$K,F$1,FALSE),0) -> 165450 | G19: =IFERROR(VLOOKUP($D19,매장경비정리!$C:$K,G$1,FALSE),0) -> 42 | H19: =IFERROR(VLOOKUP($D19,매장경비정리!$C:$K,H$1,FALSE),0) -> 32500 | I19: =IFERROR(VLOOKUP($D19,매장경비정리!$C:$K,I$1,FALSE),0) -> 8 | J19: =IFERROR(VLOOKUP($D19,매장경비정리!$C:$K,J$1,FALSE),0) -> 0 | K19: =IFERROR(VLOOKUP($D19,매장경비정리!$C:$K,K$1,FALSE),0) -> 0 | L19: =SUM(F19,H19,J19) -> 197950 | M19: =L19/E19 -> 0.0035818634 | P19: =VLOOKUP($D19,'[1]25년 5월경비'!$D:$M,P$1,FALSE) -> 62599320 | Q19: =VLOOKUP($D19,'[1]25년 5월경비'!$D:$M,Q$1,FALSE) -> 322150 | R19: =VLOOKUP($D19,'[1]25년 5월경비'!$D:$M,R$1,FALSE) -> 78 | S19: =VLOOKUP($D19,'[1]25년 5월경비'!$D:$M,S$1,FALSE) -> 0 | T19: =VLOOKUP($D19,'[1]25년 5월경비'!$D:$M,T$1,FALSE) -> 0 | U19: =VLOOKUP($D19,'[1]25년 5월경비'!$D:$M,U$1,FALSE) -> 0 | V19: =VLOOKUP($D19,'[1]25년 5월경비'!$D:$M,V$1,FALSE) -> 0 | W19: =VLOOKUP($D19,'[1]25년 5월경비'!$D:$M,W$1,FALSE) -> 322150 | X19: =W19/P19 -> 0.005146222 | Z19: =E19-P19 -> -7334790 | AA19: =F19-Q19 -> -156700 | AB19: =G19-R19 -> -36 | AC19: =H19-S19 -> 32500 | AD19: =I19-T19 -> 8 | AE19: =J19-U19 -> 0 | AF19: =K19-V19 -> 0 | AG19: =L19-W19 -> -124200
E20: =SUM(E10:E19) -> 534329980 | F20: =SUM(F10:F19) -> 1307250 | G20: =SUM(G10:G19) -> 293 | H20: =SUM(H10:H19) -> 439750 | I20: =SUM(I10:I19) -> 104 | J20: =SUM(J10:J19) -> 3500 | K20: =SUM(K10:K19) -> 1 | L20: =SUM(L10:L19) -> 1750500 | M20: =L20/E20 -> 0.0032760655 | P20: =SUM(P10:P19) -> 442461030 | Q20: =SUM(Q10:Q19) -> 1101750 | R20: =SUM(R10:R19) -> 235 | S20: =SUM(S10:S19) -> 558120 | T20: =SUM(T10:T19) -> 138 | U20: =SUM(U10:U19) -> 120500 | V20: =SUM(V10:V19) -> 6 | W20: =SUM(W10:W19) -> 1780370 | X20: =W20/P20 -> 0.0040237894 | Z20: =SUM(Z10:Z19) -> 91868950 | AA20: =SUM(AA10:AA19) -> 205500 | AB20: =SUM(AB10:AB19) -> 58 | AC20: =SUM(AC10:AC19) -> -118370 | AD20: =SUM(AD10:AD19) -> -34 | AE20: =SUM(AE10:AE19) -> -117000 | AF20: =SUM(AF10:AF19) -> -5 | AG20: =SUM(AG10:AG19) -> -29870
A22: 담당자 | B22: NO. | C22: 직택배 시행기간 | D22: 매장명 | E22: 26년 5월 매출 | F22: 고객배송 택배비 | G22: 건수 | H22: 매장 수평 택배비 | I22: 건수 | J22: 매장경비 | K22: 건수 | L22: 계 | M22: 매출대비 전체비율 | P22: 25년 5월 매출 | Q22: 고객배송 택배비 | R22: 건수 | S22: 매장 수평 택배비 | T22: 건수 | U22: 매장경비 | V22: 건수 | W22: 계 | X22: 매출대비 전체비율 | Z22: 전년 대비 매출 | AA22: 고객배송 택배비 | AB22: 건수 | AC22: 매장 수평 택배비 | AD22: 건수 | AE22: 매장경비 | AF22: 건수 | AG22: 계 | AH22: 확인 | AI22: 비고란 | AJ22: 근로계약서 | AL22: 고객배송 기본택배비 | AM22: 고객배송 택배업체 | AN22: 비고 | AO22: 수평,고객배송 과다체크
A23: 안정우 팀장 | B23: 1 | C23: 45404 | D23: 롯데상인점 | E23: =VLOOKUP(D23,매출!C:J,8,0) -> 48142530 | F23: =IFERROR(VLOOKUP($D23,매장경비정리!$C:$K,F$1,FALSE),0) -> 70000 | G23: =IFERROR(VLOOKUP($D23,매장경비정리!$C:$K,G$1,FALSE),0) -> 15 | H23: =IFERROR(VLOOKUP($D23,매장경비정리!$C:$K,H$1,FALSE),0) -> 35500 | I23: =IFERROR(VLOOKUP($D23,매장경비정리!$C:$K,I$1,FALSE),0) -> 9 | J23: =IFERROR(VLOOKUP($D23,매장경비정리!$C:$K,J$1,FALSE),0) -> 0 | K23: =IFERROR(VLOOKUP($D23,매장경비정리!$C:$K,K$1,FALSE),0) -> 0 | L23: =SUM(F23,H23,J23) -> 105500 | M23: =L23/E23 -> 0.0021914095 | P23: =VLOOKUP($D23,'[1]25년 5월경비'!$D:$M,P$1,FALSE) -> 25730830 | Q23: =VLOOKUP($D23,'[1]25년 5월경비'!$D:$M,Q$1,FALSE) -> 24000 | R23: =VLOOKUP($D23,'[1]25년 5월경비'!$D:$M,R$1,FALSE) -> 3 | S23: =VLOOKUP($D23,'[1]25년 5월경비'!$D:$M,S$1,FALSE) -> 54000 | T23: =VLOOKUP($D23,'[1]25년 5월경비'!$D:$M,T$1,FALSE) -> 14 | U23: =VLOOKUP($D23,'[1]25년 5월경비'!$D:$M,U$1,FALSE) -> 0 | V23: =VLOOKUP($D23,'[1]25년 5월경비'!$D:$M,V$1,FALSE) -> 0 | W23: =VLOOKUP($D23,'[1]25년 5월경비'!$D:$M,W$1,FALSE) -> 78000 | X23: =W23/P23 -> 0.003031383 | Z23: =E23-P23 -> 22411700 | AA23: =F23-Q23 -> 46000 | AB23: =G23-R23 -> 12 | AC23: =H23-S23 -> -18500 | AD23: =I23-T23 -> -5 | AE23: =J23-U23 -> 0 | AF23: =K23-V23 -> 0 | AG23: =L23-W23 -> 27500
B24: 2 | C24: 45425 | D24: 롯데대구점 | E24: =VLOOKUP(D24,매출!C:J,8,0) -> 40477220 | F24: =IFERROR(VLOOKUP($D24,매장경비정리!$C:$K,F$1,FALSE),0) -> 134500 | G24: =IFERROR(VLOOKUP($D24,매장경비정리!$C:$K,G$1,FALSE),0) -> 18 | H24: =IFERROR(VLOOKUP($D24,매장경비정리!$C:$K,H$1,FALSE),0) -> 85500 | I24: =IFERROR(VLOOKUP($D24,매장경비정리!$C:$K,I$1,FALSE),0) -> 21 | J24: =IFERROR(VLOOKUP($D24,매장경비정리!$C:$K,J$1,FALSE),0) -> 0 | K24: =IFERROR(VLOOKUP($D24,매장경비정리!$C:$K,K$1,FALSE),0) -> 0 | L24: =SUM(F24,H24,J24) -> 220000 | M24: =L24/E24 -> 0.0054351559 | P24: =VLOOKUP($D24,'[1]25년 5월경비'!$D:$M,P$1,FALSE) -> 35200670 | Q24: =VLOOKUP($D24,'[1]25년 5월경비'!$D:$M,Q$1,FALSE) -> 80000 | R24: =VLOOKUP($D24,'[1]25년 5월경비'!$D:$M,R$1,FALSE) -> 12 | S24: =VLOOKUP($D24,'[1]25년 5월경비'!$D:$M,S$1,FALSE) -> 40670 | T24: =VLOOKUP($D24,'[1]25년 5월경비'!$D:$M,T$1,FALSE) -> 10 | U24: =VLOOKUP($D24,'[1]25년 5월경비'!$D:$M,U$1,FALSE) -> 0 | V24: =VLOOKUP($D24,'[1]25년 5월경비'!$D:$M,V$1,FALSE) -> 0 | W24: =VLOOKUP($D24,'[1]25년 5월경비'!$D:$M,W$1,FALSE) -> 120670 | X24: =W24/P24 -> 0.0034280597 | Z24: =E24-P24 -> 5276550 | AA24: =F24-Q24 -> 54500 | AB24: =G24-R24 -> 6 | AC24: =H24-S24 -> 44830 | AD24: =I24-T24 -> 11 | AE24: =J24-U24 -> 0 | AF24: =K24-V24 -> 0 | AG24: =L24-W24 -> 99330
B25: 3 | C25: 45418 | D25: 롯데인천터미널점 | E25: =VLOOKUP(D25,매출!C:J,8,0) -> 77019390 | F25: =IFERROR(VLOOKUP($D25,매장경비정리!$C:$K,F$1,FALSE),0) -> 66700 | G25: =IFERROR(VLOOKUP($D25,매장경비정리!$C:$K,G$1,FALSE),0) -> 15 | H25: =IFERROR(VLOOKUP($D25,매장경비정리!$C:$K,H$1,FALSE),0) -> 60500 | I25: =IFERROR(VLOOKUP($D25,매장경비정리!$C:$K,I$1,FALSE),0) -> 15 | J25: =IFERROR(VLOOKUP($D25,매장경비정리!$C:$K,J$1,FALSE),0) -> 4000 | K25: =IFERROR(VLOOKUP($D25,매장경비정리!$C:$K,K$1,FALSE),0) -> 1 | L25: =SUM(F25,H25,J25) -> 131200 | M25: =L25/E25 -> 0.0017034671 | P25: =VLOOKUP($D25,'[1]25년 5월경비'!$D:$M,P$1,FALSE) -> 117971560 | Q25: =VLOOKUP($D25,'[1]25년 5월경비'!$D:$M,Q$1,FALSE) -> 94400 | R25: =VLOOKUP($D25,'[1]25년 5월경비'!$D:$M,R$1,FALSE) -> 15 | S25: =VLOOKUP($D25,'[1]25년 5월경비'!$D:$M,S$1,FALSE) -> 113600 | T25: =VLOOKUP($D25,'[1]25년 5월경비'!$D:$M,T$1,FALSE) -> 28 | U25: =VLOOKUP($D25,'[1]25년 5월경비'!$D:$M,U$1,FALSE) -> 0 | V25: =VLOOKUP($D25,'[1]25년 5월경비'!$D:$M,V$1,FALSE) -> 0 | W25: =VLOOKUP($D25,'[1]25년 5월경비'!$D:$M,W$1,FALSE) -> 208000 | X25: =W25/P25 -> 0.0017631368 | Z25: =E25-P25 -> -40952170 | AA25: =F25-Q25 -> -27700 | AB25: =G25-R25 -> 0 | AC25: =H25-S25 -> -53100 | AD25: =I25-T25 -> -13 | AE25: =J25-U25 -> 4000 | AF25: =K25-V25 -> 1 | AG25: =L25-W25 -> -76800
B26: 4 | C26: 45418 | D26: 롯데동래점 | E26: =VLOOKUP(D26,매출!C:J,8,0) -> 31438100 | F26: =IFERROR(VLOOKUP($D26,매장경비정리!$C:$K,F$1,FALSE),0) -> 0 | G26: =IFERROR(VLOOKUP($D26,매장경비정리!$C:$K,G$1,FALSE),0) -> 0 | H26: =IFERROR(VLOOKUP($D26,매장경비정리!$C:$K,H$1,FALSE),0) -> 0 | I26: =IFERROR(VLOOKUP($D26,매장경비정리!$C:$K,I$1,FALSE),0) -> 0 | J26: =IFERROR(VLOOKUP($D26,매장경비정리!$C:$K,J$1,FALSE),0) -> 0 | K26: =IFERROR(VLOOKUP($D26,매장경비정리!$C:$K,K$1,FALSE),0) -> 0 | L26: =SUM(F26,H26,J26) -> 0 | M26: =L26/E26 -> 0 | P26: =VLOOKUP($D26,'[1]25년 5월경비'!$D:$M,P$1,FALSE) -> 27641950 | Q26: =VLOOKUP($D26,'[1]25년 5월경비'!$D:$M,Q$1,FALSE) -> 177000 | R26: =VLOOKUP($D26,'[1]25년 5월경비'!$D:$M,R$1,FALSE) -> 32 | S26: =VLOOKUP($D26,'[1]25년 5월경비'!$D:$M,S$1,FALSE) -> 54500 | T26: =VLOOKUP($D26,'[1]25년 5월경비'!$D:$M,T$1,FALSE) -> 13 | U26: =VLOOKUP($D26,'[1]25년 5월경비'!$D:$M,U$1,FALSE) -> 0 | V26: =VLOOKUP($D26,'[1]25년 5월경비'!$D:$M,V$1,FALSE) -> 0 | W26: =VLOOKUP($D26,'[1]25년 5월경비'!$D:$M,W$1,FALSE) -> 231500 | X26: =W26/P26 -> 0.0083749518 | Z26: =E26-P26 -> 3796150 | AA26: =F26-Q26 -> -177000 | AB26: =G26-R26 -> -32 | AC26: =H26-S26 -> -54500 | AD26: =I26-T26 -> -13 | AE26: =J26-U26 -> 0 | AF26: =K26-V26 -> 0 | AG26: =L26-W26 -> -231500
B27: 5 | C27: 45425 | D27: 롯데부산본점 | E27: =VLOOKUP(D27,매출!C:J,8,0) -> 128028400 | F27: =IFERROR(VLOOKUP($D27,매장경비정리!$C:$K,F$1,FALSE),0) -> 117000 | G27: =IFERROR(VLOOKUP($D27,매장경비정리!$C:$K,G$1,FALSE),0) -> 29 | H27: =IFERROR(VLOOKUP($D27,매장경비정리!$C:$K,H$1,FALSE),0) -> 108400 | I27: =IFERROR(VLOOKUP($D27,매장경비정리!$C:$K,I$1,FALSE),0) -> 27 | J27: =IFERROR(VLOOKUP($D27,매장경비정리!$C:$K,J$1,FALSE),0) -> 22000 | K27: =IFERROR(VLOOKUP($D27,매장경비정리!$C:$K,K$1,FALSE),0) -> 3 | L27: =SUM(F27,H27,J27) -> 247400 | M27: =L27/E27 -> 0.0019323838 | P27: =VLOOKUP($D27,'[1]25년 5월경비'!$D:$M,P$1,FALSE) -> 101004360 | Q27: =VLOOKUP($D27,'[1]25년 5월경비'!$D:$M,Q$1,FALSE) -> 166000 | R27: =VLOOKUP($D27,'[1]25년 5월경비'!$D:$M,R$1,FALSE) -> 29 | S27: =VLOOKUP($D27,'[1]25년 5월경비'!$D:$M,S$1,FALSE) -> 150100 | T27: =VLOOKUP($D27,'[1]25년 5월경비'!$D:$M,T$1,FALSE) -> 38 | U27: =VLOOKUP($D27,'[1]25년 5월경비'!$D:$M,U$1,FALSE) -> 62700 | V27: =VLOOKUP($D27,'[1]25년 5월경비'!$D:$M,V$1,FALSE) -> 4 | W27: =VLOOKUP($D27,'[1]25년 5월경비'!$D:$M,W$1,FALSE) -> 378800 | X27: =W27/P27 -> 0.0037503332 | Z27: =E27-P27 -> 27024040 | AA27: =F27-Q27 -> -49000 | AB27: =G27-R27 -> 0 | AC27: =H27-S27 -> -41700 | AD27: =I27-T27 -> -11 | AE27: =J27-U27 -> -40700 | AF27: =K27-V27 -> -1 | AG27: =L27-W27 -> -131400
B28: 6 | C28: 45411 | D28: 롯데광복점 | E28: =VLOOKUP(D28,매출!C:J,8,0) -> 53860630 | F28: =IFERROR(VLOOKUP($D28,매장경비정리!$C:$K,F$1,FALSE),0) -> 87000 | G28: =IFERROR(VLOOKUP($D28,매장경비정리!$C:$K,G$1,FALSE),0) -> 22 | H28: =IFERROR(VLOOKUP($D28,매장경비정리!$C:$K,H$1,FALSE),0) -> 42000 | I28: =IFERROR(VLOOKUP($D28,매장경비정리!$C:$K,I$1,FALSE),0) -> 11 | J28: =IFERROR(VLOOKUP($D28,매장경비정리!$C:$K,J$1,FALSE),0) -> 15900 | K28: =IFERROR(VLOOKUP($D28,매장경비정리!$C:$K,K$1,FALSE),0) -> 1 | L28: =SUM(F28,H28,J28) -> 144900 | M28: =L28/E28 -> 0.0026902767 | P28: =VLOOKUP($D28,'[1]25년 5월경비'!$D:$M,P$1,FALSE) -> 41503950 | Q28: =VLOOKUP($D28,'[1]25년 5월경비'!$D:$M,Q$1,FALSE) -> 85050 | R28: =VLOOKUP($D28,'[1]25년 5월경비'!$D:$M,R$1,FALSE) -> 22 | S28: =VLOOKUP($D28,'[1]25년 5월경비'!$D:$M,S$1,FALSE) -> 96500 | T28: =VLOOKUP($D28,'[1]25년 5월경비'!$D:$M,T$1,FALSE) -> 19 | U28: =VLOOKUP($D28,'[1]25년 5월경비'!$D:$M,U$1,FALSE) -> 0 | V28: =VLOOKUP($D28,'[1]25년 5월경비'!$D:$M,V$1,FALSE) -> 0 | W28: =VLOOKUP($D28,'[1]25년 5월경비'!$D:$M,W$1,FALSE) -> 181550 | X28: =W28/P28 -> 0.0043742824 | Z28: =E28-P28 -> 12356680 | AA28: =F28-Q28 -> 1950 | AB28: =G28-R28 -> 0 | AC28: =H28-S28 -> -54500 | AD28: =I28-T28 -> -8 | AE28: =J28-U28 -> 15900 | AF28: =K28-V28 -> 1 | AG28: =L28-W28 -> -36650
B29: 7 | C29: 45411 | D29: 롯데포항점 | E29: =VLOOKUP(D29,매출!C:J,8,0) -> 73635020 | F29: =IFERROR(VLOOKUP($D29,매장경비정리!$C:$K,F$1,FALSE),0) -> 0 | G29: =IFERROR(VLOOKUP($D29,매장경비정리!$C:$K,G$1,FALSE),0) -> 0 | H29: =IFERROR(VLOOKUP($D29,매장경비정리!$C:$K,H$1,FALSE),0) -> 0 | I29: =IFERROR(VLOOKUP($D29,매장경비정리!$C:$K,I$1,FALSE),0) -> 0 | J29: =IFERROR(VLOOKUP($D29,매장경비정리!$C:$K,J$1,FALSE),0) -> 0 | K29: =IFERROR(VLOOKUP($D29,매장경비정리!$C:$K,K$1,FALSE),0) -> 0 | L29: =SUM(F29,H29,J29) -> 0 | M29: =L29/E29 -> 0 | P29: =VLOOKUP($D29,'[1]25년 5월경비'!$D:$M,P$1,FALSE) -> 66528480 | Q29: =VLOOKUP($D29,'[1]25년 5월경비'!$D:$M,Q$1,FALSE) -> 0 | R29: =VLOOKUP($D29,'[1]25년 5월경비'!$D:$M,R$1,FALSE) -> 0 | S29: =VLOOKUP($D29,'[1]25년 5월경비'!$D:$M,S$1,FALSE) -> 0 | T29: =VLOOKUP($D29,'[1]25년 5월경비'!$D:$M,T$1,FALSE) -> 0 | U29: =VLOOKUP($D29,'[1]25년 5월경비'!$D:$M,U$1,FALSE) -> 0 | V29: =VLOOKUP($D29,'[1]25년 5월경비'!$D:$M,V$1,FALSE) -> 0 | W29: =VLOOKUP($D29,'[1]25년 5월경비'!$D:$M,W$1,FALSE) -> 0 | X29: =W29/P29 -> 0 | Z29: =E29-P29 -> 7106540 | AA29: =F29-Q29 -> 0 | AB29: =G29-R29 -> 0 | AC29: =H29-S29 -> 0 | AD29: =I29-T29 -> 0 | AE29: =J29-U29 -> 0 | AF29: =K29-V29 -> 0 | AG29: =L29-W29 -> 0
B30: 8 | C30: 45432 | D30: 롯데평촌점 | E30: =VLOOKUP(D30,매출!C:J,8,0) -> 83647550 | F30: =IFERROR(VLOOKUP($D30,매장경비정리!$C:$K,F$1,FALSE),0) -> 0 | G30: =IFERROR(VLOOKUP($D30,매장경비정리!$C:$K,G$1,FALSE),0) -> 0 | H30: =IFERROR(VLOOKUP($D30,매장경비정리!$C:$K,H$1,FALSE),0) -> 0 | I30: =IFERROR(VLOOKUP($D30,매장경비정리!$C:$K,I$1,FALSE),0) -> 0 | J30: =IFERROR(VLOOKUP($D30,매장경비정리!$C:$K,J$1,FALSE),0) -> 0 | K30: =IFERROR(VLOOKUP($D30,매장경비정리!$C:$K,K$1,FALSE),0) -> 0 | L30: =SUM(F30,H30,J30) -> 0 | M30: =L30/E30 -> 0 | P30: =VLOOKUP($D30,'[1]25년 5월경비'!$D:$M,P$1,FALSE) -> 62783580 | Q30: =VLOOKUP($D30,'[1]25년 5월경비'!$D:$M,Q$1,FALSE) -> 0 | R30: =VLOOKUP($D30,'[1]25년 5월경비'!$D:$M,R$1,FALSE) -> 0 | S30: =VLOOKUP($D30,'[1]25년 5월경비'!$D:$M,S$1,FALSE) -> 0 | T30: =VLOOKUP($D30,'[1]25년 5월경비'!$D:$M,T$1,FALSE) -> 0 | U30: =VLOOKUP($D30,'[1]25년 5월경비'!$D:$M,U$1,FALSE) -> 0 | V30: =VLOOKUP($D30,'[1]25년 5월경비'!$D:$M,V$1,FALSE) -> 0 | W30: =VLOOKUP($D30,'[1]25년 5월경비'!$D:$M,W$1,FALSE) -> 0 | X30: =W30/P30 -> 0 | Z30: =E30-P30 -> 20863970 | AA30: =F30-Q30 -> 0 | AB30: =G30-R30 -> 0 | AC30: =H30-S30 -> 0 | AD30: =I30-T30 -> 0 | AE30: =J30-U30 -> 0 | AF30: =K30-V30 -> 0 | AG30: =L30-W30 -> 0
B31: 9 | C31: 45404 | D31: 신세계대구점 | E31: =VLOOKUP(D31,매출!C:J,8,0) -> 128665630 | F31: =IFERROR(VLOOKUP($D31,매장경비정리!$C:$K,F$1,FALSE),0) -> 0 | G31: =IFERROR(VLOOKUP($D31,매장경비정리!$C:$K,G$1,FALSE),0) -> 0 | H31: =IFERROR(VLOOKUP($D31,매장경비정리!$C:$K,H$1,FALSE),0) -> 0 | I31: =IFERROR(VLOOKUP($D31,매장경비정리!$C:$K,I$1,FALSE),0) -> 0 | J31: =IFERROR(VLOOKUP($D31,매장경비정리!$C:$K,J$1,FALSE),0) -> 0 | K31: =IFERROR(VLOOKUP($D31,매장경비정리!$C:$K,K$1,FALSE),0) -> 0 | L31: =SUM(F31,H31,J31) -> 0 | M31: =L31/E31 -> 0 | P31: =VLOOKUP($D31,'[1]25년 5월경비'!$D:$M,P$1,FALSE) -> 104992240 | Q31: =VLOOKUP($D31,'[1]25년 5월경비'!$D:$M,Q$1,FALSE) -> 60500 | R31: =VLOOKUP($D31,'[1]25년 5월경비'!$D:$M,R$1,FALSE) -> 13 | S31: =VLOOKUP($D31,'[1]25년 5월경비'!$D:$M,S$1,FALSE) -> 66000 | T31: =VLOOKUP($D31,'[1]25년 5월경비'!$D:$M,T$1,FALSE) -> 15 | U31: =VLOOKUP($D31,'[1]25년 5월경비'!$D:$M,U$1,FALSE) -> 0 | V31: =VLOOKUP($D31,'[1]25년 5월경비'!$D:$M,V$1,FALSE) -> 0 | W31: =VLOOKUP($D31,'[1]25년 5월경비'!$D:$M,W$1,FALSE) -> 126500 | X31: =W31/P31 -> 0.0012048509 | Z31: =E31-P31 -> 23673390 | AA31: =F31-Q31 -> -60500 | AB31: =G31-R31 -> -13 | AC31: =H31-S31 -> -66000 | AD31: =I31-T31 -> -15 | AE31: =J31-U31 -> 0 | AF31: =K31-V31 -> 0 | AG31: =L31-W31 -> -126500
B32: 10 | C32: 45411 | D32: 현대천호점 | E32: =VLOOKUP(D32,매출!C:J,8,0) -> 100163700 | F32: =IFERROR(VLOOKUP($D32,매장경비정리!$C:$K,F$1,FALSE),0) -> 0 | G32: =IFERROR(VLOOKUP($D32,매장경비정리!$C:$K,G$1,FALSE),0) -> 0 | H32: =IFERROR(VLOOKUP($D32,매장경비정리!$C:$K,H$1,FALSE),0) -> 0 | I32: =IFERROR(VLOOKUP($D32,매장경비정리!$C:$K,I$1,FALSE),0) -> 0 | J32: =IFERROR(VLOOKUP($D32,매장경비정리!$C:$K,J$1,FALSE),0) -> 0 | K32: =IFERROR(VLOOKUP($D32,매장경비정리!$C:$K,K$1,FALSE),0) -> 0 | L32: =SUM(F32,H32,J32) -> 0 | M32: =L32/E32 -> 0 | P32: =VLOOKUP($D32,'[1]25년 5월경비'!$D:$M,P$1,FALSE) -> 80394050 | Q32: =VLOOKUP($D32,'[1]25년 5월경비'!$D:$M,Q$1,FALSE) -> 0 | R32: =VLOOKUP($D32,'[1]25년 5월경비'!$D:$M,R$1,FALSE) -> 0 | S32: =VLOOKUP($D32,'[1]25년 5월경비'!$D:$M,S$1,FALSE) -> 0 | T32: =VLOOKUP($D32,'[1]25년 5월경비'!$D:$M,T$1,FALSE) -> 0 | U32: =VLOOKUP($D32,'[1]25년 5월경비'!$D:$M,U$1,FALSE) -> 0 | V32: =VLOOKUP($D32,'[1]25년 5월경비'!$D:$M,V$1,FALSE) -> 0 | W32: =VLOOKUP($D32,'[1]25년 5월경비'!$D:$M,W$1,FALSE) -> 0 | X32: =W32/P32 -> 0 | Z32: =E32-P32 -> 19769650 | AA32: =F32-Q32 -> 0 | AB32: =G32-R32 -> 0 | AC32: =H32-S32 -> 0 | AD32: =I32-T32 -> 0 | AE32: =J32-U32 -> 0 | AF32: =K32-V32 -> 0 | AG32: =L32-W32 -> 0
B33: 11 | C33: 45425 | D33: 현대대구점 | E33: =VLOOKUP(D33,매출!C:J,8,0) -> 140435320 | F33: =IFERROR(VLOOKUP($D33,매장경비정리!$C:$K,F$1,FALSE),0) -> 0 | G33: =IFERROR(VLOOKUP($D33,매장경비정리!$C:$K,G$1,FALSE),0) -> 0 | H33: =IFERROR(VLOOKUP($D33,매장경비정리!$C:$K,H$1,FALSE),0) -> 0 | I33: =IFERROR(VLOOKUP($D33,매장경비정리!$C:$K,I$1,FALSE),0) -> 0 | J33: =IFERROR(VLOOKUP($D33,매장경비정리!$C:$K,J$1,FALSE),0) -> 0 | K33: =IFERROR(VLOOKUP($D33,매장경비정리!$C:$K,K$1,FALSE),0) -> 0 | L33: =SUM(F33,H33,J33) -> 0 | M33: =L33/E33 -> 0 | P33: =VLOOKUP($D33,'[1]25년 5월경비'!$D:$M,P$1,FALSE) -> 120767583 | Q33: =VLOOKUP($D33,'[1]25년 5월경비'!$D:$M,Q$1,FALSE) -> 0 | R33: =VLOOKUP($D33,'[1]25년 5월경비'!$D:$M,R$1,FALSE) -> 0 | S33: =VLOOKUP($D33,'[1]25년 5월경비'!$D:$M,S$1,FALSE) -> 0 | T33: =VLOOKUP($D33,'[1]25년 5월경비'!$D:$M,T$1,FALSE) -> 0 | U33: =VLOOKUP($D33,'[1]25년 5월경비'!$D:$M,U$1,FALSE) -> 0 | V33: =VLOOKUP($D33,'[1]25년 5월경비'!$D:$M,V$1,FALSE) -> 0 | W33: =VLOOKUP($D33,'[1]25년 5월경비'!$D:$M,W$1,FALSE) -> 0 | X33: =W33/P33 -> 0 | Z33: =E33-P33 -> 19667737 | AA33: =F33-Q33 -> 0 | AB33: =G33-R33 -> 0 | AC33: =H33-S33 -> 0 | AD33: =I33-T33 -> 0 | AE33: =J33-U33 -> 0 | AF33: =K33-V33 -> 0 | AG33: =L33-W33 -> 0
B34: 12 | C34: 45411 | D34: 현대판교점 | E34: =VLOOKUP(D34,매출!C:J,8,0) -> 115875950 | F34: =IFERROR(VLOOKUP($D34,매장경비정리!$C:$K,F$1,FALSE),0) -> 0 | G34: =IFERROR(VLOOKUP($D34,매장경비정리!$C:$K,G$1,FALSE),0) -> 0 | H34: =IFERROR(VLOOKUP($D34,매장경비정리!$C:$K,H$1,FALSE),0) -> 0 | I34: =IFERROR(VLOOKUP($D34,매장경비정리!$C:$K,I$1,FALSE),0) -> 0 | J34: =IFERROR(VLOOKUP($D34,매장경비정리!$C:$K,J$1,FALSE),0) -> 0 | K34: =IFERROR(VLOOKUP($D34,매장경비정리!$C:$K,K$1,FALSE),0) -> 0 | L34: =SUM(F34,H34,J34) -> 0 | M34: =L34/E34 -> 0 | P34: =VLOOKUP($D34,'[1]25년 5월경비'!$D:$M,P$1,FALSE) -> 91924790 | Q34: =VLOOKUP($D34,'[1]25년 5월경비'!$D:$M,Q$1,FALSE) -> 0 | R34: =VLOOKUP($D34,'[1]25년 5월경비'!$D:$M,R$1,FALSE) -> 0 | S34: =VLOOKUP($D34,'[1]25년 5월경비'!$D:$M,S$1,FALSE) -> 0 | T34: =VLOOKUP($D34,'[1]25년 5월경비'!$D:$M,T$1,FALSE) -> 0 | U34: =VLOOKUP($D34,'[1]25년 5월경비'!$D:$M,U$1,FALSE) -> 0 | V34: =VLOOKUP($D34,'[1]25년 5월경비'!$D:$M,V$1,FALSE) -> 0 | W34: =VLOOKUP($D34,'[1]25년 5월경비'!$D:$M,W$1,FALSE) -> 0 | X34: =W34/P34 -> 0 | Z34: =E34-P34 -> 23951160 | AA34: =F34-Q34 -> 0 | AB34: =G34-R34 -> 0 | AC34: =H34-S34 -> 0 | AD34: =I34-T34 -> 0 | AE34: =J34-U34 -> 0 | AF34: =K34-V34 -> 0 | AG34: =L34-W34 -> 0
B35: 13 | C35: 45425 | D35: 현대중동점 | E35: =VLOOKUP(D35,매출!C:J,8,0) -> 65219490 | F35: =IFERROR(VLOOKUP($D35,매장경비정리!$C:$K,F$1,FALSE),0) -> 247000 | G35: =IFERROR(VLOOKUP($D35,매장경비정리!$C:$K,G$1,FALSE),0) -> 58 | H35: =IFERROR(VLOOKUP($D35,매장경비정리!$C:$K,H$1,FALSE),0) -> 84500 | I35: =IFERROR(VLOOKUP($D35,매장경비정리!$C:$K,I$1,FALSE),0) -> 21 | J35: =IFERROR(VLOOKUP($D35,매장경비정리!$C:$K,J$1,FALSE),0) -> 0 | K35: =IFERROR(VLOOKUP($D35,매장경비정리!$C:$K,K$1,FALSE),0) -> 0 | L35: =SUM(F35,H35,J35) -> 331500 | M35: =L35/E35 -> 0.0050828364 | P35: =VLOOKUP($D35,'[1]25년 5월경비'!$D:$M,P$1,FALSE) -> 41384350 | Q35: =VLOOKUP($D35,'[1]25년 5월경비'!$D:$M,Q$1,FALSE) -> 183400 | R35: =VLOOKUP($D35,'[1]25년 5월경비'!$D:$M,R$1,FALSE) -> 39 | S35: =VLOOKUP($D35,'[1]25년 5월경비'!$D:$M,S$1,FALSE) -> 79000 | T35: =VLOOKUP($D35,'[1]25년 5월경비'!$D:$M,T$1,FALSE) -> 19 | U35: =VLOOKUP($D35,'[1]25년 5월경비'!$D:$M,U$1,FALSE) -> 6000 | V35: =VLOOKUP($D35,'[1]25년 5월경비'!$D:$M,V$1,FALSE) -> 1 | W35: =VLOOKUP($D35,'[1]25년 5월경비'!$D:$M,W$1,FALSE) -> 268400 | X35: =W35/P35 -> 0.0064855434 | Z35: =E35-P35 -> 23835140 | AA35: =F35-Q35 -> 63600 | AB35: =G35-R35 -> 19 | AC35: =H35-S35 -> 5500 | AD35: =I35-T35 -> 2 | AE35: =J35-U35 -> -6000 | AF35: =K35-V35 -> -1 | AG35: =L35-W35 -> 63100
B36: 14 | D36: 현대신촌점 | E36: =VLOOKUP(D36,매출!C:J,8,0) -> 57987500 | F36: =IFERROR(VLOOKUP($D36,매장경비정리!$C:$K,F$1,FALSE),0) -> 187000 | G36: =IFERROR(VLOOKUP($D36,매장경비정리!$C:$K,G$1,FALSE),0) -> 39 | H36: =IFERROR(VLOOKUP($D36,매장경비정리!$C:$K,H$1,FALSE),0) -> 140500 | I36: =IFERROR(VLOOKUP($D36,매장경비정리!$C:$K,I$1,FALSE),0) -> 34 | J36: =IFERROR(VLOOKUP($D36,매장경비정리!$C:$K,J$1,FALSE),0) -> 13000 | K36: =IFERROR(VLOOKUP($D36,매장경비정리!$C:$K,K$1,FALSE),0) -> 2 | L36: =SUM(F36,H36,J36) -> 340500 | M36: =L36/E36 -> 0.0058719552 | P36: =VLOOKUP($D36,'[1]25년 5월경비'!$D:$M,P$1,FALSE) -> 28330030 | Q36: =VLOOKUP($D36,'[1]25년 5월경비'!$D:$M,Q$1,FALSE) -> 54000 | R36: =VLOOKUP($D36,'[1]25년 5월경비'!$D:$M,R$1,FALSE) -> 13 | S36: =VLOOKUP($D36,'[1]25년 5월경비'!$D:$M,S$1,FALSE) -> 138800 | T36: =VLOOKUP($D36,'[1]25년 5월경비'!$D:$M,T$1,FALSE) -> 31 | U36: =VLOOKUP($D36,'[1]25년 5월경비'!$D:$M,U$1,FALSE) -> 22900 | V36: =VLOOKUP($D36,'[1]25년 5월경비'!$D:$M,V$1,FALSE) -> 2 | W36: =VLOOKUP($D36,'[1]25년 5월경비'!$D:$M,W$1,FALSE) -> 215700 | X36: =W36/P36 -> 0.0076138289 | Z36: =E36-P36 -> 29657470 | AA36: =F36-Q36 -> 133000 | AB36: =G36-R36 -> 26 | AC36: =H36-S36 -> 1700 | AD36: =I36-T36 -> 3 | AE36: =J36-U36 -> -9900 | AF36: =K36-V36 -> 0 | AG36: =L36-W36 -> 124800
B37: 15 | C37: 45338 | D37: 롯데아울렛동부산점 | E37: =VLOOKUP(D37,매출!C:J,8,0) -> 54807810 | F37: =IFERROR(VLOOKUP($D37,매장경비정리!$C:$K,F$1,FALSE),0) -> 472000 | G37: =IFERROR(VLOOKUP($D37,매장경비정리!$C:$K,G$1,FALSE),0) -> 91 | H37: =IFERROR(VLOOKUP($D37,매장경비정리!$C:$K,H$1,FALSE),0) -> 46000 | I37: =IFERROR(VLOOKUP($D37,매장경비정리!$C:$K,I$1,FALSE),0) -> 12 | J37: =IFERROR(VLOOKUP($D37,매장경비정리!$C:$K,J$1,FALSE),0) -> 24000 | K37: =IFERROR(VLOOKUP($D37,매장경비정리!$C:$K,K$1,FALSE),0) -> 1 | L37: =SUM(F37,H37,J37) -> 542000 | M37: =L37/E37 -> 0.0098891016 | P37: =VLOOKUP($D37,'[1]25년 5월경비'!$D:$M,P$1,FALSE) -> 47166320 | Q37: =VLOOKUP($D37,'[1]25년 5월경비'!$D:$M,Q$1,FALSE) -> 437000 | R37: =VLOOKUP($D37,'[1]25년 5월경비'!$D:$M,R$1,FALSE) -> 73 | S37: =VLOOKUP($D37,'[1]25년 5월경비'!$D:$M,S$1,FALSE) -> 95000 | T37: =VLOOKUP($D37,'[1]25년 5월경비'!$D:$M,T$1,FALSE) -> 23 | U37: =VLOOKUP($D37,'[1]25년 5월경비'!$D:$M,U$1,FALSE) -> 0 | V37: =VLOOKUP($D37,'[1]25년 5월경비'!$D:$M,V$1,FALSE) -> 0 | W37: =VLOOKUP($D37,'[1]25년 5월경비'!$D:$M,W$1,FALSE) -> 532000 | X37: =W37/P37 -> 0.011279235 | Z37: =E37-P37 -> 7641490 | AA37: =F37-Q37 -> 35000 | AB37: =G37-R37 -> 18 | AC37: =H37-S37 -> -49000 | AD37: =I37-T37 -> -11 | AE37: =J37-U37 -> 24000 | AF37: =K37-V37 -> 1 | AG37: =L37-W37 -> 10000
B38: 16 | C38: 45404 | D38: 롯데노원점 | E38: =VLOOKUP(D38,매출!C:J,8,0) -> 44564230 | F38: =IFERROR(VLOOKUP($D38,매장경비정리!$C:$K,F$1,FALSE),0) -> 0 | G38: =IFERROR(VLOOKUP($D38,매장경비정리!$C:$K,G$1,FALSE),0) -> 0 | H38: =IFERROR(VLOOKUP($D38,매장경비정리!$C:$K,H$1,FALSE),0) -> 0 | I38: =IFERROR(VLOOKUP($D38,매장경비정리!$C:$K,I$1,FALSE),0) -> 0 | J38: =IFERROR(VLOOKUP($D38,매장경비정리!$C:$K,J$1,FALSE),0) -> 0 | K38: =IFERROR(VLOOKUP($D38,매장경비정리!$C:$K,K$1,FALSE),0) -> 0 | L38: =SUM(F38,H38,J38) -> 0 | M38: =L38/E38 -> 0 | P38: =VLOOKUP($D38,'[1]25년 5월경비'!$D:$M,P$1,FALSE) -> 34423650 | Q38: =VLOOKUP($D38,'[1]25년 5월경비'!$D:$M,Q$1,FALSE) -> 0 | R38: =VLOOKUP($D38,'[1]25년 5월경비'!$D:$M,R$1,FALSE) -> 0 | S38: =VLOOKUP($D38,'[1]25년 5월경비'!$D:$M,S$1,FALSE) -> 0 | T38: =VLOOKUP($D38,'[1]25년 5월경비'!$D:$M,T$1,FALSE) -> 0 | U38: =VLOOKUP($D38,'[1]25년 5월경비'!$D:$M,U$1,FALSE) -> 0 | V38: =VLOOKUP($D38,'[1]25년 5월경비'!$D:$M,V$1,FALSE) -> 0 | W38: =VLOOKUP($D38,'[1]25년 5월경비'!$D:$M,W$1,FALSE) -> 0 | X38: =W38/P38 -> 0 | Z38: =E38-P38 -> 10140580 | AA38: =F38-Q38 -> 0 | AB38: =G38-R38 -> 0 | AC38: =H38-S38 -> 0 | AD38: =I38-T38 -> 0 | AE38: =J38-U38 -> 0 | AF38: =K38-V38 -> 0 | AG38: =L38-W38 -> 0
B39: 17 | C39: 45425 | D39: 신세계센텀점 | E39: =VLOOKUP(D39,매출!C:J,8,0) -> 131578880 | F39: =IFERROR(VLOOKUP($D39,매장경비정리!$C:$K,F$1,FALSE),0) -> 0 | G39: =IFERROR(VLOOKUP($D39,매장경비정리!$C:$K,G$1,FALSE),0) -> 0 | H39: =IFERROR(VLOOKUP($D39,매장경비정리!$C:$K,H$1,FALSE),0) -> 0 | I39: =IFERROR(VLOOKUP($D39,매장경비정리!$C:$K,I$1,FALSE),0) -> 0 | J39: =IFERROR(VLOOKUP($D39,매장경비정리!$C:$K,J$1,FALSE),0) -> 0 | K39: =IFERROR(VLOOKUP($D39,매장경비정리!$C:$K,K$1,FALSE),0) -> 0 | L39: =SUM(F39,H39,J39) -> 0 | M39: =L39/E39 -> 0 | P39: =VLOOKUP($D39,'[1]25년 5월경비'!$D:$M,P$1,FALSE) -> 134501410 | Q39: =VLOOKUP($D39,'[1]25년 5월경비'!$D:$M,Q$1,FALSE) -> 0 | R39: =VLOOKUP($D39,'[1]25년 5월경비'!$D:$M,R$1,FALSE) -> 0 | S39: =VLOOKUP($D39,'[1]25년 5월경비'!$D:$M,S$1,FALSE) -> 0 | T39: =VLOOKUP($D39,'[1]25년 5월경비'!$D:$M,T$1,FALSE) -> 0 | U39: =VLOOKUP($D39,'[1]25년 5월경비'!$D:$M,U$1,FALSE) -> 0 | V39: =VLOOKUP($D39,'[1]25년 5월경비'!$D:$M,V$1,FALSE) -> 0 | W39: =VLOOKUP($D39,'[1]25년 5월경비'!$D:$M,W$1,FALSE) -> 0 | X39: =W39/P39 -> 0 | Z39: =E39-P39 -> -2922530 | AA39: =F39-Q39 -> 0 | AB39: =G39-R39 -> 0 | AC39: =H39-S39 -> 0 | AD39: =I39-T39 -> 0 | AE39: =J39-U39 -> 0 | AF39: =K39-V39 -> 0 | AG39: =L39-W39 -> 0
B40: 18 | C40: 45432 | D40: 신세계강남점 | E40: =VLOOKUP(D40,매출!C:J,8,0) -> 109556570 | F40: =IFERROR(VLOOKUP($D40,매장경비정리!$C:$K,F$1,FALSE),0) -> 220600 | G40: =IFERROR(VLOOKUP($D40,매장경비정리!$C:$K,G$1,FALSE),0) -> 37 | H40: =IFERROR(VLOOKUP($D40,매장경비정리!$C:$K,H$1,FALSE),0) -> 77200 | I40: =IFERROR(VLOOKUP($D40,매장경비정리!$C:$K,I$1,FALSE),0) -> 18 | J40: =IFERROR(VLOOKUP($D40,매장경비정리!$C:$K,J$1,FALSE),0) -> 20000 | K40: =IFERROR(VLOOKUP($D40,매장경비정리!$C:$K,K$1,FALSE),0) -> 1 | L40: =SUM(F40,H40,J40) -> 317800 | M40: =L40/E40 -> 0.0029007845 | P40: =VLOOKUP($D40,'[1]25년 5월경비'!$D:$M,P$1,FALSE) -> 103625400 | Q40: =VLOOKUP($D40,'[1]25년 5월경비'!$D:$M,Q$1,FALSE) -> 85300 | R40: =VLOOKUP($D40,'[1]25년 5월경비'!$D:$M,R$1,FALSE) -> 12 | S40: =VLOOKUP($D40,'[1]25년 5월경비'!$D:$M,S$1,FALSE) -> 194500 | T40: =VLOOKUP($D40,'[1]25년 5월경비'!$D:$M,T$1,FALSE) -> 48 | U40: =VLOOKUP($D40,'[1]25년 5월경비'!$D:$M,U$1,FALSE) -> 10000 | V40: =VLOOKUP($D40,'[1]25년 5월경비'!$D:$M,V$1,FALSE) -> 1 | W40: =VLOOKUP($D40,'[1]25년 5월경비'!$D:$M,W$1,FALSE) -> 289800 | X40: =W40/P40 -> 0.0027966116 | Z40: =E40-P40 -> 5931170 | AA40: =F40-Q40 -> 135300 | AB40: =G40-R40 -> 25 | AC40: =H40-S40 -> -117300 | AD40: =I40-T40 -> -30 | AE40: =J40-U40 -> 10000 | AF40: =K40-V40 -> 0 | AG40: =L40-W40 -> 28000
B41: 19 | C41: 45411 | D41: 신세계의정부점 | E41: =VLOOKUP(D41,매출!C:J,8,0) -> 56748840 | F41: =IFERROR(VLOOKUP($D41,매장경비정리!$C:$K,F$1,FALSE),0) -> 211000 | G41: =IFERROR(VLOOKUP($D41,매장경비정리!$C:$K,G$1,FALSE),0) -> 48 | H41: =IFERROR(VLOOKUP($D41,매장경비정리!$C:$K,H$1,FALSE),0) -> 42000 | I41: =IFERROR(VLOOKUP($D41,매장경비정리!$C:$K,I$1,FALSE),0) -> 10 | J41: =IFERROR(VLOOKUP($D41,매장경비정리!$C:$K,J$1,FALSE),0) -> 19900 | K41: =IFERROR(VLOOKUP($D41,매장경비정리!$C:$K,K$1,FALSE),0) -> 2 | L41: =SUM(F41,H41,J41) -> 272900 | M41: =L41/E41 -> 0.0048089089 | P41: =VLOOKUP($D41,'[1]25년 5월경비'!$D:$M,P$1,FALSE) -> 47372530 | Q41: =VLOOKUP($D41,'[1]25년 5월경비'!$D:$M,Q$1,FALSE) -> 0 | R41: =VLOOKUP($D41,'[1]25년 5월경비'!$D:$M,R$1,FALSE) -> 0 | S41: =VLOOKUP($D41,'[1]25년 5월경비'!$D:$M,S$1,FALSE) -> 63500 | T41: =VLOOKUP($D41,'[1]25년 5월경비'!$D:$M,T$1,FALSE) -> 16 | U41: =VLOOKUP($D41,'[1]25년 5월경비'!$D:$M,U$1,FALSE) -> 29100 | V41: =VLOOKUP($D41,'[1]25년 5월경비'!$D:$M,V$1,FALSE) -> 2 | W41: =VLOOKUP($D41,'[1]25년 5월경비'!$D:$M,W$1,FALSE) -> 92600 | X41: =W41/P41 -> 0.0019547193 | Z41: =E41-P41 -> 9376310 | AA41: =F41-Q41 -> 211000 | AB41: =G41-R41 -> 48 | AC41: =H41-S41 -> -21500 | AD41: =I41-T41 -> -6 | AE41: =J41-U41 -> -9200 | AF41: =K41-V41 -> 0 | AG41: =L41-W41 -> 180300
