Workbook

Sheet 피벗값_구분
W1: ▼ SUMIFS 파라미터 (월초에 이곳만 수정)
B2: 전년동기대비 증감액 및 증감율 | S2: ★ Ver2: SUMIFS 자동화 - 표1에 데이터 추가 시 즉시 자동갱신 (피벗 불필요) | W2: 전년도 | X2: 2025
L3: 단위:천원 | W3: 당기년도 | X3: 2026
B4: =("("&$X$4&"~"&$X$5&"월)") -> (1~5월) | C4: 매출금액 | E4: 수금액(V+) | G4: 생산원가(V-) | I4: 총경비 | K4: 영업이익(V-) | M4: 전년대비증감액 | W4: 시작월 | X4: 1
B5: 구분 | C5: 2025 | D5: 2026 | E5: 2025 | F5: 2026 | G5: 2025 | H5: 2026 | I5: 2025 | J5: 2026 | K5: 2025 | L5: 2026 | M5: 전체 매출금액 | N5: 전체 수금액(V+) | O5: 전체 생산원가(V-) | P5: 전체 총경비 | Q5: 전체 영업이익(V-) | W5: 종료월 | X5: 5
B6: 동일 | C6: =SUMIFS(표1[매출금액],표1[구분],"동일",표1[년],$X$2,표1[월],">="&$X$4,표1[월],"<="&$X$5) -> 14422510974 | D6: =SUMIFS(표1[매출금액],표1[구분],"동일",표1[년],$X$3,표1[월],">="&$X$4,표1[월],"<="&$X$5) -> 15777050580 | E6: =SUMIFS(표1[수금액(V+)],표1[구분],"동일",표1[년],$X$2,표1[월],">="&$X$4,표1[월],"<="&$X$5) -> 9595031940 | F6: =SUMIFS(표1[수금액(V+)],표1[구분],"동일",표1[년],$X$3,표1[월],">="&$X$4,표1[월],"<="&$X$5) -> 10388921006 | G6: =SUMIFS(표1[생산원가(V-)],표1[구분],"동일",표1[년],$X$2,표1[월],">="&$X$4,표1[월],"<="&$X$5) -> 4474694123 | H6: =SUMIFS(표1[생산원가(V-)],표1[구분],"동일",표1[년],$X$3,표1[월],">="&$X$4,표1[월],"<="&$X$5) -> 4600259340 | I6: =SUMIFS(표1[총경비],표1[구분],"동일",표1[년],$X$2,표1[월],">="&$X$4,표1[월],"<="&$X$5) -> 2219504148 | J6: =SUMIFS(표1[총경비],표1[구분],"동일",표1[년],$X$3,표1[월],">="&$X$4,표1[월],"<="&$X$5) -> 2385842435 | K6: =SUMIFS(표1[영업이익(V-)],표1[구분],"동일",표1[년],$X$2,표1[월],">="&$X$4,표1[월],"<="&$X$5) -> 4248062190 | L6: =SUMIFS(표1[영업이익(V-)],표1[구분],"동일",표1[년],$X$3,표1[월],">="&$X$4,표1[월],"<="&$X$5) -> 4844214303 | M6: =D6-C6 -> 1354539606 | N6: =F6-E6 -> 793889066 | O6: =H6-G6 -> 125565217 | P6: =J6-I6 -> 166338287 | Q6: =L6-K6 -> 596152113
B7: 신규 | C7: 0 | D7: 0 | E7: 0 | F7: 0 | G7: 0 | H7: 0 | I7: 0 | J7: 0 | K7: 0 | L7: 0 | M7: =D7-C7 -> 0 | N7: =F7-E7 -> 0 | O7: =H7-G7 -> 0 | P7: =J7-I7 -> 0 | Q7: =L7-K7 -> 0
B8: 폐점 | C8: =SUMIFS(표1[매출금액],표1[구분],"폐점",표1[년],$X$2,표1[월],">="&$X$4,표1[월],"<="&$X$5) -> 417681420 | D8: =SUMIFS(표1[매출금액],표1[구분],"폐점",표1[년],$X$3,표1[월],">="&$X$4,표1[월],"<="&$X$5) -> 341598380 | E8: =SUMIFS(표1[수금액(V+)],표1[구분],"폐점",표1[년],$X$2,표1[월],">="&$X$4,표1[월],"<="&$X$5) -> 264322482 | F8: =SUMIFS(표1[수금액(V+)],표1[구분],"폐점",표1[년],$X$3,표1[월],">="&$X$4,표1[월],"<="&$X$5) -> 216949145 | G8: =SUMIFS(표1[생산원가(V-)],표1[구분],"폐점",표1[년],$X$2,표1[월],">="&$X$4,표1[월],"<="&$X$5) -> 130013101 | H8: =SUMIFS(표1[생산원가(V-)],표1[구분],"폐점",표1[년],$X$3,표1[월],">="&$X$4,표1[월],"<="&$X$5) -> 98933054 | I8: =SUMIFS(표1[총경비],표1[구분],"폐점",표1[년],$X$2,표1[월],">="&$X$4,표1[월],"<="&$X$5) -> 78643790 | J8: =SUMIFS(표1[총경비],표1[구분],"폐점",표1[년],$X$3,표1[월],">="&$X$4,표1[월],"<="&$X$5) -> 40754380 | K8: =SUMIFS(표1[영업이익(V-)],표1[구분],"폐점",표1[년],$X$2,표1[월],">="&$X$4,표1[월],"<="&$X$5) -> 110280065 | L8: =SUMIFS(표1[영업이익(V-)],표1[구분],"폐점",표1[년],$X$3,표1[월],">="&$X$4,표1[월],"<="&$X$5) -> 98293442 | M8: =D8-C8 -> -76083040 | N8: =F8-E8 -> -47373337 | O8: =H8-G8 -> -31080047 | P8: =J8-I8 -> -37889410 | Q8: =L8-K8 -> -11986623
B9: 행사 | C9: =SUMIFS(표1[매출금액],표1[구분],"행사",표1[년],$X$2,표1[월],">="&$X$4,표1[월],"<="&$X$5) -> 51781440 | D9: =SUMIFS(표1[매출금액],표1[구분],"행사",표1[년],$X$3,표1[월],">="&$X$4,표1[월],"<="&$X$5) -> 126402630 | E9: =SUMIFS(표1[수금액(V+)],표1[구분],"행사",표1[년],$X$2,표1[월],">="&$X$4,표1[월],"<="&$X$5) -> 39612855 | F9: =SUMIFS(표1[수금액(V+)],표1[구분],"행사",표1[년],$X$3,표1[월],">="&$X$4,표1[월],"<="&$X$5) -> 87509788 | G9: =SUMIFS(표1[생산원가(V-)],표1[구분],"행사",표1[년],$X$2,표1[월],">="&$X$4,표1[월],"<="&$X$5) -> 16155346 | H9: =SUMIFS(표1[생산원가(V-)],표1[구분],"행사",표1[년],$X$3,표1[월],">="&$X$4,표1[월],"<="&$X$5) -> 33716815 | I9: =SUMIFS(표1[총경비],표1[구분],"행사",표1[년],$X$2,표1[월],">="&$X$4,표1[월],"<="&$X$5) -> 7987030 | J9: =SUMIFS(표1[총경비],표1[구분],"행사",표1[년],$X$3,표1[월],">="&$X$4,표1[월],"<="&$X$5) -> 4640000 | K9: =SUMIFS(표1[영업이익(V-)],표1[구분],"행사",표1[년],$X$2,표1[월],">="&$X$4,표1[월],"<="&$X$5) -> 19856341 | L9: =SUMIFS(표1[영업이익(V-)],표1[구분],"행사",표1[년],$X$3,표1[월],">="&$X$4,표1[월],"<="&$X$5) -> 45837538 | M9: =D9-C9 -> 74621190 | N9: =F9-E9 -> 47896933 | O9: =H9-G9 -> 17561469 | P9: =J9-I9 -> -3347030 | Q9: =L9-K9 -> 25981197
B10: 총합계 | C10: =SUM(C6:C9) -> 14891973834 | D10: =SUM(D6:D9) -> 16245051590 | E10: =SUM(E6:E9) -> 9898967277 | F10: =SUM(F6:F9) -> 10693379939 | G10: =SUM(G6:G9) -> 4620862570 | H10: =SUM(H6:H9) -> 4732909209 | I10: =SUM(I6:I9) -> 2306134968 | J10: =SUM(J6:J9) -> 2431236815 | ... Q10: =SUM(Q6:Q9) -> 610146687
L12: 단위:천원
B13: =B4 -> (1~5월) | C13: 전기대비 매출 증가분의 당기 매출기여도
B14: 구분 | C14: 매출차이 | E14: 수금액(V+)차이 | G14: 생산원가(V-)차이 | I14: 총경비차이 | K14: 영업이익(V-)차이
B15: 동일 | C15: =M6 -> 1354539606 | D15: =C15/D$10 -> 0.083381675 | E15: =N6 -> 793889066 | F15: =E15/F$10 -> 0.074241173 | G15: =O6 -> 125565217 | H15: =G15/H$10 -> 0.02653024 | I15: =P6 -> 166338287 | J15: =I15/J$10 -> 0.068417147 | K15: =Q6 -> 596152113 | L15: =K15/L$10 -> 0.11950899
B16: 신규 | C16: =M7 -> 0 | D16: =C16/D$10 -> 0 | E16: =N7 -> 0 | F16: =E16/F$10 -> 0 | G16: =O7 -> 0 | H16: =G16/H$10 -> 0 | I16: =P7 -> 0 | J16: =I16/J$10 -> 0 | K16: =Q7 -> 0 | L16: =K16/L$10 -> 0
B17: 폐점 | C17: =M8 -> -76083040 | D17: =C17/D$10 -> -0.0046834594 | E17: =N8 -> -47373337 | F17: =E17/F$10 -> -0.0044301556 | G17: =O8 -> -31080047 | H17: =G17/H$10 -> -0.0065667955 | I17: =P8 -> -37889410 | J17: =I17/J$10 -> -0.015584418 | K17: =Q8 -> -11986623 | L17: =K17/L$10 -> -0.0024029257
B18: 행사 | C18: =M9 -> 74621190 | D18: =C18/D$10 -> 0.004593472 | E18: =N9 -> 47896933 | F18: =E18/F$10 -> 0.0044791201 | G18: =O9 -> 17561469 | H18: =G18/H$10 -> 0.003710502 | I18: =P9 -> -3347030 | J18: =I18/J$10 -> -0.0013766779 | K18: =Q9 -> 25981197 | L18: =K18/L$10 -> 0.0052083798
B19: 총합계 | C19: =SUM(C15:C18) -> 1353077756 | D19: =C19/D$10 -> 0.083291687 | E19: =SUM(E15:E18) -> 794412662 | F19: =E19/F$10 -> 0.074290137 | G19: =SUM(G15:G18) -> 112046639 | H19: =G19/H$10 -> 0.023673946 | I19: =SUM(I15:I18) -> 125101847 | J19: =I19/J$10 -> 0.051456052 | K19: =SUM(K15:K18) -> 610146687 | L19: =K19/L$10 -> 0.12231445

Sheet 피벗값_매장명(동일)
B2: 동일매장분석
T3: 단위: 천원 | V3: ★ 구분 시트에서 구분 변경 시 자동 반영
B4: =피벗값_구분!B4 -> (1~5월) | D4: 매출금액 | G4: 수금액(V+) | J4: 생산원가(V-) | M4: 총경비 | P4: 영업이익(V-)
B5: 동일 | C5: 매장명 | D5: 2025 | E5: 2026 | F5: 당기기준 신장률 | G5: 2025 | H5: 2026 | I5: 매출대비 수금율 | J5: 2025 | K5: 2026 | L5: 매출대비 원가배수 | M5: 2025 | N5: 2026 | O5: 매출대비 경비율 | P5: 2025 | Q5: 2026 | R5: 매출대비 이익률 | S5: 공헌 이익률 | T5: 증감액 | V5: 2025 영업이익 높은순 정렬
B6: =IFERROR(INDEX(구분!$B:$B,MATCH(1,구분!$E:$E,0)),"") -> 00101 | C6: =IFERROR(VLOOKUP(B6,구분!$B:$C,2,0),"") -> 롯데잠실점 | D6: =IFERROR(IF(B6="",0,SUMIFS(표1[매출금액],표1[매장코드],B6,표1[년],피벗값_구분!$X$2,표1[월],">="&피벗값_구분!$X$4,표1[월],"<="&피벗값_구분!$X$5)),0) -> 304063520 | E6: =IFERROR(IF(B6="",0,SUMIFS(표1[매출금액],표1[매장코드],B6,표1[년],피벗값_구분!$X$3,표1[월],">="&피벗값_구분!$X$4,표1[월],"<="&피벗값_구분!$X$5)),0) -> 369840250 | F6: =IFERROR(IF(B6="","",(E6-D6)/D6),"") -> 0.21632562 | G6: =IFERROR(IF(B6="",0,SUMIFS(표1[수금액(V+)],표1[매장코드],B6,표1[년],피벗값_구분!$X$2,표1[월],">="&피벗값_구분!$X$4,표1[월],"<="&피벗값_구분!$X$5)),0) -> 195026705 | H6: =IFERROR(IF(B6="",0,SUMIFS(표1[수금액(V+)],표1[매장코드],B6,표1[년],피벗값_구분!$X$3,표1[월],">="&피벗값_구분!$X$4,표1[월],"<="&피벗값_구분!$X$5)),0) -> 236914267 | I6: =IFERROR(IF(B6="","",H6/E6),"") -> 0.64058541 | J6: =IFERROR(IF(B6="",0,SUMIFS(표1[생산원가(V-)],표1[매장코드],B6,표1[년],피벗값_구분!$X$2,표1[월],">="&피벗값_구분!$X$4,표1[월],"<="&피벗값_구분!$X$5)),0) -> 88822778 | K6: =IFERROR(IF(B6="",0,SUMIFS(표1[생산원가(V-)],표1[매장코드],B6,표1[년],피벗값_구분!$X$3,표1[월],">="&피벗값_구분!$X$4,표1[월],"<="&피벗값_구분!$X$5)),0) -> 107012131 | L6: =IFERROR(IF(B6="","",E6/1.1/K6),"") -> 3.1418719 | M6: =IFERROR(IF(B6="",0,SUMIFS(표1[총경비],표1[매장코드],B6,표1[년],피벗값_구분!$X$2,표1[월],">="&피벗값_구분!$X$4,표1[월],"<="&피벗값_구분!$X$5)),0) -> 32165690 | N6: =IFERROR(IF(B6="",0,SUMIFS(표1[총경비],표1[매장코드],B6,표1[년],피벗값_구분!$X$3,표1[월],">="&피벗값_구분!$X$4,표1[월],"<="&피벗값_구분!$X$5)),0) -> 35215740 | O6: =IFERROR(IF(B6="","",N6/E6),"") -> 0.095218787 | P6: =IFERROR(IF(B6="",0,SUMIFS(표1[영업이익(V-)],표1[매장코드],B6,표1[년],피벗값_구분!$X$2,표1[월],">="&피벗값_구분!$X$4,표1[월],"<="&피벗값_구분!$X$5)),0) -> 88474227 | Q6: =IFERROR(IF(B6="",0,SUMIFS(표1[영업이익(V-)],표1[매장코드],B6,표1[년],피벗값_구분!$X$3,표1[월],">="&피벗값_구분!$X$4,표1[월],"<="&피벗값_구분!$X$5)),0) -> 108364475 | R6: =IFERROR(IF(B6="","",Q6/(E6/1.1)),"") -> 0.32230381 | S6: =Q6/$Q$70 -> 0.022369876 | T6: =IF(B6="","",Q6-P6) -> 19890248
B7: =IFERROR(INDEX(구분!$B:$B,MATCH(2,구분!$E:$E,0)),"") -> 00102 | C7: =IFERROR(VLOOKUP(B7,구분!$B:$C,2,0),"") -> 롯데관악점 | D7: =IFERROR(IF(B7="",0,SUMIFS(표1[매출금액],표1[매장코드],B7,표1[년],피벗값_구분!$X$2,표1[월],">="&피벗값_구분!$X$4,표1[월],"<="&피벗값_구분!$X$5)),0) -> 98863760 | E7: =IFERROR(IF(B7="",0,SUMIFS(표1[매출금액],표1[매장코드],B7,표1[년],피벗값_구분!$X$3,표1[월],">="&피벗값_구분!$X$4,표1[월],"<="&피벗값_구분!$X$5)),0) -> 99962340 | F7: =IFERROR(IF(B7="","",(E7-D7)/D7),"") -> 0.01111206 | G7: =IFERROR(IF(B7="",0,SUMIFS(표1[수금액(V+)],표1[매장코드],B7,표1[년],피벗값_구분!$X$2,표1[월],">="&피벗값_구분!$X$4,표1[월],"<="&피벗값_구분!$X$5)),0) -> 64332399 | H7: =IFERROR(IF(B7="",0,SUMIFS(표1[수금액(V+)],표1[매장코드],B7,표1[년],피벗값_구분!$X$3,표1[월],">="&피벗값_구분!$X$4,표1[월],"<="&피벗값_구분!$X$5)),0) -> 65028151 | I7: =IFERROR(IF(B7="","",H7/E7),"") -> 0.6505265 | J7: =IFERROR(IF(B7="",0,SUMIFS(표1[생산원가(V-)],표1[매장코드],B7,표1[년],피벗값_구분!$X$2,표1[월],">="&피벗값_구분!$X$4,표1[월],"<="&피벗값_구분!$X$5)),0) -> 31586409 | K7: =IFERROR(IF(B7="",0,SUMIFS(표1[생산원가(V-)],표1[매장코드],B7,표1[년],피벗값_구분!$X$3,표1[월],">="&피벗값_구분!$X$4,표1[월],"<="&피벗값_구분!$X$5)),0) -> 30402138 | L7: =IFERROR(IF(B7="","",E7/1.1/K7),"") -> 2.9890942 | M7: =IFERROR(IF(B7="",0,SUMIFS(표1[총경비],표1[매장코드],B7,표1[년],피벗값_구분!$X$2,표1[월],">="&피벗값_구분!$X$4,표1[월],"<="&피벗값_구분!$X$5)),0) -> 24760380 | N7: =IFERROR(IF(B7="",0,SUMIFS(표1[총경비],표1[매장코드],B7,표1[년],피벗값_구분!$X$3,표1[월],">="&피벗값_구분!$X$4,표1[월],"<="&피벗값_구분!$X$5)),0) -> 25129410 | O7: =IFERROR(IF(B7="","",N7/E7),"") -> 0.25138877 | P7: =IFERROR(IF(B7="",0,SUMIFS(표1[영업이익(V-)],표1[매장코드],B7,표1[년],피벗값_구분!$X$2,표1[월],">="&피벗값_구분!$X$4,표1[월],"<="&피벗값_구분!$X$5)),0) -> 26897590 | Q7: =IFERROR(IF(B7="",0,SUMIFS(표1[영업이익(V-)],표1[매장코드],B7,표1[년],피벗값_구분!$X$3,표1[월],">="&피벗값_구분!$X$4,표1[월],"<="&피벗값_구분!$X$5)),0) -> 28714363 | R7: =IFERROR(IF(B7="","",Q7/(E7/1.1)),"") -> 0.31597699 | S7: =Q7/$Q$70 -> 0.0059275584 | T7: =IF(B7="","",Q7-P7) -> 1816773
B8: =IFERROR(INDEX(구분!$B:$B,MATCH(3,구분!$E:$E,0)),"") -> 00106 | C8: =IFERROR(VLOOKUP(B8,구분!$B:$C,2,0),"") -> 롯데광주점 | D8: =IFERROR(IF(B8="",0,SUMIFS(표1[매출금액],표1[매장코드],B8,표1[년],피벗값_구분!$X$2,표1[월],">="&피벗값_구분!$X$4,표1[월],"<="&피벗값_구분!$X$5)),0) -> 260717950 | E8: =IFERROR(IF(B8="",0,SUMIFS(표1[매출금액],표1[매장코드],B8,표1[년],피벗값_구분!$X$3,표1[월],">="&피벗값_구분!$X$4,표1[월],"<="&피벗값_구분!$X$5)),0) -> 256148830 | F8: =IFERROR(IF(B8="","",(E8-D8)/D8),"") -> -0.017525145 | G8: =IFERROR(IF(B8="",0,SUMIFS(표1[수금액(V+)],표1[매장코드],B8,표1[년],피벗값_구분!$X$2,표1[월],">="&피벗값_구분!$X$4,표1[월],"<="&피벗값_구분!$X$5)),0) -> 167079816 | H8: =IFERROR(IF(B8="",0,SUMIFS(표1[수금액(V+)],표1[매장코드],B8,표1[년],피벗값_구분!$X$3,표1[월],">="&피벗값_구분!$X$4,표1[월],"<="&피벗값_구분!$X$5)),0) -> 163826099 | I8: =IFERROR(IF(B8="","",H8/E8),"") -> 0.63957387 | J8: =IFERROR(IF(B8="",0,SUMIFS(표1[생산원가(V-)],표1[매장코드],B8,표1[년],피벗값_구분!$X$2,표1[월],">="&피벗값_구분!$X$4,표1[월],"<="&피벗값_구분!$X$5)),0) -> 82989002 | K8: =IFERROR(IF(B8="",0,SUMIFS(표1[생산원가(V-)],표1[매장코드],B8,표1[년],피벗값_구분!$X$3,표1[월],">="&피벗값_구분!$X$4,표1[월],"<="&피벗값_구분!$X$5)),0) -> 77026418 | L8: =IFERROR(IF(B8="","",E8/1.1/K8),"") -> 3.023152 | M8: =IFERROR(IF(B8="",0,SUMIFS(표1[총경비],표1[매장코드],B8,표1[년],피벗값_구분!$X$2,표1[월],">="&피벗값_구분!$X$4,표1[월],"<="&피벗값_구분!$X$5)),0) -> 33584010 | N8: =IFERROR(IF(B8="",0,SUMIFS(표1[총경비],표1[매장코드],B8,표1[년],피벗값_구분!$X$3,표1[월],">="&피벗값_구분!$X$4,표1[월],"<="&피벗값_구분!$X$5)),0) -> 34545970 | O8: =IFERROR(IF(B8="","",N8/E8),"") -> 0.13486679 | P8: =IFERROR(IF(B8="",0,SUMIFS(표1[영업이익(V-)],표1[매장코드],B8,표1[년],피벗값_구분!$X$2,표1[월],">="&피벗값_구분!$X$4,표1[월],"<="&피벗값_구분!$X$5)),0) -> 68901739 | Q8: =IFERROR(IF(B8="",0,SUMIFS(표1[영업이익(V-)],표1[매장코드],B8,표1[년],피벗값_구분!$X$3,표1[월],">="&피벗값_구분!$X$4,표1[월],"<="&피벗값_구분!$X$5)),0) -> 71906400 | R8: =IFERROR(IF(B8="","",Q8/(E8/1.1)),"") -> 0.30879329 | S8: =Q8/$Q$70 -> 0.014843769 | T8: =IF(B8="","",Q8-P8) -> 3004661
B9: =IFERROR(INDEX(구분!$B:$B,MATCH(4,구분!$E:$E,0)),"") -> 00110 | C9: =IFERROR(VLOOKUP(B9,구분!$B:$C,2,0),"") -> 롯데강남점 | D9: =IFERROR(IF(B9="",0,SUMIFS(표1[매출금액],표1[매장코드],B9,표1[년],피벗값_구분!$X$2,표1[월],">="&피벗값_구분!$X$4,표1[월],"<="&피벗값_구분!$X$5)),0) -> 160310570 | E9: =IFERROR(IF(B9="",0,SUMIFS(표1[매출금액],표1[매장코드],B9,표1[년],피벗값_구분!$X$3,표1[월],">="&피벗값_구분!$X$4,표1[월],"<="&피벗값_구분!$X$5)),0) -> 166624390 | F9: =IFERROR(IF(B9="","",(E9-D9)/D9),"") -> 0.039384926 | G9: =IFERROR(IF(B9="",0,SUMIFS(표1[수금액(V+)],표1[매장코드],B9,표1[년],피벗값_구분!$X$2,표1[월],">="&피벗값_구분!$X$4,표1[월],"<="&피벗값_구분!$X$5)),0) -> 102582703 | H9: =IFERROR(IF(B9="",0,SUMIFS(표1[수금액(V+)],표1[매장코드],B9,표1[년],피벗값_구분!$X$3,표1[월],">="&피벗값_구분!$X$4,표1[월],"<="&피벗값_구분!$X$5)),0) -> 106778299 | I9: =IFERROR(IF(B9="","",H9/E9),"") -> 0.64083235 | J9: =IFERROR(IF(B9="",0,SUMIFS(표1[생산원가(V-)],표1[매장코드],B9,표1[년],피벗값_구분!$X$2,표1[월],">="&피벗값_구분!$X$4,표1[월],"<="&피벗값_구분!$X$5)),0) -> 48357983 | K9: =IFERROR(IF(B9="",0,SUMIFS(표1[생산원가(V-)],표1[매장코드],B9,표1[년],피벗값_구분!$X$3,표1[월],">="&피벗값_구분!$X$4,표1[월],"<="&피벗값_구분!$X$5)),0) -> 49190055 | L9: =IFERROR(IF(B9="","",E9/1.1/K9),"") -> 3.0794175 | M9: =IFERROR(IF(B9="",0,SUMIFS(표1[총경비],표1[매장코드],B9,표1[년],피벗값_구분!$X$2,표1[월],">="&피벗값_구분!$X$4,표1[월],"<="&피벗값_구분!$X$5)),0) -> 26271390 | N9: =IFERROR(IF(B9="",0,SUMIFS(표1[총경비],표1[매장코드],B9,표1[년],피벗값_구분!$X$3,표1[월],">="&피벗값_구분!$X$4,표1[월],"<="&피벗값_구분!$X$5)),0) -> 26831460 | O9: =IFERROR(IF(B9="","",N9/E9),"") -> 0.16102961 | P9: =IFERROR(IF(B9="",0,SUMIFS(표1[영업이익(V-)],표1[매장코드],B9,표1[년],피벗값_구분!$X$2,표1[월],">="&피벗값_구분!$X$4,표1[월],"<="&피벗값_구분!$X$5)),0) -> 44899019 | Q9: =IFERROR(IF(B9="",0,SUMIFS(표1[영업이익(V-)],표1[매장코드],B9,표1[년],피벗값_구분!$X$3,표1[월],">="&피벗값_구분!$X$4,표1[월],"<="&피벗값_구분!$X$5)),0) -> 47881126 | R9: =IFERROR(IF(B9="","",Q9/(E9/1.1)),"") -> 0.31609561 | S9: =Q9/$Q$70 -> 0.0098841882 | T9: =IF(B9="","",Q9-P9) -> 2982107
B10: =IFERROR(INDEX(구분!$B:$B,MATCH(5,구분!$E:$E,0)),"") -> 00111 | C10: =IFERROR(VLOOKUP(B10,구분!$B:$C,2,0),"") -> 롯데포항점 | D10: =IFERROR(IF(B10="",0,SUMIFS(표1[매출금액],표1[매장코드],B10,표1[년],피벗값_구분!$X$2,표1[월],">="&피벗값_구분!$X$4,표1[월],"<="&피벗값_구분!$X$5)),0) -> 282624550 | E10: =IFERROR(IF(B10="",0,SUMIFS(표1[매출금액],표1[매장코드],B10,표1[년],피벗값_구분!$X$3,표1[월],">="&피벗값_구분!$X$4,표1[월],"<="&피벗값_구분!$X$5)),0) -> 293790280 | F10: =IFERROR(IF(B10="","",(E10-D10)/D10),"") -> 0.03950729 | G10: =IFERROR(IF(B10="",0,SUMIFS(표1[수금액(V+)],표1[매장코드],B10,표1[년],피벗값_구분!$X$2,표1[월],">="&피벗값_구분!$X$4,표1[월],"<="&피벗값_구분!$X$5)),0) -> 181269907 | H10: =IFERROR(IF(B10="",0,SUMIFS(표1[수금액(V+)],표1[매장코드],B10,표1[년],피벗값_구분!$X$3,표1[월],">="&피벗값_구분!$X$4,표1[월],"<="&피벗값_구분!$X$5)),0) -> 188363309 | I10: =IFERROR(IF(B10="","",H10/E10),"") -> 0.64114888 | J10: =IFERROR(IF(B10="",0,SUMIFS(표1[생산원가(V-)],표1[매장코드],B10,표1[년],피벗값_구분!$X$2,표1[월],">="&피벗값_구분!$X$4,표1[월],"<="&피벗값_구분!$X$5)),0) -> 84181505 | K10: =IFERROR(IF(B10="",0,SUMIFS(표1[생산원가(V-)],표1[매장코드],B10,표1[년],피벗값_구분!$X$3,표1[월],">="&피벗값_구분!$X$4,표1[월],"<="&피벗값_구분!$X$5)),0) -> 83812337 | L10: =IFERROR(IF(B10="","",E10/1.1/K10),"") -> 3.1866678 | M10: =IFERROR(IF(B10="",0,SUMIFS(표1[총경비],표1[매장코드],B10,표1[년],피벗값_구분!$X$2,표1[월],">="&피벗값_구분!$X$4,표1[월],"<="&피벗값_구분!$X$5)),0) -> 41640450 | N10: =IFERROR(IF(B10="",0,SUMIFS(표1[총경비],표1[매장코드],B10,표1[년],피벗값_구분!$X$3,표1[월],">="&피벗값_구분!$X$4,표1[월],"<="&피벗값_구분!$X$5)),0) -> 43422940 | O10: =IFERROR(IF(B10="","",N10/E10),"") -> 0.14780251 | P10: =IFERROR(IF(B10="",0,SUMIFS(표1[영업이익(V-)],표1[매장코드],B10,표1[년],피벗값_구분!$X$2,표1[월],">="&피벗값_구분!$X$4,표1[월],"<="&피벗값_구분!$X$5)),0) -> 80609320 | Q10: =IFERROR(IF(B10="",0,SUMIFS(표1[영업이익(V-)],표1[매장코드],B10,표1[년],피벗값_구분!$X$3,표1[월],">="&피벗값_구분!$X$4,표1[월],"<="&피벗값_구분!$X$5)),0) -> 87427035 | R10: =IFERROR(IF(B10="","",Q10/(E10/1.1)),"") -> 0.32734146 | S10: =Q10/$Q$70 -> 0.018047722 | T10: =IF(B10="","",Q10-P10) -> 6817715
B11: =IFERROR(INDEX(구분!$B:$B,MATCH(6,구분!$E:$E,0)),"") -> 00112 | C11: =IFERROR(VLOOKUP(B11,구분!$B:$C,2,0),"") -> 롯데울산점 | D11: =IFERROR(IF(B11="",0,SUMIFS(표1[매출금액],표1[매장코드],B11,표1[년],피벗값_구분!$X$2,표1[월],">="&피벗값_구분!$X$4,표1[월],"<="&피벗값_구분!$X$5)),0) -> 103482570 | E11: =IFERROR(IF(B11="",0,SUMIFS(표1[매출금액],표1[매장코드],B11,표1[년],피벗값_구분!$X$3,표1[월],">="&피벗값_구분!$X$4,표1[월],"<="&피벗값_구분!$X$5)),0) -> 134001550 | F11: =IFERROR(IF(B11="","",(E11-D11)/D11),"") -> 0.29491904 | G11: =IFERROR(IF(B11="",0,SUMIFS(표1[수금액(V+)],표1[매장코드],B11,표1[년],피벗값_구분!$X$2,표1[월],">="&피벗값_구분!$X$4,표1[월],"<="&피벗값_구분!$X$5)),0) -> 66235283 | H11: =IFERROR(IF(B11="",0,SUMIFS(표1[수금액(V+)],표1[매장코드],B11,표1[년],피벗값_구분!$X$3,표1[월],">="&피벗값_구분!$X$4,표1[월],"<="&피벗값_구분!$X$5)),0) -> 85873002 | I11: =IFERROR(IF(B11="","",H11/E11),"") -> 0.64083589 | J11: =IFERROR(IF(B11="",0,SUMIFS(표1[생산원가(V-)],표1[매장코드],B11,표1[년],피벗값_구분!$X$2,표1[월],">="&피벗값_구분!$X$4,표1[월],"<="&피벗값_구분!$X$5)),0) -> 31079900 | K11: =IFERROR(IF(B11="",0,SUMIFS(표1[생산원가(V-)],표1[매장코드],B11,표1[년],피벗값_구분!$X$3,표1[월],">="&피벗값_구분!$X$4,표1[월],"<="&피벗값_구분!$X$5)),0) -> 39617508 | L11: =IFERROR(IF(B11="","",E11/1.1/K11),"") -> 3.0748928 | M11: =IFERROR(IF(B11="",0,SUMIFS(표1[총경비],표1[매장코드],B11,표1[년],피벗값_구분!$X$2,표1[월],">="&피벗값_구분!$X$4,표1[월],"<="&피벗값_구분!$X$5)),0) -> 25080060 | N11: =IFERROR(IF(B11="",0,SUMIFS(표1[총경비],표1[매장코드],B11,표1[년],피벗값_구분!$X$3,표1[월],">="&피벗값_구분!$X$4,표1[월],"<="&피벗값_구분!$X$5)),0) -> 23789890 | O11: =IFERROR(IF(B11="","",N11/E11),"") -> 0.17753444 | P11: =IFERROR(IF(B11="",0,SUMIFS(표1[영업이익(V-)],표1[매장코드],B11,표1[년],피벗값_구분!$X$2,표1[월],">="&피벗값_구분!$X$4,표1[월],"<="&피벗값_구분!$X$5)),0) -> 29133993 | Q11: =IFERROR(IF(B11="",0,SUMIFS(표1[영업이익(V-)],표1[매장코드],B11,표1[년],피벗값_구분!$X$3,표1[월],">="&피벗값_구분!$X$4,표1[월],"<="&피벗값_구분!$X$5)),0) -> 38448857 | R11: =IFERROR(IF(B11="","",Q11/(E11/1.1)),"") -> 0.31562129 | S11: =Q11/$Q$70 -> 0.0079370677 | T11: =IF(B11="","",Q11-P11) -> 9314864
B12: =IFERROR(INDEX(구분!$B:$B,MATCH(7,구분!$E:$E,0)),"") -> 00113 | C12: =IFERROR(VLOOKUP(B12,구분!$B:$C,2,0),"") -> 롯데동래점 | D12: =IFERROR(IF(B12="",0,SUMIFS(표1[매출금액],표1[매장코드],B12,표1[년],피벗값_구분!$X$2,표1[월],">="&피벗값_구분!$X$4,표1[월],"<="&피벗값_구분!$X$5)),0) -> 137501710 | E12: =IFERROR(IF(B12="",0,SUMIFS(표1[매출금액],표1[매장코드],B12,표1[년],피벗값_구분!$X$3,표1[월],">="&피벗값_구분!$X$4,표1[월],"<="&피벗값_구분!$X$5)),0) -> 138875100 | F12: =IFERROR(IF(B12="","",(E12-D12)/D12),"") -> 0.0099881667 | G12: =IFERROR(IF(B12="",0,SUMIFS(표1[수금액(V+)],표1[매장코드],B12,표1[년],피벗값_구분!$X$2,표1[월],">="&피벗값_구분!$X$4,표1[월],"<="&피벗값_구분!$X$5)),0) -> 88584162 | H12: =IFERROR(IF(B12="",0,SUMIFS(표1[수금액(V+)],표1[매장코드],B12,표1[년],피벗값_구분!$X$3,표1[월],">="&피벗값_구분!$X$4,표1[월],"<="&피벗값_구분!$X$5)),0) -> 89765125 | I12: =IFERROR(IF(B12="","",H12/E12),"") -> 0.64637307 | J12: =IFERROR(IF(B12="",0,SUMIFS(표1[생산원가(V-)],표1[매장코드],B12,표1[년],피벗값_구분!$X$2,표1[월],">="&피벗값_구분!$X$4,표1[월],"<="&피벗값_구분!$X$5)),0) -> 47370915 | K12: =IFERROR(IF(B12="",0,SUMIFS(표1[생산원가(V-)],표1[매장코드],B12,표1[년],피벗값_구분!$X$3,표1[월],">="&피벗값_구분!$X$4,표1[월],"<="&피벗값_구분!$X$5)),0) -> 44995233 | L12: =IFERROR(IF(B12="","",E12/1.1/K12),"") -> 2.8058548 | M12: =IFERROR(IF(B12="",0,SUMIFS(표1[총경비],표1[매장코드],B12,표1[년],피벗값_구분!$X$2,표1[월],">="&피벗값_구분!$X$4,표1[월],"<="&피벗값_구분!$X$5)),0) -> 31226320 | N12: =IFERROR(IF(B12="",0,SUMIFS(표1[총경비],표1[매장코드],B12,표1[년],피벗값_구분!$X$3,표1[월],">="&피벗값_구분!$X$4,표1[월],"<="&피벗값_구분!$X$5)),0) -> 26328970 | O12: =IFERROR(IF(B12="","",N12/E12),"") -> 0.18958741 | P12: =IFERROR(IF(B12="",0,SUMIFS(표1[영업이익(V-)],표1[매장코드],B12,표1[년],피벗값_구분!$X$2,표1[월],">="&피벗값_구분!$X$4,표1[월],"<="&피벗값_구분!$X$5)),0) -> 33160142 | Q12: =IFERROR(IF(B12="",0,SUMIFS(표1[영업이익(V-)],표1[매장코드],B12,표1[년],피벗값_구분!$X$3,표1[월],">="&피벗값_구분!$X$4,표1[월],"<="&피벗값_구분!$X$5)),0) -> 36609426 | R12: =IFERROR(IF(B12="","",Q12/(E12/1.1)),"") -> 0.28997544 | S12: =Q12/$Q$70 -> 0.0075573506 | T12: =IF(B12="","",Q12-P12) -> 3449284
B13: =IFERROR(INDEX(구분!$B:$B,MATCH(8,구분!$E:$E,0)),"") -> 00114 | C13: =IFERROR(VLOOKUP(B13,구분!$B:$C,2,0),"") -> 롯데창원점 | D13: =IFERROR(IF(B13="",0,SUMIFS(표1[매출금액],표1[매장코드],B13,표1[년],피벗값_구분!$X$2,표1[월],">="&피벗값_구분!$X$4,표1[월],"<="&피벗값_구분!$X$5)),0) -> 299016680 | E13: =IFERROR(IF(B13="",0,SUMIFS(표1[매출금액],표1[매장코드],B13,표1[년],피벗값_구분!$X$3,표1[월],">="&피벗값_구분!$X$4,표1[월],"<="&피벗값_구분!$X$5)),0) -> 276462270 | F13: =IFERROR(IF(B13="","",(E13-D13)/D13),"") -> -0.075428602 | G13: =IFERROR(IF(B13="",0,SUMIFS(표1[수금액(V+)],표1[매장코드],B13,표1[년],피벗값_구분!$X$2,표1[월],">="&피벗값_구분!$X$4,표1[월],"<="&피벗값_구분!$X$5)),0) -> 191524203 | H13: =IFERROR(IF(B13="",0,SUMIFS(표1[수금액(V+)],표1[매장코드],B13,표1[년],피벗값_구분!$X$3,표1[월],">="&피벗값_구분!$X$4,표1[월],"<="&피벗값_구분!$X$5)),0) -> 177069746 | I13: =IFERROR(IF(B13="","",H13/E13),"") -> 0.64048431 | J13: =IFERROR(IF(B13="",0,SUMIFS(표1[생산원가(V-)],표1[매장코드],B13,표1[년],피벗값_구분!$X$2,표1[월],">="&피벗값_구분!$X$4,표1[월],"<="&피벗값_구분!$X$5)),0) -> 92390173 | K13: =IFERROR(IF(B13="",0,SUMIFS(표1[생산원가(V-)],표1[매장코드],B13,표1[년],피벗값_구분!$X$3,표1[월],">="&피벗값_구분!$X$4,표1[월],"<="&피벗값_구분!$X$5)),0) -> 80314201 | L13: =IFERROR(IF(B13="","",E13/1.1/K13),"") -> 3.1293262 | M13: =IFERROR(IF(B13="",0,SUMIFS(표1[총경비],표1[매장코드],B13,표1[년],피벗값_구분!$X$2,표1[월],">="&피벗값_구분!$X$4,표1[월],"<="&피벗값_구분!$X$5)),0) -> 40081750 | N13: =IFERROR(IF(B13="",0,SUMIFS(표1[총경비],표1[매장코드],B13,표1[년],피벗값_구분!$X$3,표1[월],">="&피벗값_구분!$X$4,표1[월],"<="&피벗값_구분!$X$5)),0) -> 35734470 | O13: =IFERROR(IF(B13="","",N13/E13),"") -> 0.12925623 | P13: =IFERROR(IF(B13="",0,SUMIFS(표1[영업이익(V-)],표1[매장코드],B13,표1[년],피벗값_구분!$X$2,표1[월],">="&피벗값_구분!$X$4,표1[월],"<="&피벗값_구분!$X$5)),0) -> 81722739 | Q13: =IFERROR(IF(B13="",0,SUMIFS(표1[영업이익(V-)],표1[매장코드],B13,표1[년],피벗값_구분!$X$3,표1[월],">="&피벗값_구분!$X$4,표1[월],"<="&피벗값_구분!$X$5)),0) -> 80658295 | R13: =IFERROR(IF(B13="","",Q13/(E13/1.1)),"") -> 0.3209267 | S13: =Q13/$Q$70 -> 0.016650439 | T13: =IF(B13="","",Q13-P13) -> -1064444
B14: =IFERROR(INDEX(구분!$B:$B,MATCH(9,구분!$E:$E,0)),"") -> 00119 | C14: =IFERROR(VLOOKUP(B14,구분!$B:$C,2,0),"") -> 롯데상인점 | D14: =IFERROR(IF(B14="",0,SUMIFS(표1[매출금액],표1[매장코드],B14,표1[년],피벗값_구분!$X$2,표1[월],">="&피벗값_구분!$X$4,표1[월],"<="&피벗값_구분!$X$5)),0) -> 106443340 | E14: =IFERROR(IF(B14="",0,SUMIFS(표1[매출금액],표1[매장코드],B14,표1[년],피벗값_구분!$X$3,표1[월],">="&피벗값_구분!$X$4,표1[월],"<="&피벗값_구분!$X$5)),0) -> 155318390 | F14: =IFERROR(IF(B14="","",(E14-D14)/D14),"") -> 0.45916494 | G14: =IFERROR(IF(B14="",0,SUMIFS(표1[수금액(V+)],표1[매장코드],B14,표1[년],피벗값_구분!$X$2,표1[월],">="&피벗값_구분!$X$4,표1[월],"<="&피벗값_구분!$X$5)),0) -> 68322156 | H14: =IFERROR(IF(B14="",0,SUMIFS(표1[수금액(V+)],표1[매장코드],B14,표1[년],피벗값_구분!$X$3,표1[월],">="&피벗값_구분!$X$4,표1[월],"<="&피벗값_구분!$X$5)),0) -> 100225186 | I14: =IFERROR(IF(B14="","",H14/E14),"") -> 0.6452886 | J14: =IFERROR(IF(B14="",0,SUMIFS(표1[생산원가(V-)],표1[매장코드],B14,표1[년],피벗값_구분!$X$2,표1[월],">="&피벗값_구분!$X$4,표1[월],"<="&피벗값_구분!$X$5)),0) -> 30905544 | K14: =IFERROR(IF(B14="",0,SUMIFS(표1[생산원가(V-)],표1[매장코드],B14,표1[년],피벗값_구분!$X$3,표1[월],">="&피벗값_구분!$X$4,표1[월],"<="&피벗값_구분!$X$5)),0) -> 47335940 | L14: =IFERROR(IF(B14="","",E14/1.1/K14),"") -> 2.9829034 | M14: =IFERROR(IF(B14="",0,SUMIFS(표1[총경비],표1[매장코드],B14,표1[년],피벗값_구분!$X$2,표1[월],">="&피벗값_구분!$X$4,표1[월],"<="&피벗값_구분!$X$5)),0) -> 26070060 | N14: =IFERROR(IF(B14="",0,SUMIFS(표1[총경비],표1[매장코드],B14,표1[년],피벗값_구분!$X$3,표1[월],">="&피벗값_구분!$X$4,표1[월],"<="&피벗값_구분!$X$5)),0) -> 28845460 | O14: =IFERROR(IF(B14="","",N14/E14),"") -> 0.18571825 | P14: =IFERROR(IF(B14="",0,SUMIFS(표1[영업이익(V-)],표1[매장코드],B14,표1[년],피벗값_구분!$X$2,표1[월],">="&피벗값_구분!$X$4,표1[월],"<="&피벗값_구분!$X$5)),0) -> 31205507 | Q14: =IFERROR(IF(B14="",0,SUMIFS(표1[영업이익(V-)],표1[매장코드],B14,표1[년],피벗값_구분!$X$3,표1[월],">="&피벗값_구분!$X$4,표1[월],"<="&피벗값_구분!$X$5)),0) -> 43777865 | R14: =IFERROR(IF(B14="","",Q14/(E14/1.1)),"") -> 0.31004475 | S14: =Q14/$Q$70 -> 0.0090371446 | T14: =IF(B14="","",Q14-P14) -> 12572358
B15: =IFERROR(INDEX(구분!$B:$B,MATCH(10,구분!$E:$E,0)),"") -> 00120 | C15: =IFERROR(VLOOKUP(B15,구분!$B:$C,2,0),"") -> 롯데미아점 | D15: =IFERROR(IF(B15="",0,SUMIFS(표1[매출금액],표1[매장코드],B15,표1[년],피벗값_구분!$X$2,표1[월],">="&피벗값_구분!$X$4,표1[월],"<="&피벗값_구분!$X$5)),0) -> 98651320 | E15: =IFERROR(IF(B15="",0,SUMIFS(표1[매출금액],표1[매장코드],B15,표1[년],피벗값_구분!$X$3,표1[월],">="&피벗값_구분!$X$4,표1[월],"<="&피벗값_구분!$X$5)),0) -> 77884180 | F15: =IFERROR(IF(B15="","",(E15-D15)/D15),"") -> -0.21051051 | G15: =IFERROR(IF(B15="",0,SUMIFS(표1[수금액(V+)],표1[매장코드],B15,표1[년],피벗값_구분!$X$2,표1[월],">="&피벗값_구분!$X$4,표1[월],"<="&피벗값_구분!$X$5)),0) -> 64881409 | H15: =IFERROR(IF(B15="",0,SUMIFS(표1[수금액(V+)],표1[매장코드],B15,표1[년],피벗값_구분!$X$3,표1[월],">="&피벗값_구분!$X$4,표1[월],"<="&피벗값_구분!$X$5)),0) -> 50674357 | I15: =IFERROR(IF(B15="","",H15/E15),"") -> 0.65063736 | J15: =IFERROR(IF(B15="",0,SUMIFS(표1[생산원가(V-)],표1[매장코드],B15,표1[년],피벗값_구분!$X$2,표1[월],">="&피벗값_구분!$X$4,표1[월],"<="&피벗값_구분!$X$5)),0) -> 34622269 | K15: =IFERROR(IF(B15="",0,SUMIFS(표1[생산원가(V-)],표1[매장코드],B15,표1[년],피벗값_구분!$X$3,표1[월],">="&피벗값_구분!$X$4,표1[월],"<="&피벗값_구분!$X$5)),0) -> 24510267 | L15: =IFERROR(IF(B15="","",E15/1.1/K15),"") -> 2.8887405 | M15: =IFERROR(IF(B15="",0,SUMIFS(표1[총경비],표1[매장코드],B15,표1[년],피벗값_구분!$X$2,표1[월],">="&피벗값_구분!$X$4,표1[월],"<="&피벗값_구분!$X$5)),0) -> 23699270 | N15: =IFERROR(IF(B15="",0,SUMIFS(표1[총경비],표1[매장코드],B15,표1[년],피벗값_구분!$X$3,표1[월],">="&피벗값_구분!$X$4,표1[월],"<="&피벗값_구분!$X$5)),0) -> 19769880 | O15: =IFERROR(IF(B15="","",N15/E15),"") -> 0.25383692 | P15: =IFERROR(IF(B15="",0,SUMIFS(표1[영업이익(V-)],표1[매장코드],B15,표1[년],피벗값_구분!$X$2,표1[월],">="&피벗값_구분!$X$4,표1[월],"<="&피벗값_구분!$X$5)),0) -> 24360830 | Q15: =IFERROR(IF(B15="",0,SUMIFS(표1[영업이익(V-)],표1[매장코드],B15,표1[년],피벗값_구분!$X$3,표1[월],">="&피벗값_구분!$X$4,표1[월],"<="&피벗값_구분!$X$5)),0) -> 21557331 | R15: =IFERROR(IF(B15="","",Q15/(E15/1.1)),"") -> 0.30446573 | S15: =Q15/$Q$70 -> 0.0044501192 | T15: =IF(B15="","",Q15-P15) -> -2803499
B16: =IFERROR(INDEX(구분!$B:$B,MATCH(11,구분!$E:$E,0)),"") -> 00125 | C16: =IFERROR(VLOOKUP(B16,구분!$B:$C,2,0),"") -> 롯데구리점 | D16: =IFERROR(IF(B16="",0,SUMIFS(표1[매출금액],표1[매장코드],B16,표1[년],피벗값_구분!$X$2,표1[월],">="&피벗값_구분!$X$4,표1[월],"<="&피벗값_구분!$X$5)),0) -> 143276750 | E16: =IFERROR(IF(B16="",0,SUMIFS(표1[매출금액],표1[매장코드],B16,표1[년],피벗값_구분!$X$3,표1[월],">="&피벗값_구분!$X$4,표1[월],"<="&피벗값_구분!$X$5)),0) -> 181778830 | F16: =IFERROR(IF(B16="","",(E16-D16)/D16),"") -> 0.26872525 | G16: =IFERROR(IF(B16="",0,SUMIFS(표1[수금액(V+)],표1[매장코드],B16,표1[년],피벗값_구분!$X$2,표1[월],">="&피벗값_구분!$X$4,표1[월],"<="&피벗값_구분!$X$5)),0) -> 91821991 | H16: =IFERROR(IF(B16="",0,SUMIFS(표1[수금액(V+)],표1[매장코드],B16,표1[년],피벗값_구분!$X$3,표1[월],">="&피벗값_구분!$X$4,표1[월],"<="&피벗값_구분!$X$5)),0) -> 116523928 | I16: =IFERROR(IF(B16="","",H16/E16),"") -> 0.64102034 | J16: =IFERROR(IF(B16="",0,SUMIFS(표1[생산원가(V-)],표1[매장코드],B16,표1[년],피벗값_구분!$X$2,표1[월],">="&피벗값_구분!$X$4,표1[월],"<="&피벗값_구분!$X$5)),0) -> 44530712 | K16: =IFERROR(IF(B16="",0,SUMIFS(표1[생산원가(V-)],표1[매장코드],B16,표1[년],피벗값_구분!$X$3,표1[월],">="&피벗값_구분!$X$4,표1[월],"<="&피벗값_구분!$X$5)),0) -> 52199820 | L16: =IFERROR(IF(B16="","",E16/1.1/K16),"") -> 3.1657864 | M16: =IFERROR(IF(B16="",0,SUMIFS(표1[총경비],표1[매장코드],B16,표1[년],피벗값_구분!$X$2,표1[월],">="&피벗값_구분!$X$4,표1[월],"<="&피벗값_구분!$X$5)),0) -> 29016700 | N16: =IFERROR(IF(B16="",0,SUMIFS(표1[총경비],표1[매장코드],B16,표1[년],피벗값_구분!$X$3,표1[월],">="&피벗값_구분!$X$4,표1[월],"<="&피벗값_구분!$X$5)),0) -> 29188010 | O16: =IFERROR(IF(B16="","",N16/E16),"") -> 0.16056881 | P16: =IFERROR(IF(B16="",0,SUMIFS(표1[영업이익(V-)],표1[매장코드],B16,표1[년],피벗값_구분!$X$2,표1[월],">="&피벗값_구분!$X$4,표1[월],"<="&피벗값_구분!$X$5)),0) -> 38943825 | Q16: =IFERROR(IF(B16="",0,SUMIFS(표1[영업이익(V-)],표1[매장코드],B16,표1[년],피벗값_구분!$X$3,표1[월],">="&피벗값_구분!$X$4,표1[월],"<="&피벗값_구분!$X$5)),0) -> 53731024 | R16: =IFERROR(IF(B16="","",Q16/(E16/1.1)),"") -> 0.32514307 | S16: =Q16/$Q$70 -> 0.011091793 | T16: =IF(B16="","",Q16-P16) -> 14787199
B17: =IFERROR(INDEX(구분!$B:$B,MATCH(12,구분!$E:$E,0)),"") -> 00126 | C17: =IFERROR(VLOOKUP(B17,구분!$B:$C,2,0),"") -> 롯데영등포점 | D17: =IFERROR(IF(B17="",0,SUMIFS(표1[매출금액],표1[매장코드],B17,표1[년],피벗값_구분!$X$2,표1[월],">="&피벗값_구분!$X$4,표1[월],"<="&피벗값_구분!$X$5)),0) -> 177711470 | E17: =IFERROR(IF(B17="",0,SUMIFS(표1[매출금액],표1[매장코드],B17,표1[년],피벗값_구분!$X$3,표1[월],">="&피벗값_구분!$X$4,표1[월],"<="&피벗값_구분!$X$5)),0) -> 189650540 | F17: =IFERROR(IF(B17="","",(E17-D17)/D17),"") -> 0.067182326 | G17: =IFERROR(IF(B17="",0,SUMIFS(표1[수금액(V+)],표1[매장코드],B17,표1[년],피벗값_구분!$X$2,표1[월],">="&피벗값_구분!$X$4,표1[월],"<="&피벗값_구분!$X$5)),0) -> 113866604 | H17: =IFERROR(IF(B17="",0,SUMIFS(표1[수금액(V+)],표1[매장코드],B17,표1[년],피벗값_구분!$X$3,표1[월],">="&피벗값_구분!$X$4,표1[월],"<="&피벗값_구분!$X$5)),0) -> 121334561 | I17: =IFERROR(IF(B17="","",H17/E17),"") -> 0.63977968 | J17: =IFERROR(IF(B17="",0,SUMIFS(표1[생산원가(V-)],표1[매장코드],B17,표1[년],피벗값_구분!$X$2,표1[월],">="&피벗값_구분!$X$4,표1[월],"<="&피벗값_구분!$X$5)),0) -> 56681074 | K17: =IFERROR(IF(B17="",0,SUMIFS(표1[생산원가(V-)],표1[매장코드],B17,표1[년],피벗값_구분!$X$3,표1[월],">="&피벗값_구분!$X$4,표1[월],"<="&피벗값_구분!$X$5)),0) -> 56747511 | L17: =IFERROR(IF(B17="","",E17/1.1/K17),"") -> 3.0381876 | M17: =IFERROR(IF(B17="",0,SUMIFS(표1[총경비],표1[매장코드],B17,표1[년],피벗값_구분!$X$2,표1[월],">="&피벗값_구분!$X$4,표1[월],"<="&피벗값_구분!$X$5)),0) -> 25461490 | N17: =IFERROR(IF(B17="",0,SUMIFS(표1[총경비],표1[매장코드],B17,표1[년],피벗값_구분!$X$3,표1[월],">="&피벗값_구분!$X$4,표1[월],"<="&피벗값_구분!$X$5)),0) -> 27190460 | O17: =IFERROR(IF(B17="","",N17/E17),"") -> 0.14337138 | P17: =IFERROR(IF(B17="",0,SUMIFS(표1[영업이익(V-)],표1[매장코드],B17,표1[년],피벗값_구분!$X$2,표1[월],">="&피벗값_구분!$X$4,표1[월],"<="&피벗값_구분!$X$5)),0) -> 46834021 | Q17: =IFERROR(IF(B17="",0,SUMIFS(표1[영업이익(V-)],표1[매장코드],B17,표1[년],피벗값_구분!$X$3,표1[월],">="&피벗값_구분!$X$4,표1[월],"<="&피벗값_구분!$X$5)),0) -> 53556635 | R17: =IFERROR(IF(B17="","",Q17/(E17/1.1)),"") -> 0.31063607 | S17: =Q17/$Q$70 -> 0.011055794 | T17: =IF(B17="","",Q17-P17) -> 6722614
B18: =IFERROR(INDEX(구분!$B:$B,MATCH(13,구분!$E:$E,0)),"") -> 00128 | C18: =IFERROR(VLOOKUP(B18,구분!$B:$C,2,0),"") -> 롯데부산본점 | D18: =IFERROR(IF(B18="",0,SUMIFS(표1[매출금액],표1[매장코드],B18,표1[년],피벗값_구분!$X$2,표1[월],">="&피벗값_구분!$X$4,표1[월],"<="&피벗값_구분!$X$5)),0) -> 318432220 | E18: =IFERROR(IF(B18="",0,SUMIFS(표1[매출금액],표1[매장코드],B18,표1[년],피벗값_구분!$X$3,표1[월],">="&피벗값_구분!$X$4,표1[월],"<="&피벗값_구분!$X$5)),0) -> 341686200 | F18: =IFERROR(IF(B18="","",(E18-D18)/D18),"") -> 0.073026467 | G18: =IFERROR(IF(B18="",0,SUMIFS(표1[수금액(V+)],표1[매장코드],B18,표1[년],피벗값_구분!$X$2,표1[월],">="&피벗값_구분!$X$4,표1[월],"<="&피벗값_구분!$X$5)),0) -> 203796169 | H18: =IFERROR(IF(B18="",0,SUMIFS(표1[수금액(V+)],표1[매장코드],B18,표1[년],피벗값_구분!$X$3,표1[월],">="&피벗값_구분!$X$4,표1[월],"<="&피벗값_구분!$X$5)),0) -> 218843755 | I18: =IFERROR(IF(B18="","",H18/E18),"") -> 0.64048169 | J18: =IFERROR(IF(B18="",0,SUMIFS(표1[생산원가(V-)],표1[매장코드],B18,표1[년],피벗값_구분!$X$2,표1[월],">="&피벗값_구분!$X$4,표1[월],"<="&피벗값_구분!$X$5)),0) -> 93232490 | K18: =IFERROR(IF(B18="",0,SUMIFS(표1[생산원가(V-)],표1[매장코드],B18,표1[년],피벗값_구분!$X$3,표1[월],">="&피벗값_구분!$X$4,표1[월],"<="&피벗값_구분!$X$5)),0) -> 97968242 | L18: =IFERROR(IF(B18="","",E18/1.1/K18),"") -> 3.1706583 | M18: =IFERROR(IF(B18="",0,SUMIFS(표1[총경비],표1[매장코드],B18,표1[년],피벗값_구분!$X$2,표1[월],">="&피벗값_구분!$X$4,표1[월],"<="&피벗값_구분!$X$5)),0) -> 36971910 | N18: =IFERROR(IF(B18="",0,SUMIFS(표1[총경비],표1[매장코드],B18,표1[년],피벗값_구분!$X$3,표1[월],">="&피벗값_구분!$X$4,표1[월],"<="&피벗값_구분!$X$5)),0) -> 36020670 | O18: =IFERROR(IF(B18="","",N18/E18),"") -> 0.10542032 | P18: =IFERROR(IF(B18="",0,SUMIFS(표1[영업이익(V-)],표1[매장코드],B18,표1[년],피벗값_구분!$X$2,표1[월],">="&피벗값_구분!$X$4,표1[월],"<="&피벗값_구분!$X$5)),0) -> 92036754 | Q18: =IFERROR(IF(B18="",0,SUMIFS(표1[영업이익(V-)],표1[매장코드],B18,표1[년],피벗값_구분!$X$3,표1[월],">="&피벗값_구분!$X$4,표1[월],"<="&피벗값_구분!$X$5)),0) -> 100980625 | R18: =IFERROR(IF(B18="","",Q18/(E18/1.1)),"") -> 0.32508977 | S18: =Q18/$Q$70 -> 0.020845615 | T18: =IF(B18="","",Q18-P18) -> 8943871
B19: =IFERROR(INDEX(구분!$B:$B,MATCH(14,구분!$E:$E,0)),"") -> 00129 | C19: =IFERROR(VLOOKUP(B19,구분!$B:$C,2,0),"") -> 롯데평촌점 | D19: =IFERROR(IF(B19="",0,SUMIFS(표1[매출금액],표1[매장코드],B19,표1[년],피벗값_구분!$X$2,표1[월],">="&피벗값_구분!$X$4,표1[월],"<="&피벗값_구분!$X$5)),0) -> 295984510 | E19: =IFERROR(IF(B19="",0,SUMIFS(표1[매출금액],표1[매장코드],B19,표1[년],피벗값_구분!$X$3,표1[월],">="&피벗값_구분!$X$4,표1[월],"<="&피벗값_구분!$X$5)),0) -> 355223110 | F19: =IFERROR(IF(B19="","",(E19-D19)/D19),"") -> 0.20014088 | G19: =IFERROR(IF(B19="",0,SUMIFS(표1[수금액(V+)],표1[매장코드],B19,표1[년],피벗값_구분!$X$2,표1[월],">="&피벗값_구분!$X$4,표1[월],"<="&피벗값_구분!$X$5)),0) -> 189974329 | H19: =IFERROR(IF(B19="",0,SUMIFS(표1[수금액(V+)],표1[매장코드],B19,표1[년],피벗값_구분!$X$3,표1[월],">="&피벗값_구분!$X$4,표1[월],"<="&피벗값_구분!$X$5)),0) -> 227708060 | I19: =IFERROR(IF(B19="","",H19/E19),"") -> 0.64102828 | J19: =IFERROR(IF(B19="",0,SUMIFS(표1[생산원가(V-)],표1[매장코드],B19,표1[년],피벗값_구분!$X$2,표1[월],">="&피벗값_구분!$X$4,표1[월],"<="&피벗값_구분!$X$5)),0) -> 92654598 | K19: =IFERROR(IF(B19="",0,SUMIFS(표1[생산원가(V-)],표1[매장코드],B19,표1[년],피벗값_구분!$X$3,표1[월],">="&피벗값_구분!$X$4,표1[월],"<="&피벗값_구분!$X$5)),0) -> 102007171 | L19: =IFERROR(IF(B19="","",E19/1.1/K19),"") -> 3.1657588 | M19: =IFERROR(IF(B19="",0,SUMIFS(표1[총경비],표1[매장코드],B19,표1[년],피벗값_구분!$X$2,표1[월],">="&피벗값_구분!$X$4,표1[월],"<="&피벗값_구분!$X$5)),0) -> 38190450 | N19: =IFERROR(IF(B19="",0,SUMIFS(표1[총경비],표1[매장코드],B19,표1[년],피벗값_구분!$X$3,표1[월],">="&피벗값_구분!$X$4,표1[월],"<="&피벗값_구분!$X$5)),0) -> 49458840 | O19: =IFERROR(IF(B19="","",N19/E19),"") -> 0.13923317 | P19: =IFERROR(IF(B19="",0,SUMIFS(표1[영업이익(V-)],표1[매장코드],B19,표1[년],피벗값_구분!$X$2,표1[월],">="&피벗값_구분!$X$4,표1[월],"<="&피벗값_구분!$X$5)),0) -> 80049337 | Q19: =IFERROR(IF(B19="",0,SUMIFS(표1[영업이익(V-)],표1[매장코드],B19,표1[년],피벗값_구분!$X$3,표1[월],">="&피벗값_구분!$X$4,표1[월],"<="&피벗값_구분!$X$5)),0) -> 105000157 | R19: =IFERROR(IF(B19="","",Q19/(E19/1.1)),"") -> 0.32514825 | S19: =Q19/$Q$70 -> 0.021675374 | T19: =IF(B19="","",Q19-P19) -> 24950820
B20: =IFERROR(INDEX(구분!$B:$B,MATCH(15,구분!$E:$E,0)),"") -> 00130 | C20: =IFERROR(VLOOKUP(B20,구분!$B:$C,2,0),"") -> 롯데안산점 | D20: =IFERROR(IF(B20="",0,SUMIFS(표1[매출금액],표1[매장코드],B20,표1[년],피벗값_구분!$X$2,표1[월],">="&피벗값_구분!$X$4,표1[월],"<="&피벗값_구분!$X$5)),0) -> 159382210 | E20: =IFERROR(IF(B20="",0,SUMIFS(표1[매출금액],표1[매장코드],B20,표1[년],피벗값_구분!$X$3,표1[월],">="&피벗값_구분!$X$4,표1[월],"<="&피벗값_구분!$X$5)),0) -> 157492840 | F20: =IFERROR(IF(B20="","",(E20-D20)/D20),"") -> -0.011854334 | G20: =IFERROR(IF(B20="",0,SUMIFS(표1[수금액(V+)],표1[매장코드],B20,표1[년],피벗값_구분!$X$2,표1[월],">="&피벗값_구분!$X$4,표1[월],"<="&피벗값_구분!$X$5)),0) -> 104289246 | H20: =IFERROR(IF(B20="",0,SUMIFS(표1[수금액(V+)],표1[매장코드],B20,표1[년],피벗값_구분!$X$3,표1[월],">="&피벗값_구분!$X$4,표1[월],"<="&피벗값_구분!$X$5)),0) -> 103944753 | I20: =IFERROR(IF(B20="","",H20/E20),"") -> 0.65999669 | J20: =IFERROR(IF(B20="",0,SUMIFS(표1[생산원가(V-)],표1[매장코드],B20,표1[년],피벗값_구분!$X$2,표1[월],">="&피벗값_구분!$X$4,표1[월],"<="&피벗값_구분!$X$5)),0) -> 48184072 | K20: =IFERROR(IF(B20="",0,SUMIFS(표1[생산원가(V-)],표1[매장코드],B20,표1[년],피벗값_구분!$X$3,표1[월],">="&피벗값_구분!$X$4,표1[월],"<="&피벗값_구분!$X$5)),0) -> 49094753 | L20: =IFERROR(IF(B20="","",E20/1.1/K20),"") -> 2.9163057 | M20: =IFERROR(IF(B20="",0,SUMIFS(표1[총경비],표1[매장코드],B20,표1[년],피벗값_구분!$X$2,표1[월],">="&피벗값_구분!$X$4,표1[월],"<="&피벗값_구분!$X$5)),0) -> 28404420 | N20: =IFERROR(IF(B20="",0,SUMIFS(표1[총경비],표1[매장코드],B20,표1[년],피벗값_구분!$X$3,표1[월],">="&피벗값_구분!$X$4,표1[월],"<="&피벗값_구분!$X$5)),0) -> 30288810 | O20: =IFERROR(IF(B20="","",N20/E20),"") -> 0.19231865 | P20: =IFERROR(IF(B20="",0,SUMIFS(표1[영업이익(V-)],표1[매장코드],B20,표1[년],피벗값_구분!$X$2,표1[월],">="&피벗값_구분!$X$4,표1[월],"<="&피벗값_구분!$X$5)),0) -> 46624334 | Q20: =IFERROR(IF(B20="",0,SUMIFS(표1[영업이익(V-)],표1[매장코드],B20,표1[년],피벗값_구분!$X$3,표1[월],">="&피벗값_구분!$X$4,표1[월],"<="&피벗값_구분!$X$5)),0) -> 45400476 | R20: =IFERROR(IF(B20="","",Q20/(E20/1.1)),"") -> 0.3170971 | S20: =Q20/$Q$70 -> 0.0093721031 | T20: =IF(B20="","",Q20-P20) -> -1223858
B21: =IFERROR(INDEX(구분!$B:$B,MATCH(16,구분!$E:$E,0)),"") -> 00131 | C21: =IFERROR(VLOOKUP(B21,구분!$B:$C,2,0),"") -> 롯데노원점 | D21: =IFERROR(IF(B21="",0,SUMIFS(표1[매출금액],표1[매장코드],B21,표1[년],피벗값_구분!$X$2,표1[월],">="&피벗값_구분!$X$4,표1[월],"<="&피벗값_구분!$X$5)),0) -> 197303730 | E21: =IFERROR(IF(B21="",0,SUMIFS(표1[매출금액],표1[매장코드],B21,표1[년],피벗값_구분!$X$3,표1[월],">="&피벗값_구분!$X$4,표1[월],"<="&피벗값_구분!$X$5)),0) -> 191897800 | F21: =IFERROR(IF(B21="","",(E21-D21)/D21),"") -> -0.027399026 | G21: =IFERROR(IF(B21="",0,SUMIFS(표1[수금액(V+)],표1[매장코드],B21,표1[년],피벗값_구분!$X$2,표1[월],">="&피벗값_구분!$X$4,표1[월],"<="&피벗값_구분!$X$5)),0) -> 126353289 | H21: =IFERROR(IF(B21="",0,SUMIFS(표1[수금액(V+)],표1[매장코드],B21,표1[년],피벗값_구분!$X$3,표1[월],">="&피벗값_구분!$X$4,표1[월],"<="&피벗값_구분!$X$5)),0) -> 122853458 | I21: =IFERROR(IF(B21="","",H21/E21),"") -> 0.64020253 | J21: =IFERROR(IF(B21="",0,SUMIFS(표1[생산원가(V-)],표1[매장코드],B21,표1[년],피벗값_구분!$X$2,표1[월],">="&피벗값_구분!$X$4,표1[월],"<="&피벗값_구분!$X$5)),0) -> 60864187 | K21: =IFERROR(IF(B21="",0,SUMIFS(표1[생산원가(V-)],표1[매장코드],B21,표1[년],피벗값_구분!$X$3,표1[월],">="&피벗값_구분!$X$4,표1[월],"<="&피벗값_구분!$X$5)),0) -> 54260858 | L21: =IFERROR(IF(B21="","",E21/1.1/K21),"") -> 3.2150716 | M21: =IFERROR(IF(B21="",0,SUMIFS(표1[총경비],표1[매장코드],B21,표1[년],피벗값_구분!$X$2,표1[월],">="&피벗값_구분!$X$4,표1[월],"<="&피벗값_구분!$X$5)),0) -> 28694950 | N21: =IFERROR(IF(B21="",0,SUMIFS(표1[총경비],표1[매장코드],B21,표1[년],피벗값_구분!$X$3,표1[월],">="&피벗값_구분!$X$4,표1[월],"<="&피벗값_구분!$X$5)),0) -> 28157190 | O21: =IFERROR(IF(B21="","",N21/E21),"") -> 0.14673013 | P21: =IFERROR(IF(B21="",0,SUMIFS(표1[영업이익(V-)],표1[매장코드],B21,표1[년],피벗값_구분!$X$2,표1[월],">="&피벗값_구분!$X$4,표1[월],"<="&피벗값_구분!$X$5)),0) -> 54002440 | Q21: =IFERROR(IF(B21="",0,SUMIFS(표1[영업이익(V-)],표1[매장코드],B21,표1[년],피벗값_구분!$X$3,표1[월],">="&피벗값_구분!$X$4,표1[월],"<="&피벗값_구분!$X$5)),0) -> 57424103 | R21: =IFERROR(IF(B21="","",Q21/(E21/1.1)),"") -> 0.32916747 | S21: =Q21/$Q$70 -> 0.011854162 | T21: =IF(B21="","",Q21-P21) -> 3421663
B22: =IFERROR(INDEX(구분!$B:$B,MATCH(17,구분!$E:$E,0)),"") -> 00132 | C22: =IFERROR(VLOOKUP(B22,구분!$B:$C,2,0),"") -> 롯데광복점 | D22: =IFERROR(IF(B22="",0,SUMIFS(표1[매출금액],표1[매장코드],B22,표1[년],피벗값_구분!$X$2,표1[월],">="&피벗값_구분!$X$4,표1[월],"<="&피벗값_구분!$X$5)),0) -> 148429910 | E22: =IFERROR(IF(B22="",0,SUMIFS(표1[매출금액],표1[매장코드],B22,표1[년],피벗값_구분!$X$3,표1[월],">="&피벗값_구분!$X$4,표1[월],"<="&피벗값_구분!$X$5)),0) -> 169389600 | F22: =IFERROR(IF(B22="","",(E22-D22)/D22),"") -> 0.14120934 | G22: =IFERROR(IF(B22="",0,SUMIFS(표1[수금액(V+)],표1[매장코드],B22,표1[년],피벗값_구분!$X$2,표1[월],">="&피벗값_구분!$X$4,표1[월],"<="&피벗값_구분!$X$5)),0) -> 95098681 | H22: =IFERROR(IF(B22="",0,SUMIFS(표1[수금액(V+)],표1[매장코드],B22,표1[년],피벗값_구분!$X$3,표1[월],">="&피벗값_구분!$X$4,표1[월],"<="&피벗값_구분!$X$5)),0) -> 108599095 | I22: =IFERROR(IF(B22="","",H22/E22),"") -> 0.6411202 | J22: =IFERROR(IF(B22="",0,SUMIFS(표1[생산원가(V-)],표1[매장코드],B22,표1[년],피벗값_구분!$X$2,표1[월],">="&피벗값_구분!$X$4,표1[월],"<="&피벗값_구분!$X$5)),0) -> 44909984 | K22: =IFERROR(IF(B22="",0,SUMIFS(표1[생산원가(V-)],표1[매장코드],B22,표1[년],피벗값_구분!$X$3,표1[월],">="&피벗값_구분!$X$4,표1[월],"<="&피벗값_구분!$X$5)),0) -> 47622024 | L22: =IFERROR(IF(B22="","",E22/1.1/K22),"") -> 3.2335993 | M22: =IFERROR(IF(B22="",0,SUMIFS(표1[총경비],표1[매장코드],B22,표1[년],피벗값_구분!$X$2,표1[월],">="&피벗값_구분!$X$4,표1[월],"<="&피벗값_구분!$X$5)),0) -> 28879830 | N22: =IFERROR(IF(B22="",0,SUMIFS(표1[총경비],표1[매장코드],B22,표1[년],피벗값_구분!$X$3,표1[월],">="&피벗값_구분!$X$4,표1[월],"<="&피벗값_구분!$X$5)),0) -> 29722360 | O22: =IFERROR(IF(B22="","",N22/E22),"") -> 0.17546744 | P22: =IFERROR(IF(B22="",0,SUMIFS(표1[영업이익(V-)],표1[매장코드],B22,표1[년],피벗값_구분!$X$2,표1[월],">="&피벗값_구분!$X$4,표1[월],"<="&피벗값_구분!$X$5)),0) -> 41543363 | Q22: =IFERROR(IF(B22="",0,SUMIFS(표1[영업이익(V-)],표1[매장코드],B22,표1[년],피벗값_구분!$X$3,표1[월],">="&피벗값_구분!$X$4,표1[월],"<="&피벗값_구분!$X$5)),0) -> 51104427 | R22: =IFERROR(IF(B22="","",Q22/(E22/1.1)),"") -> 0.3318673 | S22: =Q22/$Q$70 -> 0.01054958 | T22: =IF(B22="","",Q22-P22) -> 9561064
B23: =IFERROR(INDEX(구분!$B:$B,MATCH(18,구분!$E:$E,0)),"") -> 00135 | C23: =IFERROR(VLOOKUP(B23,구분!$B:$C,2,0),"") -> 롯데수원점 | D23: =IFERROR(IF(B23="",0,SUMIFS(표1[매출금액],표1[매장코드],B23,표1[년],피벗값_구분!$X$2,표1[월],">="&피벗값_구분!$X$4,표1[월],"<="&피벗값_구분!$X$5)),0) -> 148514440 | E23: =IFERROR(IF(B23="",0,SUMIFS(표1[매출금액],표1[매장코드],B23,표1[년],피벗값_구분!$X$3,표1[월],">="&피벗값_구분!$X$4,표1[월],"<="&피벗값_구분!$X$5)),0) -> 126271840 | F23: =IFERROR(IF(B23="","",(E23-D23)/D23),"") -> -0.14976725 | G23: =IFERROR(IF(B23="",0,SUMIFS(표1[수금액(V+)],표1[매장코드],B23,표1[년],피벗값_구분!$X$2,표1[월],">="&피벗값_구분!$X$4,표1[월],"<="&피벗값_구분!$X$5)),0) -> 95193670 | H23: =IFERROR(IF(B23="",0,SUMIFS(표1[수금액(V+)],표1[매장코드],B23,표1[년],피벗값_구분!$X$3,표1[월],">="&피벗값_구분!$X$4,표1[월],"<="&피벗값_구분!$X$5)),0) -> 80956443 | I23: =IFERROR(IF(B23="","",H23/E23),"") -> 0.64112824 | J23: =IFERROR(IF(B23="",0,SUMIFS(표1[생산원가(V-)],표1[매장코드],B23,표1[년],피벗값_구분!$X$2,표1[월],">="&피벗값_구분!$X$4,표1[월],"<="&피벗값_구분!$X$5)),0) -> 46119521 | K23: =IFERROR(IF(B23="",0,SUMIFS(표1[생산원가(V-)],표1[매장코드],B23,표1[년],피벗값_구분!$X$3,표1[월],">="&피벗값_구분!$X$4,표1[월],"<="&피벗값_구분!$X$5)),0) -> 37486707 | L23: =IFERROR(IF(B23="","",E23/1.1/K23),"") -> 3.062221 | M23: =IFERROR(IF(B23="",0,SUMIFS(표1[총경비],표1[매장코드],B23,표1[년],피벗값_구분!$X$2,표1[월],">="&피벗값_구분!$X$4,표1[월],"<="&피벗값_구분!$X$5)),0) -> 28682330 | N23: =IFERROR(IF(B23="",0,SUMIFS(표1[총경비],표1[매장코드],B23,표1[년],피벗값_구분!$X$3,표1[월],">="&피벗값_구분!$X$4,표1[월],"<="&피벗값_구분!$X$5)),0) -> 27873090 | O23: =IFERROR(IF(B23="","",N23/E23),"") -> 0.22073876 | P23: =IFERROR(IF(B23="",0,SUMIFS(표1[영업이익(V-)],표1[매장코드],B23,표1[년],피벗값_구분!$X$2,표1[월],">="&피벗값_구분!$X$4,표1[월],"<="&피벗값_구분!$X$5)),0) -> 40420179 | Q23: =IFERROR(IF(B23="",0,SUMIFS(표1[영업이익(V-)],표1[매장코드],B23,표1[년],피벗값_구분!$X$3,표1[월],">="&피벗값_구분!$X$4,표1[월],"<="&피벗값_구분!$X$5)),0) -> 36110059 | R23: =IFERROR(IF(B23="","",Q23/(E23/1.1)),"") -> 0.31456788 | S23: =Q23/$Q$70 -> 0.0074542654 | T23: =IF(B23="","",Q23-P23) -> -4310120
B24: =IFERROR(INDEX(구분!$B:$B,MATCH(19,구분!$E:$E,0)),"") -> 00137 | C24: =IFERROR(VLOOKUP(B24,구분!$B:$C,2,0),"") -> 롯데대구점 | D24: =IFERROR(IF(B24="",0,SUMIFS(표1[매출금액],표1[매장코드],B24,표1[년],피벗값_구분!$X$2,표1[월],">="&피벗값_구분!$X$4,표1[월],"<="&피벗값_구분!$X$5)),0) -> 128179450 | E24: =IFERROR(IF(B24="",0,SUMIFS(표1[매출금액],표1[매장코드],B24,표1[년],피벗값_구분!$X$3,표1[월],">="&피벗값_구분!$X$4,표1[월],"<="&피벗값_구분!$X$5)),0) -> 157533820 | F24: =IFERROR(IF(B24="","",(E24-D24)/D24),"") -> 0.22900995 | G24: =IFERROR(IF(B24="",0,SUMIFS(표1[수금액(V+)],표1[매장코드],B24,표1[년],피벗값_구분!$X$2,표1[월],">="&피벗값_구분!$X$4,표1[월],"<="&피벗값_구분!$X$5)),0) -> 83001721 | H24: =IFERROR(IF(B24="",0,SUMIFS(표1[수금액(V+)],표1[매장코드],B24,표1[년],피벗값_구분!$X$3,표1[월],">="&피벗값_구분!$X$4,표1[월],"<="&피벗값_구분!$X$5)),0) -> 100874574 | I24: =IFERROR(IF(B24="","",H24/E24),"") -> 0.64033599 | J24: =IFERROR(IF(B24="",0,SUMIFS(표1[생산원가(V-)],표1[매장코드],B24,표1[년],피벗값_구분!$X$2,표1[월],">="&피벗값_구분!$X$4,표1[월],"<="&피벗값_구분!$X$5)),0) -> 44147376 | K24: =IFERROR(IF(B24="",0,SUMIFS(표1[생산원가(V-)],표1[매장코드],B24,표1[년],피벗값_구분!$X$3,표1[월],">="&피벗값_구분!$X$4,표1[월],"<="&피벗값_구분!$X$5)),0) -> 49922324 | L24: =IFERROR(IF(B24="","",E24/1.1/K24),"") -> 2.8687079 | M24: =IFERROR(IF(B24="",0,SUMIFS(표1[총경비],표1[매장코드],B24,표1[년],피벗값_구분!$X$2,표1[월],">="&피벗값_구분!$X$4,표1[월],"<="&피벗값_구분!$X$5)),0) -> 29167200 | N24: =IFERROR(IF(B24="",0,SUMIFS(표1[총경비],표1[매장코드],B24,표1[년],피벗값_구분!$X$3,표1[월],">="&피벗값_구분!$X$4,표1[월],"<="&피벗값_구분!$X$5)),0) -> 33749970 | O24: =IFERROR(IF(B24="","",N24/E24),"") -> 0.21423952 | P24: =IFERROR(IF(B24="",0,SUMIFS(표1[영업이익(V-)],표1[매장코드],B24,표1[년],피벗값_구분!$X$2,표1[월],">="&피벗값_구분!$X$4,표1[월],"<="&피벗값_구분!$X$5)),0) -> 31308733 | Q24: =IFERROR(IF(B24="",0,SUMIFS(표1[영업이익(V-)],표1[매장코드],B24,표1[년],피벗값_구분!$X$3,표1[월],">="&피벗값_구분!$X$4,표1[월],"<="&피벗값_구분!$X$5)),0) -> 41781835 | R24: =IFERROR(IF(B24="","",Q24/(E24/1.1)),"") -> 0.29174699 | S24: =Q24/$Q$70 -> 0.0086251005 | T24: =IF(B24="","",Q24-P24) -> 10473102
B25: =IFERROR(INDEX(구분!$B:$B,MATCH(20,구분!$E:$E,0)),"") -> 00139 | C25: =IFERROR(VLOOKUP(B25,구분!$B:$C,2,0),"") -> 롯데전주점 | D25: =IFERROR(IF(B25="",0,SUMIFS(표1[매출금액],표1[매장코드],B25,표1[년],피벗값_구분!$X$2,표1[월],">="&피벗값_구분!$X$4,표1[월],"<="&피벗값_구분!$X$5)),0) -> 149635130 | E25: =IFERROR(IF(B25="",0,SUMIFS(표1[매출금액],표1[매장코드],B25,표1[년],피벗값_구분!$X$3,표1[월],">="&피벗값_구분!$X$4,표1[월],"<="&피벗값_구분!$X$5)),0) -> 156029110 | F25: =IFERROR(IF(B25="","",(E25-D25)/D25),"") -> 0.042730474 | G25: =IFERROR(IF(B25="",0,SUMIFS(표1[수금액(V+)],표1[매장코드],B25,표1[년],피벗값_구분!$X$2,표1[월],">="&피벗값_구분!$X$4,표1[월],"<="&피벗값_구분!$X$5)),0) -> 95900097 | H25: =IFERROR(IF(B25="",0,SUMIFS(표1[수금액(V+)],표1[매장코드],B25,표1[년],피벗값_구분!$X$3,표1[월],">="&피벗값_구분!$X$4,표1[월],"<="&피벗값_구분!$X$5)),0) -> 99906597 | I25: =IFERROR(IF(B25="","",H25/E25),"") -> 0.64030742 | J25: =IFERROR(IF(B25="",0,SUMIFS(표1[생산원가(V-)],표1[매장코드],B25,표1[년],피벗값_구분!$X$2,표1[월],">="&피벗값_구분!$X$4,표1[월],"<="&피벗값_구분!$X$5)),0) -> 42637380 | K25: =IFERROR(IF(B25="",0,SUMIFS(표1[생산원가(V-)],표1[매장코드],B25,표1[년],피벗값_구분!$X$3,표1[월],">="&피벗값_구분!$X$4,표1[월],"<="&피벗값_구분!$X$5)),0) -> 43542863 | L25: =IFERROR(IF(B25="","",E25/1.1/K25),"") -> 3.2575866 | M25: =IFERROR(IF(B25="",0,SUMIFS(표1[총경비],표1[매장코드],B25,표1[년],피벗값_구분!$X$2,표1[월],">="&피벗값_구분!$X$4,표1[월],"<="&피벗값_구분!$X$5)),0) -> 28335220 | N25: =IFERROR(IF(B25="",0,SUMIFS(표1[총경비],표1[매장코드],B25,표1[년],피벗값_구분!$X$3,표1[월],">="&피벗값_구분!$X$4,표1[월],"<="&피벗값_구분!$X$5)),0) -> 28365060 | O25: =IFERROR(IF(B25="","",N25/E25),"") -> 0.18179338 | P25: =IFERROR(IF(B25="",0,SUMIFS(표1[영업이익(V-)],표1[매장코드],B25,표1[년],피벗값_구분!$X$2,표1[월],">="&피벗값_구분!$X$4,표1[월],"<="&피벗값_구분!$X$5)),0) -> 44544527 | Q25: =IFERROR(IF(B25="",0,SUMIFS(표1[영업이익(V-)],표1[매장코드],B25,표1[년],피벗값_구분!$X$3,표1[월],">="&피벗값_구분!$X$4,표1[월],"<="&피벗값_구분!$X$5)),0) -> 47281316 | R25: =IFERROR(IF(B25="","",Q25/(E25/1.1)),"") -> 0.33333169 | S25: =Q25/$Q$70 -> 0.0097603684 | T25: =IF(B25="","",Q25-P25) -> 2736789
B26: =IFERROR(INDEX(구분!$B:$B,MATCH(21,구분!$E:$E,0)),"") -> 00141 | C26: =IFERROR(VLOOKUP(B26,구분!$B:$C,2,0),"") -> 롯데인천터미널점 | D26: =IFERROR(IF(B26="",0,SUMIFS(표1[매출금액],표1[매장코드],B26,표1[년],피벗값_구분!$X$2,표1[월],">="&피벗값_구분!$X$4,표1[월],"<="&피벗값_구분!$X$5)),0) -> 356127100 | E26: =IFERROR(IF(B26="",0,SUMIFS(표1[매출금액],표1[매장코드],B26,표1[년],피벗값_구분!$X$3,표1[월],">="&피벗값_구분!$X$4,표1[월],"<="&피벗값_구분!$X$5)),0) -> 348028640 | F26: =IFERROR(IF(B26="","",(E26-D26)/D26),"") -> -0.022740364 | G26: =IFERROR(IF(B26="",0,SUMIFS(표1[수금액(V+)],표1[매장코드],B26,표1[년],피벗값_구분!$X$2,표1[월],">="&피벗값_구분!$X$4,표1[월],"<="&피벗값_구분!$X$5)),0) -> 228085896 | H26: =IFERROR(IF(B26="",0,SUMIFS(표1[수금액(V+)],표1[매장코드],B26,표1[년],피벗값_구분!$X$3,표1[월],">="&피벗값_구분!$X$4,표1[월],"<="&피벗값_구분!$X$5)),0) -> 222979373 | I26: =IFERROR(IF(B26="","",H26/E26),"") -> 0.6406926 | J26: =IFERROR(IF(B26="",0,SUMIFS(표1[생산원가(V-)],표1[매장코드],B26,표1[년],피벗값_구분!$X$2,표1[월],">="&피벗값_구분!$X$4,표1[월],"<="&피벗값_구분!$X$5)),0) -> 105583227 | K26: =IFERROR(IF(B26="",0,SUMIFS(표1[생산원가(V-)],표1[매장코드],B26,표1[년],피벗값_구분!$X$3,표1[월],">="&피벗값_구분!$X$4,표1[월],"<="&피벗값_구분!$X$5)),0) -> 99808291 | L26: =IFERROR(IF(B26="","",E26/1.1/K26),"") -> 3.1699739 | M26: =IFERROR(IF(B26="",0,SUMIFS(표1[총경비],표1[매장코드],B26,표1[년],피벗값_구분!$X$2,표1[월],">="&피벗값_구분!$X$4,표1[월],"<="&피벗값_구분!$X$5)),0) -> 47477860 | N26: =IFERROR(IF(B26="",0,SUMIFS(표1[총경비],표1[매장코드],B26,표1[년],피벗값_구분!$X$3,표1[월],">="&피벗값_구분!$X$4,표1[월],"<="&피벗값_구분!$X$5)),0) -> 46266070 | O26: =IFERROR(IF(B26="","",N26/E26),"") -> 0.13293754 | P26: =IFERROR(IF(B26="",0,SUMIFS(표1[영업이익(V-)],표1[매장코드],B26,표1[년],피벗값_구분!$X$2,표1[월],">="&피벗값_구분!$X$4,표1[월],"<="&피벗값_구분!$X$5)),0) -> 101767587 | Q26: =IFERROR(IF(B26="",0,SUMIFS(표1[영업이익(V-)],표1[매장코드],B26,표1[년],피벗값_구분!$X$3,표1[월],">="&피벗값_구분!$X$4,표1[월],"<="&피벗값_구분!$X$5)),0) -> 102900230 | R26: =IFERROR(IF(B26="","",Q26/(E26/1.1)),"") -> 0.32523258 | S26: =Q26/$Q$70 -> 0.021241882 | T26: =IF(B26="","",Q26-P26) -> 1132643
B27: =IFERROR(INDEX(구분!$B:$B,MATCH(22,구분!$E:$E,0)),"") -> 00142 | C27: =IFERROR(VLOOKUP(B27,구분!$B:$C,2,0),"") -> 롯데동탄점 | D27: =IFERROR(IF(B27="",0,SUMIFS(표1[매출금액],표1[매장코드],B27,표1[년],피벗값_구분!$X$2,표1[월],">="&피벗값_구분!$X$4,표1[월],"<="&피벗값_구분!$X$5)),0) -> 250689340 | E27: =IFERROR(IF(B27="",0,SUMIFS(표1[매출금액],표1[매장코드],B27,표1[년],피벗값_구분!$X$3,표1[월],">="&피벗값_구분!$X$4,표1[월],"<="&피벗값_구분!$X$5)),0) -> 324186670 | F27: =IFERROR(IF(B27="","",(E27-D27)/D27),"") -> 0.29318091 | G27: =IFERROR(IF(B27="",0,SUMIFS(표1[수금액(V+)],표1[매장코드],B27,표1[년],피벗값_구분!$X$2,표1[월],">="&피벗값_구분!$X$4,표1[월],"<="&피벗값_구분!$X$5)),0) -> 160592051 | H27: =IFERROR(IF(B27="",0,SUMIFS(표1[수금액(V+)],표1[매장코드],B27,표1[년],피벗값_구분!$X$3,표1[월],">="&피벗값_구분!$X$4,표1[월],"<="&피벗값_구분!$X$5)),0) -> 208990633 | I27: =IFERROR(IF(B27="","",H27/E27),"") -> 0.6446614 | J27: =IFERROR(IF(B27="",0,SUMIFS(표1[생산원가(V-)],표1[매장코드],B27,표1[년],피벗값_구분!$X$2,표1[월],">="&피벗값_구분!$X$4,표1[월],"<="&피벗값_구분!$X$5)),0) -> 73856648 | K27: =IFERROR(IF(B27="",0,SUMIFS(표1[생산원가(V-)],표1[매장코드],B27,표1[년],피벗값_구분!$X$3,표1[월],">="&피벗값_구분!$X$4,표1[월],"<="&피벗값_구분!$X$5)),0) -> 92593622 | L27: =IFERROR(IF(B27="","",E27/1.1/K27),"") -> 3.1828883 | M27: =IFERROR(IF(B27="",0,SUMIFS(표1[총경비],표1[매장코드],B27,표1[년],피벗값_구분!$X$2,표1[월],">="&피벗값_구분!$X$4,표1[월],"<="&피벗값_구분!$X$5)),0) -> 37644830 | N27: =IFERROR(IF(B27="",0,SUMIFS(표1[총경비],표1[매장코드],B27,표1[년],피벗값_구분!$X$3,표1[월],">="&피벗값_구분!$X$4,표1[월],"<="&피벗값_구분!$X$5)),0) -> 40703050 | O27: =IFERROR(IF(B27="","",N27/E27),"") -> 0.12555436 | P27: =IFERROR(IF(B27="",0,SUMIFS(표1[영업이익(V-)],표1[매장코드],B27,표1[년],피벗값_구분!$X$2,표1[월],">="&피벗값_구분!$X$4,표1[월],"<="&피벗값_구분!$X$5)),0) -> 72136126 | Q27: =IFERROR(IF(B27="",0,SUMIFS(표1[영업이익(V-)],표1[매장코드],B27,표1[년],피벗값_구분!$X$3,표1[월],">="&피벗값_구분!$X$4,표1[월],"<="&피벗값_구분!$X$5)),0) -> 97397864 | R27: =IFERROR(IF(B27="","",Q27/(E27/1.1)),"") -> 0.33048136 | S27: =Q27/$Q$70 -> 0.020106019 | T27: =IF(B27="","",Q27-P27) -> 25261738
B28: =IFERROR(INDEX(구분!$B:$B,MATCH(23,구분!$E:$E,0)),"") -> 00201 | C28: =IFERROR(VLOOKUP(B28,구분!$B:$C,2,0),"") -> 현대천호점 | D28: =IFERROR(IF(B28="",0,SUMIFS(표1[매출금액],표1[매장코드],B28,표1[년],피벗값_구분!$X$2,표1[월],">="&피벗값_구분!$X$4,표1[월],"<="&피벗값_구분!$X$5)),0) -> 459385100 | E28: =IFERROR(IF(B28="",0,SUMIFS(표1[매출금액],표1[매장코드],B28,표1[년],피벗값_구분!$X$3,표1[월],">="&피벗값_구분!$X$4,표1[월],"<="&피벗값_구분!$X$5)),0) -> 429974100 | F28: =IFERROR(IF(B28="","",(E28-D28)/D28),"") -> -0.064022538 | G28: =IFERROR(IF(B28="",0,SUMIFS(표1[수금액(V+)],표1[매장코드],B28,표1[년],피벗값_구분!$X$2,표1[월],">="&피벗값_구분!$X$4,표1[월],"<="&피벗값_구분!$X$5)),0) -> 296514959 | H28: =IFERROR(IF(B28="",0,SUMIFS(표1[수금액(V+)],표1[매장코드],B28,표1[년],피벗값_구분!$X$3,표1[월],">="&피벗값_구분!$X$4,표1[월],"<="&피벗값_구분!$X$5)),0) -> 272071310 | I28: =IFERROR(IF(B28="","",H28/E28),"") -> 0.63276209 | J28: =IFERROR(IF(B28="",0,SUMIFS(표1[생산원가(V-)],표1[매장코드],B28,표1[년],피벗값_구분!$X$2,표1[월],">="&피벗값_구분!$X$4,표1[월],"<="&피벗값_구분!$X$5)),0) -> 142519248 | K28: =IFERROR(IF(B28="",0,SUMIFS(표1[생산원가(V-)],표1[매장코드],B28,표1[년],피벗값_구분!$X$3,표1[월],">="&피벗값_구분!$X$4,표1[월],"<="&피벗값_구분!$X$5)),0) -> 123827362 | L28: =IFERROR(IF(B28="","",E28/1.1/K28),"") -> 3.1566977 | M28: =IFERROR(IF(B28="",0,SUMIFS(표1[총경비],표1[매장코드],B28,표1[년],피벗값_구분!$X$2,표1[월],">="&피벗값_구분!$X$4,표1[월],"<="&피벗값_구분!$X$5)),0) -> 66581120 | N28: =IFERROR(IF(B28="",0,SUMIFS(표1[총경비],표1[매장코드],B28,표1[년],피벗값_구분!$X$3,표1[월],">="&피벗값_구분!$X$4,표1[월],"<="&피벗값_구분!$X$5)),0) -> 62259800 | O28: =IFERROR(IF(B28="","",N28/E28),"") -> 0.14479895 | P28: =IFERROR(IF(B28="",0,SUMIFS(표1[영업이익(V-)],표1[매장코드],B28,표1[년],피벗값_구분!$X$2,표1[월],">="&피벗값_구분!$X$4,표1[월],"<="&피벗값_구분!$X$5)),0) -> 127039806 | Q28: =IFERROR(IF(B28="",0,SUMIFS(표1[영업이익(V-)],표1[매장코드],B28,표1[년],피벗값_구분!$X$3,표1[월],">="&피벗값_구분!$X$4,표1[월],"<="&피벗값_구분!$X$5)),0) -> 123510191 | R28: =IFERROR(IF(B28="","",Q28/(E28/1.1)),"") -> 0.31597533 | S28: =Q28/$Q$70 -> 0.025496434 | T28: =IF(B28="","",Q28-P28) -> -3529615
B29: =IFERROR(INDEX(구분!$B:$B,MATCH(24,구분!$E:$E,0)),"") -> 00203 | C29: =IFERROR(VLOOKUP(B29,구분!$B:$C,2,0),"") -> 현대울산점 | D29: =IFERROR(IF(B29="",0,SUMIFS(표1[매출금액],표1[매장코드],B29,표1[년],피벗값_구분!$X$2,표1[월],">="&피벗값_구분!$X$4,표1[월],"<="&피벗값_구분!$X$5)),0) -> 310578900 | E29: =IFERROR(IF(B29="",0,SUMIFS(표1[매출금액],표1[매장코드],B29,표1[년],피벗값_구분!$X$3,표1[월],">="&피벗값_구분!$X$4,표1[월],"<="&피벗값_구분!$X$5)),0) -> 347567300 | F29: =IFERROR(IF(B29="","",(E29-D29)/D29),"") -> 0.11909502 | G29: =IFERROR(IF(B29="",0,SUMIFS(표1[수금액(V+)],표1[매장코드],B29,표1[년],피벗값_구분!$X$2,표1[월],">="&피벗값_구분!$X$4,표1[월],"<="&피벗값_구분!$X$5)),0) -> 209572259 | H29: =IFERROR(IF(B29="",0,SUMIFS(표1[수금액(V+)],표1[매장코드],B29,표1[년],피벗값_구분!$X$3,표1[월],">="&피벗값_구분!$X$4,표1[월],"<="&피벗값_구분!$X$5)),0) -> 216966062 | I29: =IFERROR(IF(B29="","",H29/E29),"") -> 0.62424187 | J29: =IFERROR(IF(B29="",0,SUMIFS(표1[생산원가(V-)],표1[매장코드],B29,표1[년],피벗값_구분!$X$2,표1[월],">="&피벗값_구분!$X$4,표1[월],"<="&피벗값_구분!$X$5)),0) -> 87626323 | K29: =IFERROR(IF(B29="",0,SUMIFS(표1[생산원가(V-)],표1[매장코드],B29,표1[년],피벗값_구분!$X$3,표1[월],">="&피벗값_구분!$X$4,표1[월],"<="&피벗값_구분!$X$5)),0) -> 100831823 | L29: =IFERROR(IF(B29="","",E29/1.1/K29),"") -> 3.1336364 | M29: =IFERROR(IF(B29="",0,SUMIFS(표1[총경비],표1[매장코드],B29,표1[년],피벗값_구분!$X$2,표1[월],">="&피벗값_구분!$X$4,표1[월],"<="&피벗값_구분!$X$5)),0) -> 40408350 | N29: =IFERROR(IF(B29="",0,SUMIFS(표1[총경비],표1[매장코드],B29,표1[년],피벗값_구분!$X$3,표1[월],">="&피벗값_구분!$X$4,표1[월],"<="&피벗값_구분!$X$5)),0) -> 41013400 | O29: =IFERROR(IF(B29="","",N29/E29),"") -> 0.11800132 | P29: =IFERROR(IF(B29="",0,SUMIFS(표1[영업이익(V-)],표1[매장코드],B29,표1[년],피벗값_구분!$X$2,표1[월],">="&피벗값_구분!$X$4,표1[월],"<="&피벗값_구분!$X$5)),0) -> 102893912 | Q29: =IFERROR(IF(B29="",0,SUMIFS(표1[영업이익(V-)],표1[매장코드],B29,표1[년],피벗값_구분!$X$3,표1[월],">="&피벗값_구분!$X$4,표1[월],"<="&피벗값_구분!$X$5)),0) -> 96410051 | R29: =IFERROR(IF(B29="","",Q29/(E29/1.1)),"") -> 0.3051238 | S29: =Q29/$Q$70 -> 0.019902103 | T29: =IF(B29="","",Q29-P29) -> -6483861
B30: =IFERROR(INDEX(구분!$B:$B,MATCH(25,구분!$E:$E,0)),"") -> 00208 | C30: =IFERROR(VLOOKUP(B30,구분!$B:$C,2,0),"") -> 현대미아점 | D30: =IFERROR(IF(B30="",0,SUMIFS(표1[매출금액],표1[매장코드],B30,표1[년],피벗값_구분!$X$2,표1[월],">="&피벗값_구분!$X$4,표1[월],"<="&피벗값_구분!$X$5)),0) -> 146516950 | E30: =IFERROR(IF(B30="",0,SUMIFS(표1[매출금액],표1[매장코드],B30,표1[년],피벗값_구분!$X$3,표1[월],">="&피벗값_구분!$X$4,표1[월],"<="&피벗값_구분!$X$5)),0) -> 171678450 | F30: =IFERROR(IF(B30="","",(E30-D30)/D30),"") -> 0.17173098 | G30: =IFERROR(IF(B30="",0,SUMIFS(표1[수금액(V+)],표1[매장코드],B30,표1[년],피벗값_구분!$X$2,표1[월],">="&피벗값_구분!$X$4,표1[월],"<="&피벗값_구분!$X$5)),0) -> 98273474 | H30: =IFERROR(IF(B30="",0,SUMIFS(표1[수금액(V+)],표1[매장코드],B30,표1[년],피벗값_구분!$X$3,표1[월],">="&피벗값_구분!$X$4,표1[월],"<="&피벗값_구분!$X$5)),0) -> 107134645 | I30: =IFERROR(IF(B30="","",H30/E30),"") -> 0.62404248 | J30: =IFERROR(IF(B30="",0,SUMIFS(표1[생산원가(V-)],표1[매장코드],B30,표1[년],피벗값_구분!$X$2,표1[월],">="&피벗값_구분!$X$4,표1[월],"<="&피벗값_구분!$X$5)),0) -> 44750121 | K30: =IFERROR(IF(B30="",0,SUMIFS(표1[생산원가(V-)],표1[매장코드],B30,표1[년],피벗값_구분!$X$3,표1[월],">="&피벗값_구분!$X$4,표1[월],"<="&피벗값_구분!$X$5)),0) -> 50589176 | L30: =IFERROR(IF(B30="","",E30/1.1/K30),"") -> 3.0850733 | M30: =IFERROR(IF(B30="",0,SUMIFS(표1[총경비],표1[매장코드],B30,표1[년],피벗값_구분!$X$2,표1[월],">="&피벗값_구분!$X$4,표1[월],"<="&피벗값_구분!$X$5)),0) -> 23827600 | N30: =IFERROR(IF(B30="",0,SUMIFS(표1[총경비],표1[매장코드],B30,표1[년],피벗값_구분!$X$3,표1[월],">="&피벗값_구분!$X$4,표1[월],"<="&피벗값_구분!$X$5)),0) -> 26158890 | O30: =IFERROR(IF(B30="","",N30/E30),"") -> 0.15237142 | P30: =IFERROR(IF(B30="",0,SUMIFS(표1[영업이익(V-)],표1[매장코드],B30,표1[년],피벗값_구분!$X$2,표1[월],">="&피벗값_구분!$X$4,표1[월],"<="&피벗값_구분!$X$5)),0) -> 44589401 | Q30: =IFERROR(IF(B30="",0,SUMIFS(표1[영업이익(V-)],표1[매장코드],B30,표1[년],피벗값_구분!$X$3,표1[월],">="&피벗값_구분!$X$4,표1[월],"<="&피벗값_구분!$X$5)),0) -> 46805957 | R30: =IFERROR(IF(B30="","",Q30/(E30/1.1)),"") -> 0.29990108 | S30: =Q30/$Q$70 -> 0.0096622391 | T30: =IF(B30="","",Q30-P30) -> 2216556
B31: =IFERROR(INDEX(구분!$B:$B,MATCH(26,구분!$E:$E,0)),"") -> 00210 | C31: =IFERROR(VLOOKUP(B31,구분!$B:$C,2,0),"") -> 현대중동점 | D31: =IFERROR(IF(B31="",0,SUMIFS(표1[매출금액],표1[매장코드],B31,표1[년],피벗값_구분!$X$2,표1[월],">="&피벗값_구분!$X$4,표1[월],"<="&피벗값_구분!$X$5)),0) -> 165363670 | E31: =IFERROR(IF(B31="",0,SUMIFS(표1[매출금액],표1[매장코드],B31,표1[년],피벗값_구분!$X$3,표1[월],">="&피벗값_구분!$X$4,표1[월],"<="&피벗값_구분!$X$5)),0) -> 206604710 | F31: =IFERROR(IF(B31="","",(E31-D31)/D31),"") -> 0.24939601 | G31: =IFERROR(IF(B31="",0,SUMIFS(표1[수금액(V+)],표1[매장코드],B31,표1[년],피벗값_구분!$X$2,표1[월],">="&피벗값_구분!$X$4,표1[월],"<="&피벗값_구분!$X$5)),0) -> 102530085 | H31: =IFERROR(IF(B31="",0,SUMIFS(표1[수금액(V+)],표1[매장코드],B31,표1[년],피벗값_구분!$X$3,표1[월],">="&피벗값_구분!$X$4,표1[월],"<="&피벗값_구분!$X$5)),0) -> 128520946 | I31: =IFERROR(IF(B31="","",H31/E31),"") -> 0.62206203 | J31: =IFERROR(IF(B31="",0,SUMIFS(표1[생산원가(V-)],표1[매장코드],B31,표1[년],피벗값_구분!$X$2,표1[월],">="&피벗값_구분!$X$4,표1[월],"<="&피벗값_구분!$X$5)),0) -> 45751173 | K31: =IFERROR(IF(B31="",0,SUMIFS(표1[생산원가(V-)],표1[매장코드],B31,표1[년],피벗값_구분!$X$3,표1[월],">="&피벗값_구분!$X$4,표1[월],"<="&피벗값_구분!$X$5)),0) -> 57407639 | L31: =IFERROR(IF(B31="","",E31/1.1/K31),"") -> 3.2717329 | M31: =IFERROR(IF(B31="",0,SUMIFS(표1[총경비],표1[매장코드],B31,표1[년],피벗값_구분!$X$2,표1[월],">="&피벗값_구분!$X$4,표1[월],"<="&피벗값_구분!$X$5)),0) -> 30931630 | N31: =IFERROR(IF(B31="",0,SUMIFS(표1[총경비],표1[매장코드],B31,표1[년],피벗값_구분!$X$3,표1[월],">="&피벗값_구분!$X$4,표1[월],"<="&피벗값_구분!$X$5)),0) -> 33938610 | O31: =IFERROR(IF(B31="","",N31/E31),"") -> 0.16426833 | P31: =IFERROR(IF(B31="",0,SUMIFS(표1[영업이익(V-)],표1[매장코드],B31,표1[년],피벗값_구분!$X$2,표1[월],">="&피벗값_구분!$X$4,표1[월],"<="&피벗값_구분!$X$5)),0) -> 47457995 | Q31: =IFERROR(IF(B31="",0,SUMIFS(표1[영업이익(V-)],표1[매장코드],B31,표1[년],피벗값_구분!$X$3,표1[월],">="&피벗값_구분!$X$4,표1[월],"<="&피벗값_구분!$X$5)),0) -> 59429584 | R31: =IFERROR(IF(B31="","",Q31/(E31/1.1)),"") -> 0.31641361 | S31: =Q31/$Q$70 -> 0.012268157 | T31: =IF(B31="","",Q31-P31) -> 11971589
B32: =IFERROR(INDEX(구분!$B:$B,MATCH(27,구분!$E:$E,0)),"") -> 00212 | C32: =IFERROR(VLOOKUP(B32,구분!$B:$C,2,0),"") -> 현대킨텍스점 | D32: =IFERROR(IF(B32="",0,SUMIFS(표1[매출금액],표1[매장코드],B32,표1[년],피벗값_구분!$X$2,표1[월],">="&피벗값_구분!$X$4,표1[월],"<="&피벗값_구분!$X$5)),0) -> 0 | E32: =IFERROR(IF(B32="",0,SUMIFS(표1[매출금액],표1[매장코드],B32,표1[년],피벗값_구분!$X$3,표1[월],">="&피벗값_구분!$X$4,표1[월],"<="&피벗값_구분!$X$5)),0) -> 159288080 | F32: =IFERROR(IF(B32="","",(E32-D32)/D32),"") | G32: =IFERROR(IF(B32="",0,SUMIFS(표1[수금액(V+)],표1[매장코드],B32,표1[년],피벗값_구분!$X$2,표1[월],">="&피벗값_구분!$X$4,표1[월],"<="&피벗값_구분!$X$5)),0) -> 0 | H32: =IFERROR(IF(B32="",0,SUMIFS(표1[수금액(V+)],표1[매장코드],B32,표1[년],피벗값_구분!$X$3,표1[월],">="&피벗값_구분!$X$4,표1[월],"<="&피벗값_구분!$X$5)),0) -> 99529838 | I32: =IFERROR(IF(B32="","",H32/E32),"") -> 0.62484172 | J32: =IFERROR(IF(B32="",0,SUMIFS(표1[생산원가(V-)],표1[매장코드],B32,표1[년],피벗값_구분!$X$2,표1[월],">="&피벗값_구분!$X$4,표1[월],"<="&피벗값_구분!$X$5)),0) -> 0 | K32: =IFERROR(IF(B32="",0,SUMIFS(표1[생산원가(V-)],표1[매장코드],B32,표1[년],피벗값_구분!$X$3,표1[월],">="&피벗값_구분!$X$4,표1[월],"<="&피벗값_구분!$X$5)),0) -> 44156222 | L32: =IFERROR(IF(B32="","",E32/1.1/K32),"") -> 3.2794324 | M32: =IFERROR(IF(B32="",0,SUMIFS(표1[총경비],표1[매장코드],B32,표1[년],피벗값_구분!$X$2,표1[월],">="&피벗값_구분!$X$4,표1[월],"<="&피벗값_구분!$X$5)),0) -> 0 | N32: =IFERROR(IF(B32="",0,SUMIFS(표1[총경비],표1[매장코드],B32,표1[년],피벗값_구분!$X$3,표1[월],">="&피벗값_구분!$X$4,표1[월],"<="&피벗값_구분!$X$5)),0) -> 30196500 | O32: =IFERROR(IF(B32="","",N32/E32),"") -> 0.18957162 | P32: =IFERROR(IF(B32="",0,SUMIFS(표1[영업이익(V-)],표1[매장코드],B32,표1[년],피벗값_구분!$X$2,표1[월],">="&피벗값_구분!$X$4,표1[월],"<="&피벗값_구분!$X$5)),0) -> 0 | Q32: =IFERROR(IF(B32="",0,SUMIFS(표1[영업이익(V-)],표1[매장코드],B32,표1[년],피벗값_구분!$X$3,표1[월],">="&피벗값_구분!$X$4,표1[월],"<="&피벗값_구분!$X$5)),0) -> 46325449 | R32: =IFERROR(IF(B32="","",Q32/(E32/1.1)),"") -> 0.31991091 | S32: =Q32/$Q$70 -> 0.009563047 | T32: =IF(B32="","",Q32-P32) -> 46325449
B33: =IFERROR(INDEX(구분!$B:$B,MATCH(28,구분!$E:$E,0)),"") -> 00213 | C33: =IFERROR(VLOOKUP(B33,구분!$B:$C,2,0),"") -> 현대대구점 | D33: =IFERROR(IF(B33="",0,SUMIFS(표1[매출금액],표1[매장코드],B33,표1[년],피벗값_구분!$X$2,표1[월],">="&피벗값_구분!$X$4,표1[월],"<="&피벗값_구분!$X$5)),0) -> 517541563 | E33: =IFERROR(IF(B33="",0,SUMIFS(표1[매출금액],표1[매장코드],B33,표1[년],피벗값_구분!$X$3,표1[월],">="&피벗값_구분!$X$4,표1[월],"<="&피벗값_구분!$X$5)),0) -> 558204440 | F33: =IFERROR(IF(B33="","",(E33-D33)/D33),"") -> 0.078569297 | G33: =IFERROR(IF(B33="",0,SUMIFS(표1[수금액(V+)],표1[매장코드],B33,표1[년],피벗값_구분!$X$2,표1[월],">="&피벗값_구분!$X$4,표1[월],"<="&피벗값_구분!$X$5)),0) -> 331777168 | H33: =IFERROR(IF(B33="",0,SUMIFS(표1[수금액(V+)],표1[매장코드],B33,표1[년],피벗값_구분!$X$3,표1[월],">="&피벗값_구분!$X$4,표1[월],"<="&피벗값_구분!$X$5)),0) -> 347852367 | I33: =IFERROR(IF(B33="","",H33/E33),"") -> 0.62316302 | J33: =IFERROR(IF(B33="",0,SUMIFS(표1[생산원가(V-)],표1[매장코드],B33,표1[년],피벗값_구분!$X$2,표1[월],">="&피벗값_구분!$X$4,표1[월],"<="&피벗값_구분!$X$5)),0) -> 165191748 | K33: =IFERROR(IF(B33="",0,SUMIFS(표1[생산원가(V-)],표1[매장코드],B33,표1[년],피벗값_구분!$X$3,표1[월],">="&피벗값_구분!$X$4,표1[월],"<="&피벗값_구분!$X$5)),0) -> 168837125 | L33: =IFERROR(IF(B33="","",E33/1.1/K33),"") -> 3.0056102 | M33: =IFERROR(IF(B33="",0,SUMIFS(표1[총경비],표1[매장코드],B33,표1[년],피벗값_구분!$X$2,표1[월],">="&피벗값_구분!$X$4,표1[월],"<="&피벗값_구분!$X$5)),0) -> 72279750 | N33: =IFERROR(IF(B33="",0,SUMIFS(표1[총경비],표1[매장코드],B33,표1[년],피벗값_구분!$X$3,표1[월],">="&피벗값_구분!$X$4,표1[월],"<="&피벗값_구분!$X$5)),0) -> 77647780 | O33: =IFERROR(IF(B33="","",N33/E33),"") -> 0.13910276 | P33: =IFERROR(IF(B33="",0,SUMIFS(표1[영업이익(V-)],표1[매장코드],B33,표1[년],피벗값_구분!$X$2,표1[월],">="&피벗값_구분!$X$4,표1[월],"<="&피벗값_구분!$X$5)),0) -> 136423860 | Q33: =IFERROR(IF(B33="",0,SUMIFS(표1[영업이익(V-)],표1[매장코드],B33,표1[년],피벗값_구분!$X$3,표1[월],">="&피벗값_구분!$X$4,표1[월],"<="&피벗값_구분!$X$5)),0) -> 147392299 | R33: =IFERROR(IF(B33="","",Q33/(E33/1.1)),"") -> 0.29045188 | S33: =Q33/$Q$70 -> 0.030426461 | T33: =IF(B33="","",Q33-P33) -> 10968439
